{
  "version": 8,
  "blockIdVersion": 11,
  "anchorX": 7,
  "anchorY": 5,
  "anchorZ": 8,
  "blocks": [
    {
      "x": 1,
      "y": 13,
      "z": 6,
      "name": "Plant_Leaves_Gear"
    },
    {
      "x": 1,
      "y": 10,
      "z": 7,
      "name": "Plant_Leaves_Gear"
    },
    {
      "x": 1,
      "y": 13,
      "z": 7,
      "name": "Plant_Leaves_Gear"
    },
    {
      "x": 1,
      "y": 14,
      "z": 7,
      "name": "Plant_Leaves_Gear"
    },
    {
      "x": 1,
      "y": 10,
      "z": 8,
      "name": "Plant_Leaves_Gear"
    },
    {
      "x": 1,
      "y": 11,
      "z": 8,
      "name": "Plant_Leaves_Gear"
    },
    {
      "x": 1,
      "y": 13,
      "z": 8,
      "name": "Plant_Leaves_Gear"
    },
    {
      "x": 1,
      "y": 14,
      "z": 8,
      "name": "Plant_Leaves_Gear"
    },
    {
      "x": 1,
      "y": 15,
      "z": 8,
      "name": "Plant_Leaves_Gear"
    },
    {
      "x": 1,
      "y": 10,
      "z": 9,
      "name": "Plant_Leaves_Gear"
    },
    {
      "x": 1,
      "y": 13,
      "z": 9,
      "name": "Plant_Leaves_Gear"
    },
    {
      "x": 1,
      "y": 14,
      "z": 9,
      "name": "Plant_Leaves_Gear"
    },
    {
      "x": 2,
      "y": 13,
      "z": 5,
      "name": "Plant_Leaves_Gear"
    },
    {
      "x": 2,
      "y": 14,
      "z": 5,
      "name": "Plant_Leaves_Gear"
    },
    {
      "x": 2,
      "y": 10,
      "z": 6,
      "name": "Plant_Leaves_Gear"
    },
    {
      "x": 2,
      "y": 11,
      "z": 6,
      "name": "Plant_Leaves_Gear"
    },
    {
      "x": 2,
      "y": 13,
      "z": 6,
      "name": "Plant_Leaves_Gear"
    },
    {
      "x": 2,
      "y": 14,
      "z": 6,
      "name": "Plant_Leaves_Gear"
    },
    {
      "x": 2,
      "y": 9,
      "z": 7,
      "name": "Plant_Leaves_Gear"
    },
    {
      "x": 2,
      "y": 10,
      "z": 7,
      "name": "Plant_Leaves_Gear"
    },
    {
      "x": 2,
      "y": 11,
      "z": 7,
      "name": "Plant_Leaves_Gear"
    },
    {
      "x": 2,
      "y": 13,
      "z": 7,
      "name": "Plant_Leaves_Gear"
    },
    {
      "x": 2,
      "y": 14,
      "z": 7,
      "name": "Plant_Leaves_Gear"
    },
    {
      "x": 2,
      "y": 15,
      "z": 7,
      "name": "Plant_Leaves_Gear"
    },
    {
      "x": 2,
      "y": 10,
      "z": 8,
      "name": "Wood_Gear_Branch_Corner",
      "rotation": 3
    },
    {
      "x": 2,
      "y": 11,
      "z": 8,
      "name": "Plant_Leaves_Gear"
    },
    {
      "x": 2,
      "y": 12,
      "z": 8,
      "name": "Plant_Leaves_Gear"
    },
    {
      "x": 2,
      "y": 13,
      "z": 8,
      "name": "Wood_Gear_Branch_Corner",
      "rotation": 3
    },
    {
      "x": 2,
      "y": 14,
      "z": 8,
      "name": "Plant_Leaves_Gear"
    },
    {
      "x": 2,
      "y": 15,
      "z": 8,
      "name": "Plant_Leaves_Gear"
    },
    {
      "x": 2,
      "y": 10,
      "z": 9,
      "name": "Plant_Leaves_Gear"
    },
    {
      "x": 2,
      "y": 11,
      "z": 9,
      "name": "Plant_Leaves_Gear"
    },
    {
      "x": 2,
      "y": 12,
      "z": 9,
      "name": "Plant_Leaves_Gear"
    },
    {
      "x": 2,
      "y": 13,
      "z": 9,
      "name": "Plant_Leaves_Gear"
    },
    {
      "x": 2,
      "y": 14,
      "z": 9,
      "name": "Plant_Leaves_Gear"
    },
    {
      "x": 2,
      "y": 15,
      "z": 9,
      "name": "Plant_Leaves_Gear"
    },
    {
      "x": 2,
      "y": 10,
      "z": 10,
      "name": "Plant_Leaves_Gear"
    },
    {
      "x": 2,
      "y": 14,
      "z": 10,
      "name": "Plant_Leaves_Gear"
    },
    {
      "x": 3,
      "y": 13,
      "z": 4,
      "name": "Plant_Leaves_Gear"
    },
    {
      "x": 3,
      "y": 10,
      "z": 5,
      "name": "Plant_Leaves_Gear"
    },
    {
      "x": 3,
      "y": 12,
      "z": 5,
      "name": "Plant_Leaves_Gear"
    },
    {
      "x": 3,
      "y": 13,
      "z": 5,
      "name": "Plant_Leaves_Gear"
    },
    {
      "x": 3,
      "y": 14,
      "z": 5,
      "name": "Plant_Leaves_Gear"
    },
    {
      "x": 3,
      "y": 9,
      "z": 6,
      "name": "Plant_Leaves_Gear"
    },
    {
      "x": 3,
      "y": 10,
      "z": 6,
      "name": "Plant_Leaves_Gear"
    },
    {
      "x": 3,
      "y": 11,
      "z": 6,
      "name": "Plant_Leaves_Gear"
    },
    {
      "x": 3,
      "y": 12,
      "z": 6,
      "name": "Plant_Leaves_Gear"
    },
    {
      "x": 3,
      "y": 13,
      "z": 6,
      "name": "Plant_Leaves_Gear"
    },
    {
      "x": 3,
      "y": 9,
      "z": 7,
      "name": "Plant_Leaves_Gear"
    },
    {
      "x": 3,
      "y": 10,
      "z": 7,
      "name": "Plant_Leaves_Gear"
    },
    {
      "x": 3,
      "y": 11,
      "z": 7,
      "name": "Plant_Leaves_Gear"
    },
    {
      "x": 3,
      "y": 13,
      "z": 7,
      "name": "Plant_Leaves_Gear"
    },
    {
      "x": 3,
      "y": 14,
      "z": 7,
      "name": "Plant_Leaves_Gear"
    },
    {
      "x": 3,
      "y": 10,
      "z": 8,
      "name": "Wood_Gear_Branch_Long",
      "rotation": 5
    },
    {
      "x": 3,
      "y": 13,
      "z": 8,
      "name": "Wood_Gear_Branch_Long",
      "rotation": 5
    },
    {
      "x": 3,
      "y": 15,
      "z": 8,
      "name": "Plant_Leaves_Gear"
    },
    {
      "x": 3,
      "y": 16,
      "z": 8,
      "name": "Plant_Leaves_Gear"
    },
    {
      "x": 3,
      "y": 17,
      "z": 8,
      "name": "Plant_Leaves_Gear"
    },
    {
      "x": 3,
      "y": 18,
      "z": 8,
      "name": "Plant_Leaves_Gear"
    },
    {
      "x": 3,
      "y": 10,
      "z": 9,
      "name": "Plant_Leaves_Gear"
    },
    {
      "x": 3,
      "y": 11,
      "z": 9,
      "name": "Plant_Leaves_Gear"
    },
    {
      "x": 3,
      "y": 15,
      "z": 9,
      "name": "Plant_Leaves_Gear"
    },
    {
      "x": 3,
      "y": 17,
      "z": 9,
      "name": "Plant_Leaves_Gear"
    },
    {
      "x": 3,
      "y": 10,
      "z": 10,
      "name": "Plant_Leaves_Gear"
    },
    {
      "x": 3,
      "y": 11,
      "z": 10,
      "name": "Plant_Leaves_Gear"
    },
    {
      "x": 3,
      "y": 13,
      "z": 11,
      "name": "Plant_Leaves_Gear"
    },
    {
      "x": 3,
      "y": 14,
      "z": 11,
      "name": "Plant_Leaves_Gear"
    },
    {
      "x": 4,
      "y": 13,
      "z": 4,
      "name": "Plant_Leaves_Gear"
    },
    {
      "x": 4,
      "y": 12,
      "z": 5,
      "name": "Plant_Leaves_Gear"
    },
    {
      "x": 4,
      "y": 13,
      "z": 5,
      "name": "Plant_Leaves_Gear"
    },
    {
      "x": 4,
      "y": 14,
      "z": 5,
      "name": "Plant_Leaves_Gear"
    },
    {
      "x": 4,
      "y": 12,
      "z": 6,
      "name": "Plant_Leaves_Gear"
    },
    {
      "x": 4,
      "y": 13,
      "z": 6,
      "name": "Plant_Leaves_Gear"
    },
    {
      "x": 4,
      "y": 14,
      "z": 6,
      "name": "Plant_Leaves_Gear"
    },
    {
      "x": 4,
      "y": 16,
      "z": 7,
      "name": "Plant_Leaves_Gear"
    },
    {
      "x": 4,
      "y": 18,
      "z": 7,
      "name": "Plant_Leaves_Gear"
    },
    {
      "x": 4,
      "y": 10,
      "z": 8,
      "name": "Wood_Gear_Branch_Long",
      "rotation": 5
    },
    {
      "x": 4,
      "y": 13,
      "z": 8,
      "name": "Wood_Gear_Branch_Long",
      "rotation": 5
    },
    {
      "x": 4,
      "y": 16,
      "z": 8,
      "name": "Plant_Leaves_Gear"
    },
    {
      "x": 4,
      "y": 18,
      "z": 8,
      "name": "Plant_Leaves_Gear"
    },
    {
      "x": 4,
      "y": 19,
      "z": 8,
      "name": "Plant_Leaves_Gear"
    },
    {
      "x": 4,
      "y": 21,
      "z": 8,
      "name": "Plant_Leaves_Gear"
    },
    {
      "x": 4,
      "y": 22,
      "z": 8,
      "name": "Plant_Leaves_Gear"
    },
    {
      "x": 4,
      "y": 16,
      "z": 9,
      "name": "Plant_Leaves_Gear"
    },
    {
      "x": 4,
      "y": 18,
      "z": 9,
      "name": "Plant_Leaves_Gear"
    },
    {
      "x": 4,
      "y": 19,
      "z": 9,
      "name": "Plant_Leaves_Gear"
    },
    {
      "x": 4,
      "y": 11,
      "z": 10,
      "name": "Plant_Leaves_Gear"
    },
    {
      "x": 4,
      "y": 15,
      "z": 10,
      "name": "Plant_Leaves_Gear"
    },
    {
      "x": 4,
      "y": 17,
      "z": 10,
      "name": "Plant_Leaves_Gear"
    },
    {
      "x": 4,
      "y": 14,
      "z": 11,
      "name": "Plant_Leaves_Gear"
    },
    {
      "x": 4,
      "y": 10,
      "z": 12,
      "name": "Plant_Leaves_Gear"
    },
    {
      "x": 4,
      "y": 13,
      "z": 12,
      "name": "Plant_Leaves_Gear"
    },
    {
      "x": 4,
      "y": 14,
      "z": 12,
      "name": "Plant_Leaves_Gear"
    },
    {
      "x": 5,
      "y": 12,
      "z": 4,
      "name": "Plant_Leaves_Gear"
    },
    {
      "x": 5,
      "y": 13,
      "z": 4,
      "name": "Plant_Leaves_Gear"
    },
    {
      "x": 5,
      "y": 15,
      "z": 5,
      "name": "Plant_Leaves_Gear"
    },
    {
      "x": 5,
      "y": 18,
      "z": 5,
      "name": "Plant_Leaves_Gear"
    },
    {
      "x": 5,
      "y": 13,
      "z": 6,
      "name": "Wood_Gear_Branch_Long",
      "rotation": 5
    },
    {
      "x": 5,
      "y": 15,
      "z": 6,
      "name": "Plant_Leaves_Gear"
    },
    {
      "x": 5,
      "y": 16,
      "z": 6,
      "name": "Plant_Leaves_Gear"
    },
    {
      "x": 5,
      "y": 16,
      "z": 7,
      "name": "Plant_Leaves_Gear"
    },
    {
      "x": 5,
      "y": 18,
      "z": 7,
      "name": "Plant_Leaves_Gear"
    },
    {
      "x": 5,
      "y": 19,
      "z": 7,
      "name": "Plant_Leaves_Gear"
    },
    {
      "x": 5,
      "y": 21,
      "z": 7,
      "name": "Plant_Leaves_Gear"
    },
    {
      "x": 5,
      "y": 22,
      "z": 7,
      "name": "Plant_Leaves_Gear"
    },
    {
      "x": 5,
      "y": 10,
      "z": 8,
      "name": "Wood_Gear_Trunk_Full"
    },
    {
      "x": 5,
      "y": 13,
      "z": 8,
      "name": "Wood_Gear_Trunk_Full"
    },
    {
      "x": 5,
      "y": 16,
      "z": 8,
      "name": "Wood_Gear_Branch_Long",
      "rotation": 5
    },
    {
      "x": 5,
      "y": 18,
      "z": 8,
      "name": "Wood_Gear_Branch_Long",
      "rotation": 5
    },
    {
      "x": 5,
      "y": 21,
      "z": 8,
      "name": "Plant_Leaves_Gear"
    },
    {
      "x": 5,
      "y": 22,
      "z": 8,
      "name": "Plant_Leaves_Gear"
    },
    {
      "x": 5,
      "y": 13,
      "z": 9,
      "name": "Wood_Gear_Branch_Long",
      "rotation": 4
    },
    {
      "x": 5,
      "y": 16,
      "z": 9,
      "name": "Plant_Leaves_Gear"
    },
    {
      "x": 5,
      "y": 18,
      "z": 9,
      "name": "Plant_Leaves_Gear"
    },
    {
      "x": 5,
      "y": 19,
      "z": 9,
      "name": "Plant_Leaves_Gear"
    },
    {
      "x": 5,
      "y": 22,
      "z": 9,
      "name": "Plant_Leaves_Gear"
    },
    {
      "x": 5,
      "y": 13,
      "z": 10,
      "name": "Wood_Gear_Branch_Long",
      "rotation": 4
    },
    {
      "x": 5,
      "y": 21,
      "z": 10,
      "name": "Plant_Leaves_Gear"
    },
    {
      "x": 5,
      "y": 13,
      "z": 11,
      "name": "Wood_Gear_Branch_Long",
      "rotation": 4
    },
    {
      "x": 5,
      "y": 15,
      "z": 11,
      "name": "Plant_Leaves_Gear"
    },
    {
      "x": 5,
      "y": 9,
      "z": 12,
      "name": "Plant_Leaves_Gear"
    },
    {
      "x": 5,
      "y": 10,
      "z": 12,
      "name": "Plant_Leaves_Gear"
    },
    {
      "x": 5,
      "y": 11,
      "z": 12,
      "name": "Plant_Leaves_Gear"
    },
    {
      "x": 5,
      "y": 13,
      "z": 12,
      "name": "Wood_Gear_Branch_Corner"
    },
    {
      "x": 5,
      "y": 14,
      "z": 12,
      "name": "Plant_Leaves_Gear"
    },
    {
      "x": 5,
      "y": 15,
      "z": 12,
      "name": "Plant_Leaves_Gear"
    },
    {
      "x": 5,
      "y": 10,
      "z": 13,
      "name": "Plant_Leaves_Gear"
    },
    {
      "x": 5,
      "y": 11,
      "z": 13,
      "name": "Plant_Leaves_Gear"
    },
    {
      "x": 5,
      "y": 13,
      "z": 13,
      "name": "Plant_Leaves_Gear"
    },
    {
      "x": 5,
      "y": 14,
      "z": 13,
      "name": "Plant_Leaves_Gear"
    },
    {
      "x": 6,
      "y": 13,
      "z": 3,
      "name": "Plant_Leaves_Gear"
    },
    {
      "x": 6,
      "y": 14,
      "z": 3,
      "name": "Plant_Leaves_Gear"
    },
    {
      "x": 6,
      "y": 11,
      "z": 4,
      "name": "Plant_Leaves_Gear"
    },
    {
      "x": 6,
      "y": 12,
      "z": 4,
      "name": "Plant_Leaves_Gear"
    },
    {
      "x": 6,
      "y": 13,
      "z": 4,
      "name": "Plant_Leaves_Gear"
    },
    {
      "x": 6,
      "y": 14,
      "z": 4,
      "name": "Plant_Leaves_Gear"
    },
    {
      "x": 6,
      "y": 15,
      "z": 4,
      "name": "Plant_Leaves_Gear"
    },
    {
      "x": 6,
      "y": 18,
      "z": 4,
      "name": "Plant_Leaves_Gear"
    },
    {
      "x": 6,
      "y": 15,
      "z": 5,
      "name": "Plant_Leaves_Gear"
    },
    {
      "x": 6,
      "y": 16,
      "z": 5,
      "name": "Plant_Leaves_Gear"
    },
    {
      "x": 6,
      "y": 19,
      "z": 5,
      "name": "Plant_Leaves_Gear"
    },
    {
      "x": 6,
      "y": 20,
      "z": 5,
      "name": "Plant_Leaves_Gear"
    },
    {
      "x": 6,
      "y": 13,
      "z": 6,
      "name": "Wood_Gear_Branch_Long",
      "rotation": 5
    },
    {
      "x": 6,
      "y": 16,
      "z": 6,
      "name": "Plant_Leaves_Gear"
    },
    {
      "x": 6,
      "y": 17,
      "z": 6,
      "name": "Plant_Leaves_Gear"
    },
    {
      "x": 6,
      "y": 19,
      "z": 6,
      "name": "Plant_Leaves_Gear"
    },
    {
      "x": 6,
      "y": 22,
      "z": 6,
      "name": "Plant_Leaves_Gear"
    },
    {
      "x": 6,
      "y": 24,
      "z": 6,
      "name": "Plant_Leaves_Gear"
    },
    {
      "x": 6,
      "y": 16,
      "z": 7,
      "name": "Plant_Leaves_Gear"
    },
    {
      "x": 6,
      "y": 21,
      "z": 7,
      "name": "Plant_Leaves_Gear"
    },
    {
      "x": 6,
      "y": 22,
      "z": 7,
      "name": "Plant_Leaves_Gear"
    },
    {
      "x": 6,
      "y": 24,
      "z": 7,
      "name": "Plant_Leaves_Gear"
    },
    {
      "x": 6,
      "y": 25,
      "z": 7,
      "name": "Plant_Leaves_Gear"
    },
    {
      "x": 6,
      "y": 10,
      "z": 8,
      "name": "Wood_Gear_Trunk_Full"
    },
    {
      "x": 6,
      "y": 13,
      "z": 8,
      "name": "Wood_Gear_Trunk_Full"
    },
    {
      "x": 6,
      "y": 14,
      "z": 8,
      "name": "Deco_Nest"
    },
    {
      "x": 6,
      "y": 16,
      "z": 8,
      "name": "Wood_Gear_Branch_Long",
      "rotation": 5
    },
    {
      "x": 6,
      "y": 18,
      "z": 8,
      "name": "Wood_Gear_Branch_Long",
      "rotation": 5
    },
    {
      "x": 6,
      "y": 21,
      "z": 8,
      "name": "Wood_Gear_Branch_Long",
      "rotation": 5
    },
    {
      "x": 6,
      "y": 24,
      "z": 8,
      "name": "Plant_Leaves_Gear"
    },
    {
      "x": 6,
      "y": 22,
      "z": 9,
      "name": "Plant_Leaves_Gear"
    },
    {
      "x": 6,
      "y": 23,
      "z": 9,
      "name": "Plant_Leaves_Gear"
    },
    {
      "x": 6,
      "y": 17,
      "z": 10,
      "name": "Plant_Leaves_Gear"
    },
    {
      "x": 6,
      "y": 18,
      "z": 10,
      "name": "Plant_Leaves_Gear"
    },
    {
      "x": 6,
      "y": 21,
      "z": 10,
      "name": "Plant_Leaves_Gear"
    },
    {
      "x": 6,
      "y": 22,
      "z": 10,
      "name": "Plant_Leaves_Gear"
    },
    {
      "x": 6,
      "y": 23,
      "z": 10,
      "name": "Plant_Leaves_Gear"
    },
    {
      "x": 6,
      "y": 17,
      "z": 11,
      "name": "Plant_Leaves_Gear"
    },
    {
      "x": 6,
      "y": 18,
      "z": 11,
      "name": "Plant_Leaves_Gear"
    },
    {
      "x": 6,
      "y": 21,
      "z": 11,
      "name": "Plant_Leaves_Gear"
    },
    {
      "x": 6,
      "y": 9,
      "z": 12,
      "name": "Plant_Leaves_Gear"
    },
    {
      "x": 6,
      "y": 10,
      "z": 12,
      "name": "Plant_Leaves_Gear"
    },
    {
      "x": 6,
      "y": 11,
      "z": 12,
      "name": "Plant_Leaves_Gear"
    },
    {
      "x": 6,
      "y": 14,
      "z": 12,
      "name": "Plant_Leaves_Gear"
    },
    {
      "x": 6,
      "y": 15,
      "z": 12,
      "name": "Plant_Leaves_Gear"
    },
    {
      "x": 6,
      "y": 9,
      "z": 13,
      "name": "Plant_Leaves_Gear"
    },
    {
      "x": 6,
      "y": 10,
      "z": 13,
      "name": "Plant_Leaves_Gear"
    },
    {
      "x": 6,
      "y": 11,
      "z": 13,
      "name": "Plant_Leaves_Gear"
    },
    {
      "x": 6,
      "y": 13,
      "z": 13,
      "name": "Plant_Leaves_Gear"
    },
    {
      "x": 6,
      "y": 14,
      "z": 13,
      "name": "Plant_Leaves_Gear"
    },
    {
      "x": 6,
      "y": 10,
      "z": 14,
      "name": "Plant_Leaves_Gear"
    },
    {
      "x": 7,
      "y": 11,
      "z": 3,
      "name": "Plant_Leaves_Gear"
    },
    {
      "x": 7,
      "y": 12,
      "z": 3,
      "name": "Plant_Leaves_Gear"
    },
    {
      "x": 7,
      "y": 13,
      "z": 3,
      "name": "Plant_Leaves_Gear"
    },
    {
      "x": 7,
      "y": 13,
      "z": 4,
      "name": "Wood_Gear_Branch_Long",
      "rotation": 4
    },
    {
      "x": 7,
      "y": 14,
      "z": 4,
      "name": "Plant_Leaves_Gear"
    },
    {
      "x": 7,
      "y": 15,
      "z": 4,
      "name": "Plant_Leaves_Gear"
    },
    {
      "x": 7,
      "y": 18,
      "z": 4,
      "name": "Plant_Leaves_Gear"
    },
    {
      "x": 7,
      "y": 19,
      "z": 4,
      "name": "Plant_Leaves_Gear"
    },
    {
      "x": 7,
      "y": 13,
      "z": 5,
      "name": "Wood_Gear_Branch_Long",
      "rotation": 4
    },
    {
      "x": 7,
      "y": 16,
      "z": 5,
      "name": "Plant_Leaves_Gear"
    },
    {
      "x": 7,
      "y": 19,
      "z": 5,
      "name": "Plant_Leaves_Gear"
    },
    {
      "x": 7,
      "y": 20,
      "z": 5,
      "name": "Plant_Leaves_Gear"
    },
    {
      "x": 7,
      "y": 12,
      "z": 6,
      "name": "Wood_Gear_Trunk_Full"
    },
    {
      "x": 7,
      "y": 13,
      "z": 6,
      "name": "Wood_Gear_Trunk_Full"
    },
    {
      "x": 7,
      "y": 14,
      "z": 6,
      "name": "Wood_Gear_Branch_Long"
    },
    {
      "x": 7,
      "y": 15,
      "z": 6,
      "name": "Wood_Gear_Branch_Long"
    },
    {
      "x": 7,
      "y": 16,
      "z": 6,
      "name": "Plant_Leaves_Gear"
    },
    {
      "x": 7,
      "y": 17,
      "z": 6,
      "name": "Plant_Leaves_Gear"
    },
    {
      "x": 7,
      "y": 19,
      "z": 6,
      "name": "Wood_Gear_Branch_Long",
      "rotation": 4
    },
    {
      "x": 7,
      "y": 23,
      "z": 6,
      "name": "Plant_Leaves_Gear"
    },
    {
      "x": 7,
      "y": 24,
      "z": 6,
      "name": "Plant_Leaves_Gear"
    },
    {
      "x": 7,
      "y": 25,
      "z": 6,
      "name": "Plant_Leaves_Gear"
    },
    {
      "x": 7,
      "y": 12,
      "z": 7,
      "name": "Wood_Gear_Trunk_Full"
    },
    {
      "x": 7,
      "y": 19,
      "z": 7,
      "name": "Wood_Gear_Branch_Long",
      "rotation": 4
    },
    {
      "x": 7,
      "y": 21,
      "z": 7,
      "name": "Wood_Gear_Branch_Corner",
      "rotation": 2
    },
    {
      "x": 7,
      "y": 22,
      "z": 7,
      "name": "Wood_Gear_Branch_Long"
    },
    {
      "x": 7,
      "y": 23,
      "z": 7,
      "name": "Wood_Gear_Branch_Long"
    },
    {
      "x": 7,
      "y": 24,
      "z": 7,
      "name": "Wood_Gear_Branch_Long"
    },
    {
      "x": 7,
      "y": 25,
      "z": 7,
      "name": "Plant_Leaves_Gear"
    },
    {
      "x": 7,
      "y": 3,
      "z": 8,
      "name": "Wood_Gear_Trunk"
    },
    {
      "x": 7,
      "y": 4,
      "z": 8,
      "name": "Wood_Gear_Trunk"
    },
    {
      "x": 7,
      "y": 5,
      "z": 8,
      "name": "Wood_Gear_Trunk"
    },
    {
      "x": 7,
      "y": 6,
      "z": 8,
      "name": "Wood_Gear_Trunk"
    },
    {
      "x": 7,
      "y": 7,
      "z": 8,
      "name": "Wood_Gear_Trunk"
    },
    {
      "x": 7,
      "y": 8,
      "z": 8,
      "name": "Wood_Gear_Trunk"
    },
    {
      "x": 7,
      "y": 9,
      "z": 8,
      "name": "Wood_Gear_Trunk"
    },
    {
      "x": 7,
      "y": 10,
      "z": 8,
      "name": "Wood_Gear_Trunk_Full"
    },
    {
      "x": 7,
      "y": 11,
      "z": 8,
      "name": "Wood_Gear_Trunk"
    },
    {
      "x": 7,
      "y": 12,
      "z": 8,
      "name": "Wood_Gear_Trunk"
    },
    {
      "x": 7,
      "y": 13,
      "z": 8,
      "name": "Wood_Gear_Trunk_Full"
    },
    {
      "x": 7,
      "y": 14,
      "z": 8,
      "name": "Wood_Gear_Trunk"
    },
    {
      "x": 7,
      "y": 15,
      "z": 8,
      "name": "Wood_Gear_Trunk"
    },
    {
      "x": 7,
      "y": 16,
      "z": 8,
      "name": "Wood_Gear_Trunk"
    },
    {
      "x": 7,
      "y": 17,
      "z": 8,
      "name": "Wood_Gear_Trunk"
    },
    {
      "x": 7,
      "y": 18,
      "z": 8,
      "name": "Wood_Gear_Trunk"
    },
    {
      "x": 7,
      "y": 19,
      "z": 8,
      "name": "Wood_Gear_Trunk"
    },
    {
      "x": 7,
      "y": 20,
      "z": 8,
      "name": "Wood_Gear_Trunk"
    },
    {
      "x": 7,
      "y": 21,
      "z": 8,
      "name": "Wood_Gear_Trunk_Full"
    },
    {
      "x": 7,
      "y": 25,
      "z": 8,
      "name": "Plant_Leaves_Gear"
    },
    {
      "x": 7,
      "y": 10,
      "z": 9,
      "name": "Wood_Gear_Trunk_Full"
    },
    {
      "x": 7,
      "y": 17,
      "z": 9,
      "name": "Wood_Gear_Branch_Long",
      "rotation": 4
    },
    {
      "x": 7,
      "y": 20,
      "z": 9,
      "name": "Wood_Gear_Branch_Corner"
    },
    {
      "x": 7,
      "y": 21,
      "z": 9,
      "name": "Wood_Gear_Branch_Long"
    },
    {
      "x": 7,
      "y": 22,
      "z": 9,
      "name": "Wood_Gear_Branch_Long"
    },
    {
      "x": 7,
      "y": 23,
      "z": 9,
      "name": "Wood_Gear_Branch_Long"
    },
    {
      "x": 7,
      "y": 24,
      "z": 9,
      "name": "Plant_Leaves_Gear"
    },
    {
      "x": 7,
      "y": 10,
      "z": 10,
      "name": "Wood_Gear_Trunk_Full"
    },
    {
      "x": 7,
      "y": 17,
      "z": 10,
      "name": "Wood_Gear_Branch_Long",
      "rotation": 4
    },
    {
      "x": 7,
      "y": 21,
      "z": 10,
      "name": "Plant_Leaves_Gear"
    },
    {
      "x": 7,
      "y": 22,
      "z": 10,
      "name": "Plant_Leaves_Gear"
    },
    {
      "x": 7,
      "y": 23,
      "z": 10,
      "name": "Plant_Leaves_Gear"
    },
    {
      "x": 7,
      "y": 10,
      "z": 11,
      "name": "Wood_Gear_Branch_Long",
      "rotation": 4
    },
    {
      "x": 7,
      "y": 17,
      "z": 11,
      "name": "Plant_Leaves_Gear"
    },
    {
      "x": 7,
      "y": 18,
      "z": 11,
      "name": "Plant_Leaves_Gear"
    },
    {
      "x": 7,
      "y": 19,
      "z": 11,
      "name": "Plant_Leaves_Gear"
    },
    {
      "x": 7,
      "y": 22,
      "z": 11,
      "name": "Plant_Leaves_Gear"
    },
    {
      "x": 7,
      "y": 10,
      "z": 12,
      "name": "Wood_Gear_Branch_Long",
      "rotation": 4
    },
    {
      "x": 7,
      "y": 14,
      "z": 12,
      "name": "Plant_Leaves_Gear"
    },
    {
      "x": 7,
      "y": 16,
      "z": 12,
      "name": "Plant_Leaves_Gear"
    },
    {
      "x": 7,
      "y": 17,
      "z": 12,
      "name": "Plant_Leaves_Gear"
    },
    {
      "x": 7,
      "y": 18,
      "z": 12,
      "name": "Plant_Leaves_Gear"
    },
    {
      "x": 7,
      "y": 10,
      "z": 13,
      "name": "Wood_Gear_Branch_Corner"
    },
    {
      "x": 7,
      "y": 11,
      "z": 13,
      "name": "Plant_Leaves_Gear"
    },
    {
      "x": 7,
      "y": 12,
      "z": 13,
      "name": "Plant_Leaves_Gear"
    },
    {
      "x": 7,
      "y": 13,
      "z": 13,
      "name": "Plant_Leaves_Gear"
    },
    {
      "x": 7,
      "y": 10,
      "z": 14,
      "name": "Plant_Leaves_Gear"
    },
    {
      "x": 7,
      "y": 11,
      "z": 14,
      "name": "Plant_Leaves_Gear"
    },
    {
      "x": 8,
      "y": 12,
      "z": 3,
      "name": "Plant_Leaves_Gear"
    },
    {
      "x": 8,
      "y": 13,
      "z": 3,
      "name": "Plant_Leaves_Gear"
    },
    {
      "x": 8,
      "y": 14,
      "z": 3,
      "name": "Plant_Leaves_Gear"
    },
    {
      "x": 8,
      "y": 12,
      "z": 4,
      "name": "Plant_Leaves_Gear"
    },
    {
      "x": 8,
      "y": 13,
      "z": 4,
      "name": "Plant_Leaves_Gear"
    },
    {
      "x": 8,
      "y": 14,
      "z": 4,
      "name": "Plant_Leaves_Gear"
    },
    {
      "x": 8,
      "y": 16,
      "z": 5,
      "name": "Plant_Leaves_Gear"
    },
    {
      "x": 8,
      "y": 19,
      "z": 5,
      "name": "Plant_Leaves_Gear"
    },
    {
      "x": 8,
      "y": 13,
      "z": 6,
      "name": "Wood_Gear_Branch_Long",
      "rotation": 5
    },
    {
      "x": 8,
      "y": 15,
      "z": 6,
      "name": "Plant_Leaves_Gear"
    },
    {
      "x": 8,
      "y": 16,
      "z": 6,
      "name": "Plant_Leaves_Gear"
    },
    {
      "x": 8,
      "y": 19,
      "z": 6,
      "name": "Plant_Leaves_Gear"
    },
    {
      "x": 8,
      "y": 22,
      "z": 6,
      "name": "Plant_Leaves_Gear"
    },
    {
      "x": 8,
      "y": 15,
      "z": 7,
      "name": "Plant_Leaves_Gear"
    },
    {
      "x": 8,
      "y": 22,
      "z": 7,
      "name": "Plant_Leaves_Gear"
    },
    {
      "x": 8,
      "y": 24,
      "z": 7,
      "name": "Plant_Leaves_Gear"
    },
    {
      "x": 8,
      "y": 25,
      "z": 7,
      "name": "Plant_Leaves_Gear"
    },
    {
      "x": 8,
      "y": 11,
      "z": 8,
      "name": "Wood_Gear_Trunk_Full"
    },
    {
      "x": 8,
      "y": 19,
      "z": 8,
      "name": "Wood_Gear_Branch_Long",
      "rotation": 5
    },
    {
      "x": 8,
      "y": 21,
      "z": 8,
      "name": "Wood_Gear_Branch_Corner",
      "rotation": 1
    },
    {
      "x": 8,
      "y": 22,
      "z": 8,
      "name": "Plant_Leaves_Gear"
    },
    {
      "x": 8,
      "y": 23,
      "z": 8,
      "name": "Plant_Leaves_Gear"
    },
    {
      "x": 8,
      "y": 25,
      "z": 8,
      "name": "Plant_Leaves_Gear"
    },
    {
      "x": 8,
      "y": 23,
      "z": 9,
      "name": "Plant_Leaves_Gear"
    },
    {
      "x": 8,
      "y": 24,
      "z": 9,
      "name": "Plant_Leaves_Gear"
    },
    {
      "x": 8,
      "y": 17,
      "z": 10,
      "name": "Plant_Leaves_Gear"
    },
    {
      "x": 8,
      "y": 22,
      "z": 10,
      "name": "Plant_Leaves_Gear"
    },
    {
      "x": 8,
      "y": 23,
      "z": 10,
      "name": "Plant_Leaves_Gear"
    },
    {
      "x": 8,
      "y": 17,
      "z": 11,
      "name": "Plant_Leaves_Gear"
    },
    {
      "x": 8,
      "y": 18,
      "z": 11,
      "name": "Plant_Leaves_Gear"
    },
    {
      "x": 8,
      "y": 19,
      "z": 11,
      "name": "Plant_Leaves_Gear"
    },
    {
      "x": 8,
      "y": 10,
      "z": 12,
      "name": "Plant_Leaves_Gear"
    },
    {
      "x": 8,
      "y": 11,
      "z": 12,
      "name": "Plant_Leaves_Gear"
    },
    {
      "x": 8,
      "y": 16,
      "z": 12,
      "name": "Plant_Leaves_Gear"
    },
    {
      "x": 8,
      "y": 10,
      "z": 13,
      "name": "Plant_Leaves_Gear"
    },
    {
      "x": 8,
      "y": 11,
      "z": 13,
      "name": "Plant_Leaves_Gear"
    },
    {
      "x": 8,
      "y": 12,
      "z": 13,
      "name": "Plant_Leaves_Gear"
    },
    {
      "x": 8,
      "y": 10,
      "z": 14,
      "name": "Plant_Leaves_Gear"
    },
    {
      "x": 9,
      "y": 13,
      "z": 3,
      "name": "Plant_Leaves_Gear"
    },
    {
      "x": 9,
      "y": 11,
      "z": 4,
      "name": "Plant_Leaves_Gear"
    },
    {
      "x": 9,
      "y": 12,
      "z": 4,
      "name": "Plant_Leaves_Gear"
    },
    {
      "x": 9,
      "y": 13,
      "z": 4,
      "name": "Plant_Leaves_Gear"
    },
    {
      "x": 9,
      "y": 14,
      "z": 4,
      "name": "Plant_Leaves_Gear"
    },
    {
      "x": 9,
      "y": 11,
      "z": 5,
      "name": "Plant_Leaves_Gear"
    },
    {
      "x": 9,
      "y": 12,
      "z": 5,
      "name": "Plant_Leaves_Gear"
    },
    {
      "x": 9,
      "y": 13,
      "z": 5,
      "name": "Plant_Leaves_Gear"
    },
    {
      "x": 9,
      "y": 14,
      "z": 5,
      "name": "Plant_Leaves_Gear"
    },
    {
      "x": 9,
      "y": 12,
      "z": 6,
      "name": "Wood_Gear_Branch_Long",
      "rotation": 4
    },
    {
      "x": 9,
      "y": 13,
      "z": 6,
      "name": "Wood_Gear_Branch_Long",
      "rotation": 5
    },
    {
      "x": 9,
      "y": 14,
      "z": 6,
      "name": "Plant_Leaves_Gear"
    },
    {
      "x": 9,
      "y": 15,
      "z": 6,
      "name": "Plant_Leaves_Gear"
    },
    {
      "x": 9,
      "y": 17,
      "z": 6,
      "name": "Plant_Leaves_Gear"
    },
    {
      "x": 9,
      "y": 18,
      "z": 6,
      "name": "Plant_Leaves_Gear"
    },
    {
      "x": 9,
      "y": 21,
      "z": 6,
      "name": "Plant_Leaves_Gear"
    },
    {
      "x": 9,
      "y": 22,
      "z": 6,
      "name": "Plant_Leaves_Gear"
    },
    {
      "x": 9,
      "y": 12,
      "z": 7,
      "name": "Wood_Gear_Branch_Long",
      "rotation": 4
    },
    {
      "x": 9,
      "y": 15,
      "z": 7,
      "name": "Plant_Leaves_Gear"
    },
    {
      "x": 9,
      "y": 16,
      "z": 7,
      "name": "Plant_Leaves_Gear"
    },
    {
      "x": 9,
      "y": 18,
      "z": 7,
      "name": "Plant_Leaves_Gear"
    },
    {
      "x": 9,
      "y": 19,
      "z": 7,
      "name": "Plant_Leaves_Gear"
    },
    {
      "x": 9,
      "y": 22,
      "z": 7,
      "name": "Plant_Leaves_Gear"
    },
    {
      "x": 9,
      "y": 23,
      "z": 7,
      "name": "Plant_Leaves_Gear"
    },
    {
      "x": 9,
      "y": 11,
      "z": 8,
      "name": "Wood_Gear_Trunk_Full"
    },
    {
      "x": 9,
      "y": 12,
      "z": 8,
      "name": "Wood_Gear_Trunk_Full"
    },
    {
      "x": 9,
      "y": 13,
      "z": 8,
      "name": "Wood_Gear_Branch_Long"
    },
    {
      "x": 9,
      "y": 14,
      "z": 8,
      "name": "Wood_Gear_Branch_Long"
    },
    {
      "x": 9,
      "y": 15,
      "z": 8,
      "name": "Plant_Leaves_Gear"
    },
    {
      "x": 9,
      "y": 16,
      "z": 8,
      "name": "Plant_Leaves_Gear"
    },
    {
      "x": 9,
      "y": 19,
      "z": 8,
      "name": "Wood_Gear_Branch_Long",
      "rotation": 5
    },
    {
      "x": 9,
      "y": 22,
      "z": 8,
      "name": "Plant_Leaves_Gear"
    },
    {
      "x": 9,
      "y": 23,
      "z": 8,
      "name": "Plant_Leaves_Gear"
    },
    {
      "x": 9,
      "y": 12,
      "z": 9,
      "name": "Wood_Gear_Branch_Long",
      "rotation": 4
    },
    {
      "x": 9,
      "y": 15,
      "z": 9,
      "name": "Plant_Leaves_Gear"
    },
    {
      "x": 9,
      "y": 19,
      "z": 9,
      "name": "Plant_Leaves_Gear"
    },
    {
      "x": 9,
      "y": 22,
      "z": 9,
      "name": "Plant_Leaves_Gear"
    },
    {
      "x": 9,
      "y": 23,
      "z": 9,
      "name": "Plant_Leaves_Gear"
    },
    {
      "x": 9,
      "y": 12,
      "z": 10,
      "name": "Wood_Gear_Branch_Long",
      "rotation": 4
    },
    {
      "x": 9,
      "y": 13,
      "z": 10,
      "name": "Plant_Leaves_Gear"
    },
    {
      "x": 9,
      "y": 17,
      "z": 10,
      "name": "Plant_Leaves_Gear"
    },
    {
      "x": 9,
      "y": 18,
      "z": 10,
      "name": "Plant_Leaves_Gear"
    },
    {
      "x": 9,
      "y": 19,
      "z": 10,
      "name": "Plant_Leaves_Gear"
    },
    {
      "x": 9,
      "y": 11,
      "z": 11,
      "name": "Plant_Leaves_Gear"
    },
    {
      "x": 9,
      "y": 12,
      "z": 11,
      "name": "Plant_Leaves_Gear"
    },
    {
      "x": 9,
      "y": 16,
      "z": 11,
      "name": "Plant_Leaves_Gear"
    },
    {
      "x": 9,
      "y": 17,
      "z": 11,
      "name": "Plant_Leaves_Gear"
    },
    {
      "x": 9,
      "y": 18,
      "z": 11,
      "name": "Plant_Leaves_Gear"
    },
    {
      "x": 9,
      "y": 10,
      "z": 12,
      "name": "Plant_Leaves_Gear"
    },
    {
      "x": 9,
      "y": 11,
      "z": 12,
      "name": "Plant_Leaves_Gear"
    },
    {
      "x": 9,
      "y": 10,
      "z": 13,
      "name": "Plant_Leaves_Gear"
    },
    {
      "x": 10,
      "y": 11,
      "z": 4,
      "name": "Plant_Leaves_Gear"
    },
    {
      "x": 10,
      "y": 12,
      "z": 4,
      "name": "Plant_Leaves_Gear"
    },
    {
      "x": 10,
      "y": 11,
      "z": 5,
      "name": "Plant_Leaves_Gear"
    },
    {
      "x": 10,
      "y": 12,
      "z": 5,
      "name": "Plant_Leaves_Gear"
    },
    {
      "x": 10,
      "y": 13,
      "z": 5,
      "name": "Plant_Leaves_Gear"
    },
    {
      "x": 10,
      "y": 13,
      "z": 6,
      "name": "Plant_Leaves_Gear"
    },
    {
      "x": 10,
      "y": 14,
      "z": 6,
      "name": "Plant_Leaves_Gear"
    },
    {
      "x": 10,
      "y": 18,
      "z": 6,
      "name": "Plant_Leaves_Gear"
    },
    {
      "x": 10,
      "y": 19,
      "z": 6,
      "name": "Plant_Leaves_Gear"
    },
    {
      "x": 10,
      "y": 14,
      "z": 7,
      "name": "Plant_Leaves_Gear"
    },
    {
      "x": 10,
      "y": 15,
      "z": 7,
      "name": "Plant_Leaves_Gear"
    },
    {
      "x": 10,
      "y": 17,
      "z": 7,
      "name": "Plant_Leaves_Gear"
    },
    {
      "x": 10,
      "y": 18,
      "z": 7,
      "name": "Plant_Leaves_Gear"
    },
    {
      "x": 10,
      "y": 19,
      "z": 7,
      "name": "Plant_Leaves_Gear"
    },
    {
      "x": 10,
      "y": 20,
      "z": 7,
      "name": "Plant_Leaves_Gear"
    },
    {
      "x": 10,
      "y": 21,
      "z": 7,
      "name": "Plant_Leaves_Gear"
    },
    {
      "x": 10,
      "y": 22,
      "z": 7,
      "name": "Plant_Leaves_Gear"
    },
    {
      "x": 10,
      "y": 12,
      "z": 8,
      "name": "Wood_Gear_Branch_Long",
      "rotation": 5
    },
    {
      "x": 10,
      "y": 15,
      "z": 8,
      "name": "Plant_Leaves_Gear"
    },
    {
      "x": 10,
      "y": 18,
      "z": 8,
      "name": "Plant_Leaves_Gear"
    },
    {
      "x": 10,
      "y": 19,
      "z": 8,
      "name": "Plant_Leaves_Gear"
    },
    {
      "x": 10,
      "y": 20,
      "z": 8,
      "name": "Plant_Leaves_Gear"
    },
    {
      "x": 10,
      "y": 21,
      "z": 8,
      "name": "Plant_Leaves_Gear"
    },
    {
      "x": 10,
      "y": 22,
      "z": 8,
      "name": "Plant_Leaves_Gear"
    },
    {
      "x": 10,
      "y": 23,
      "z": 8,
      "name": "Plant_Leaves_Gear"
    },
    {
      "x": 10,
      "y": 15,
      "z": 9,
      "name": "Plant_Leaves_Gear"
    },
    {
      "x": 10,
      "y": 18,
      "z": 9,
      "name": "Plant_Leaves_Gear"
    },
    {
      "x": 10,
      "y": 19,
      "z": 9,
      "name": "Plant_Leaves_Gear"
    },
    {
      "x": 10,
      "y": 20,
      "z": 9,
      "name": "Plant_Leaves_Gear"
    },
    {
      "x": 10,
      "y": 22,
      "z": 9,
      "name": "Plant_Leaves_Gear"
    },
    {
      "x": 10,
      "y": 13,
      "z": 10,
      "name": "Plant_Leaves_Gear"
    },
    {
      "x": 10,
      "y": 18,
      "z": 10,
      "name": "Plant_Leaves_Gear"
    },
    {
      "x": 10,
      "y": 12,
      "z": 11,
      "name": "Plant_Leaves_Gear"
    },
    {
      "x": 11,
      "y": 12,
      "z": 5,
      "name": "Plant_Leaves_Gear"
    },
    {
      "x": 11,
      "y": 11,
      "z": 6,
      "name": "Plant_Leaves_Gear"
    },
    {
      "x": 11,
      "y": 12,
      "z": 6,
      "name": "Plant_Leaves_Gear"
    },
    {
      "x": 11,
      "y": 10,
      "z": 7,
      "name": "Plant_Leaves_Gear"
    },
    {
      "x": 11,
      "y": 11,
      "z": 7,
      "name": "Plant_Leaves_Gear"
    },
    {
      "x": 11,
      "y": 12,
      "z": 7,
      "name": "Plant_Leaves_Gear"
    },
    {
      "x": 11,
      "y": 13,
      "z": 7,
      "name": "Plant_Leaves_Gear"
    },
    {
      "x": 11,
      "y": 14,
      "z": 7,
      "name": "Plant_Leaves_Gear"
    },
    {
      "x": 11,
      "y": 18,
      "z": 7,
      "name": "Plant_Leaves_Gear"
    },
    {
      "x": 11,
      "y": 19,
      "z": 7,
      "name": "Plant_Leaves_Gear"
    },
    {
      "x": 11,
      "y": 12,
      "z": 8,
      "name": "Wood_Gear_Branch_Long",
      "rotation": 5
    },
    {
      "x": 11,
      "y": 13,
      "z": 8,
      "name": "Plant_Leaves_Gear"
    },
    {
      "x": 11,
      "y": 14,
      "z": 8,
      "name": "Plant_Leaves_Gear"
    },
    {
      "x": 11,
      "y": 18,
      "z": 8,
      "name": "Plant_Leaves_Gear"
    },
    {
      "x": 11,
      "y": 19,
      "z": 8,
      "name": "Plant_Leaves_Gear"
    },
    {
      "x": 11,
      "y": 12,
      "z": 9,
      "name": "Plant_Leaves_Gear"
    },
    {
      "x": 11,
      "y": 13,
      "z": 9,
      "name": "Plant_Leaves_Gear"
    },
    {
      "x": 11,
      "y": 12,
      "z": 10,
      "name": "Plant_Leaves_Gear"
    },
    {
      "x": 11,
      "y": 13,
      "z": 10,
      "name": "Plant_Leaves_Gear"
    },
    {
      "x": 12,
      "y": 12,
      "z": 7,
      "name": "Plant_Leaves_Gear"
    },
    {
      "x": 12,
      "y": 13,
      "z": 7,
      "name": "Plant_Leaves_Gear"
    },
    {
      "x": 12,
      "y": 10,
      "z": 8,
      "name": "Plant_Leaves_Gear"
    },
    {
      "x": 12,
      "y": 11,
      "z": 8,
      "name": "Plant_Leaves_Gear"
    },
    {
      "x": 12,
      "y": 12,
      "z": 8,
      "name": "Plant_Leaves_Gear"
    },
    {
      "x": 12,
      "y": 11,
      "z": 9,
      "name": "Plant_Leaves_Gear"
    },
    {
      "x": 12,
      "y": 12,
      "z": 9,
      "name": "Plant_Leaves_Gear"
    },
    {
      "x": 12,
      "y": 13,
      "z": 9,
      "name": "Plant_Leaves_Gear"
    },
    {
      "x": 12,
      "y": 12,
      "z": 10,
      "name": "Plant_Leaves_Gear"
    }
  ]
}