{
  "version": 8,
  "blockIdVersion": 11,
  "anchorX": 4,
  "anchorY": 0,
  "anchorZ": 4,
  "blocks": [
    {
      "x": 1,
      "y": 5,
      "z": 2,
      "name": "Plant_Leaves_Gear"
    },
    {
      "x": 1,
      "y": 5,
      "z": 3,
      "name": "Plant_Leaves_Gear"
    },
    {
      "x": 1,
      "y": 6,
      "z": 3,
      "name": "Plant_Leaves_Gear"
    },
    {
      "x": 1,
      "y": 7,
      "z": 3,
      "name": "Plant_Leaves_Gear"
    },
    {
      "x": 1,
      "y": 9,
      "z": 3,
      "name": "Plant_Leaves_Gear"
    },
    {
      "x": 1,
      "y": 10,
      "z": 3,
      "name": "Plant_Leaves_Gear"
    },
    {
      "x": 1,
      "y": 5,
      "z": 4,
      "name": "Plant_Leaves_Gear"
    },
    {
      "x": 1,
      "y": 6,
      "z": 4,
      "name": "Plant_Leaves_Gear"
    },
    {
      "x": 1,
      "y": 7,
      "z": 4,
      "name": "Plant_Leaves_Gear"
    },
    {
      "x": 1,
      "y": 9,
      "z": 4,
      "name": "Plant_Leaves_Gear"
    },
    {
      "x": 1,
      "y": 10,
      "z": 4,
      "name": "Plant_Leaves_Gear"
    },
    {
      "x": 1,
      "y": 5,
      "z": 5,
      "name": "Plant_Leaves_Gear"
    },
    {
      "x": 1,
      "y": 6,
      "z": 5,
      "name": "Plant_Leaves_Gear"
    },
    {
      "x": 2,
      "y": 5,
      "z": 2,
      "name": "Plant_Leaves_Gear"
    },
    {
      "x": 2,
      "y": 6,
      "z": 2,
      "name": "Plant_Leaves_Gear"
    },
    {
      "x": 2,
      "y": 9,
      "z": 2,
      "name": "Plant_Leaves_Gear"
    },
    {
      "x": 2,
      "y": 5,
      "z": 3,
      "name": "Plant_Leaves_Gear"
    },
    {
      "x": 2,
      "y": 6,
      "z": 3,
      "name": "Plant_Leaves_Gear"
    },
    {
      "x": 2,
      "y": 7,
      "z": 3,
      "name": "Plant_Leaves_Gear"
    },
    {
      "x": 2,
      "y": 9,
      "z": 3,
      "name": "Plant_Leaves_Gear"
    },
    {
      "x": 2,
      "y": 10,
      "z": 3,
      "name": "Plant_Leaves_Gear"
    },
    {
      "x": 2,
      "y": 5,
      "z": 4,
      "name": "Wood_Gear_Branch_Long",
      "rotation": 5
    },
    {
      "x": 2,
      "y": 6,
      "z": 4,
      "name": "Plant_Leaves_Gear"
    },
    {
      "x": 2,
      "y": 7,
      "z": 4,
      "name": "Plant_Leaves_Gear"
    },
    {
      "x": 2,
      "y": 9,
      "z": 4,
      "name": "Plant_Leaves_Gear"
    },
    {
      "x": 2,
      "y": 10,
      "z": 4,
      "name": "Wood_Gear_Branch_Long",
      "rotation": 5
    },
    {
      "x": 2,
      "y": 11,
      "z": 4,
      "name": "Plant_Leaves_Gear"
    },
    {
      "x": 2,
      "y": 5,
      "z": 5,
      "name": "Plant_Leaves_Gear"
    },
    {
      "x": 2,
      "y": 6,
      "z": 5,
      "name": "Plant_Leaves_Gear"
    },
    {
      "x": 2,
      "y": 7,
      "z": 5,
      "name": "Plant_Leaves_Gear"
    },
    {
      "x": 2,
      "y": 10,
      "z": 5,
      "name": "Plant_Leaves_Gear"
    },
    {
      "x": 2,
      "y": 11,
      "z": 5,
      "name": "Plant_Leaves_Gear"
    },
    {
      "x": 2,
      "y": 5,
      "z": 6,
      "name": "Plant_Leaves_Gear"
    },
    {
      "x": 3,
      "y": 5,
      "z": 1,
      "name": "Plant_Leaves_Gear"
    },
    {
      "x": 3,
      "y": 5,
      "z": 2,
      "name": "Plant_Leaves_Gear"
    },
    {
      "x": 3,
      "y": 7,
      "z": 2,
      "name": "Plant_Leaves_Gear"
    },
    {
      "x": 3,
      "y": 9,
      "z": 2,
      "name": "Plant_Leaves_Gear"
    },
    {
      "x": 3,
      "y": 10,
      "z": 2,
      "name": "Plant_Leaves_Gear"
    },
    {
      "x": 3,
      "y": 11,
      "z": 2,
      "name": "Plant_Leaves_Gear"
    },
    {
      "x": 3,
      "y": 11,
      "z": 3,
      "name": "Plant_Leaves_Gear"
    },
    {
      "x": 3,
      "y": 5,
      "z": 4,
      "name": "Wood_Gear_Trunk_Full"
    },
    {
      "x": 3,
      "y": 9,
      "z": 4,
      "name": "Wood_Gear_Branch_Corner",
      "rotation": 3
    },
    {
      "x": 3,
      "y": 10,
      "z": 4,
      "name": "Wood_Gear_Branch_Corner",
      "rotation": 11
    },
    {
      "x": 3,
      "y": 11,
      "z": 4,
      "name": "Plant_Leaves_Gear"
    },
    {
      "x": 3,
      "y": 12,
      "z": 4,
      "name": "Plant_Leaves_Gear"
    },
    {
      "x": 3,
      "y": 11,
      "z": 5,
      "name": "Plant_Leaves_Gear"
    },
    {
      "x": 3,
      "y": 12,
      "z": 5,
      "name": "Plant_Leaves_Gear"
    },
    {
      "x": 3,
      "y": 6,
      "z": 6,
      "name": "Plant_Leaves_Gear"
    },
    {
      "x": 3,
      "y": 7,
      "z": 6,
      "name": "Plant_Leaves_Gear"
    },
    {
      "x": 3,
      "y": 8,
      "z": 6,
      "name": "Plant_Leaves_Gear"
    },
    {
      "x": 3,
      "y": 9,
      "z": 6,
      "name": "Plant_Leaves_Gear"
    },
    {
      "x": 3,
      "y": 11,
      "z": 6,
      "name": "Plant_Leaves_Gear"
    },
    {
      "x": 3,
      "y": 7,
      "z": 7,
      "name": "Plant_Leaves_Gear"
    },
    {
      "x": 3,
      "y": 8,
      "z": 7,
      "name": "Plant_Leaves_Gear"
    },
    {
      "x": 4,
      "y": 7,
      "z": 1,
      "name": "Plant_Leaves_Gear"
    },
    {
      "x": 4,
      "y": 6,
      "z": 2,
      "name": "Plant_Leaves_Gear"
    },
    {
      "x": 4,
      "y": 7,
      "z": 2,
      "name": "Plant_Leaves_Gear"
    },
    {
      "x": 4,
      "y": 8,
      "z": 2,
      "name": "Plant_Leaves_Gear"
    },
    {
      "x": 4,
      "y": 10,
      "z": 2,
      "name": "Plant_Leaves_Gear"
    },
    {
      "x": 4,
      "y": 11,
      "z": 2,
      "name": "Plant_Leaves_Gear"
    },
    {
      "x": 4,
      "y": 11,
      "z": 3,
      "name": "Plant_Leaves_Gear"
    },
    {
      "x": 4,
      "y": 12,
      "z": 3,
      "name": "Plant_Leaves_Gear"
    },
    {
      "x": 4,
      "y": 0,
      "z": 4,
      "name": "Wood_Gear_Trunk"
    },
    {
      "x": 4,
      "y": 1,
      "z": 4,
      "name": "Wood_Gear_Trunk"
    },
    {
      "x": 4,
      "y": 2,
      "z": 4,
      "name": "Wood_Gear_Trunk"
    },
    {
      "x": 4,
      "y": 3,
      "z": 4,
      "name": "Wood_Gear_Trunk"
    },
    {
      "x": 4,
      "y": 4,
      "z": 4,
      "name": "Wood_Gear_Trunk"
    },
    {
      "x": 4,
      "y": 5,
      "z": 4,
      "name": "Wood_Gear_Trunk"
    },
    {
      "x": 4,
      "y": 6,
      "z": 4,
      "name": "Wood_Gear_Trunk"
    },
    {
      "x": 4,
      "y": 7,
      "z": 4,
      "name": "Wood_Gear_Trunk"
    },
    {
      "x": 4,
      "y": 8,
      "z": 4,
      "name": "Wood_Gear_Trunk"
    },
    {
      "x": 4,
      "y": 9,
      "z": 4,
      "name": "Wood_Gear_Trunk_Full"
    },
    {
      "x": 4,
      "y": 10,
      "z": 4,
      "name": "Wood_Gear_Branch_Long"
    },
    {
      "x": 4,
      "y": 11,
      "z": 4,
      "name": "Wood_Gear_Branch_Long"
    },
    {
      "x": 4,
      "y": 12,
      "z": 4,
      "name": "Plant_Leaves_Gear"
    },
    {
      "x": 4,
      "y": 7,
      "z": 5,
      "name": "Wood_Gear_Trunk_Full"
    },
    {
      "x": 4,
      "y": 11,
      "z": 5,
      "name": "Plant_Leaves_Gear"
    },
    {
      "x": 4,
      "y": 12,
      "z": 5,
      "name": "Plant_Leaves_Gear"
    },
    {
      "x": 4,
      "y": 7,
      "z": 6,
      "name": "Wood_Gear_Branch_Long",
      "rotation": 4
    },
    {
      "x": 4,
      "y": 8,
      "z": 6,
      "name": "Plant_Leaves_Gear"
    },
    {
      "x": 4,
      "y": 9,
      "z": 6,
      "name": "Plant_Leaves_Gear"
    },
    {
      "x": 4,
      "y": 11,
      "z": 6,
      "name": "Plant_Leaves_Gear"
    },
    {
      "x": 4,
      "y": 6,
      "z": 7,
      "name": "Plant_Leaves_Gear"
    },
    {
      "x": 4,
      "y": 7,
      "z": 7,
      "name": "Plant_Leaves_Gear"
    },
    {
      "x": 4,
      "y": 8,
      "z": 7,
      "name": "Plant_Leaves_Gear"
    },
    {
      "x": 5,
      "y": 6,
      "z": 1,
      "name": "Plant_Leaves_Gear"
    },
    {
      "x": 5,
      "y": 7,
      "z": 1,
      "name": "Plant_Leaves_Gear"
    },
    {
      "x": 5,
      "y": 8,
      "z": 1,
      "name": "Plant_Leaves_Gear"
    },
    {
      "x": 5,
      "y": 6,
      "z": 2,
      "name": "Plant_Leaves_Gear"
    },
    {
      "x": 5,
      "y": 7,
      "z": 2,
      "name": "Wood_Gear_Branch_Long",
      "rotation": 4
    },
    {
      "x": 5,
      "y": 8,
      "z": 2,
      "name": "Plant_Leaves_Gear"
    },
    {
      "x": 5,
      "y": 10,
      "z": 2,
      "name": "Plant_Leaves_Gear"
    },
    {
      "x": 5,
      "y": 7,
      "z": 3,
      "name": "Wood_Gear_Branch_Long",
      "rotation": 4
    },
    {
      "x": 5,
      "y": 11,
      "z": 3,
      "name": "Plant_Leaves_Gear"
    },
    {
      "x": 5,
      "y": 4,
      "z": 4,
      "name": "Wood_Gear_Branch_Long",
      "rotation": 5
    },
    {
      "x": 5,
      "y": 7,
      "z": 4,
      "name": "Wood_Gear_Trunk_Full"
    },
    {
      "x": 5,
      "y": 9,
      "z": 4,
      "name": "Wood_Gear_Branch_Corner",
      "rotation": 1
    },
    {
      "x": 5,
      "y": 10,
      "z": 4,
      "name": "Wood_Gear_Branch_Corner",
      "rotation": 9
    },
    {
      "x": 5,
      "y": 11,
      "z": 4,
      "name": "Plant_Leaves_Gear"
    },
    {
      "x": 5,
      "y": 11,
      "z": 5,
      "name": "Plant_Leaves_Gear"
    },
    {
      "x": 5,
      "y": 6,
      "z": 6,
      "name": "Plant_Leaves_Gear"
    },
    {
      "x": 5,
      "y": 7,
      "z": 6,
      "name": "Plant_Leaves_Gear"
    },
    {
      "x": 5,
      "y": 8,
      "z": 6,
      "name": "Plant_Leaves_Gear"
    },
    {
      "x": 5,
      "y": 6,
      "z": 7,
      "name": "Plant_Leaves_Gear"
    },
    {
      "x": 5,
      "y": 7,
      "z": 7,
      "name": "Plant_Leaves_Gear"
    },
    {
      "x": 6,
      "y": 7,
      "z": 1,
      "name": "Plant_Leaves_Gear"
    },
    {
      "x": 6,
      "y": 7,
      "z": 2,
      "name": "Plant_Leaves_Gear"
    },
    {
      "x": 6,
      "y": 8,
      "z": 2,
      "name": "Plant_Leaves_Gear"
    },
    {
      "x": 6,
      "y": 4,
      "z": 3,
      "name": "Plant_Leaves_Gear"
    },
    {
      "x": 6,
      "y": 10,
      "z": 3,
      "name": "Plant_Leaves_Gear"
    },
    {
      "x": 6,
      "y": 4,
      "z": 4,
      "name": "Plant_Leaves_Gear"
    },
    {
      "x": 6,
      "y": 5,
      "z": 4,
      "name": "Plant_Leaves_Gear"
    },
    {
      "x": 6,
      "y": 7,
      "z": 4,
      "name": "Wood_Gear_Branch_Long",
      "rotation": 5
    },
    {
      "x": 6,
      "y": 9,
      "z": 4,
      "name": "Plant_Leaves_Gear"
    },
    {
      "x": 6,
      "y": 10,
      "z": 4,
      "name": "Plant_Leaves_Gear"
    },
    {
      "x": 6,
      "y": 4,
      "z": 5,
      "name": "Plant_Leaves_Gear"
    },
    {
      "x": 6,
      "y": 8,
      "z": 5,
      "name": "Plant_Leaves_Gear"
    },
    {
      "x": 6,
      "y": 9,
      "z": 5,
      "name": "Plant_Leaves_Gear"
    },
    {
      "x": 6,
      "y": 10,
      "z": 5,
      "name": "Plant_Leaves_Gear"
    },
    {
      "x": 7,
      "y": 6,
      "z": 3,
      "name": "Plant_Leaves_Gear"
    },
    {
      "x": 7,
      "y": 7,
      "z": 3,
      "name": "Plant_Leaves_Gear"
    },
    {
      "x": 7,
      "y": 8,
      "z": 3,
      "name": "Plant_Leaves_Gear"
    },
    {
      "x": 7,
      "y": 4,
      "z": 4,
      "name": "Plant_Leaves_Gear"
    },
    {
      "x": 7,
      "y": 6,
      "z": 4,
      "name": "Plant_Leaves_Gear"
    },
    {
      "x": 7,
      "y": 7,
      "z": 4,
      "name": "Plant_Leaves_Gear"
    },
    {
      "x": 7,
      "y": 8,
      "z": 4,
      "name": "Plant_Leaves_Gear"
    },
    {
      "x": 7,
      "y": 9,
      "z": 4,
      "name": "Plant_Leaves_Gear"
    },
    {
      "x": 7,
      "y": 6,
      "z": 5,
      "name": "Plant_Leaves_Gear"
    },
    {
      "x": 7,
      "y": 7,
      "z": 5,
      "name": "Plant_Leaves_Gear"
    },
    {
      "x": 7,
      "y": 8,
      "z": 5,
      "name": "Plant_Leaves_Gear"
    },
    {
      "x": 7,
      "y": 9,
      "z": 5,
      "name": "Plant_Leaves_Gear"
    },
    {
      "x": 7,
      "y": 7,
      "z": 6,
      "name": "Plant_Leaves_Gear"
    }
  ]
}