{
  "version": 8,
  "blockIdVersion": 11,
  "anchorX": 7,
  "anchorY": 5,
  "anchorZ": 5,
  "blocks": [
    {
      "x": 2,
      "y": 11,
      "z": 4,
      "name": "Plant_Leaves_Gear"
    },
    {
      "x": 2,
      "y": 12,
      "z": 4,
      "name": "Plant_Leaves_Gear"
    },
    {
      "x": 2,
      "y": 13,
      "z": 4,
      "name": "Plant_Leaves_Gear"
    },
    {
      "x": 2,
      "y": 11,
      "z": 5,
      "name": "Plant_Leaves_Gear"
    },
    {
      "x": 2,
      "y": 12,
      "z": 5,
      "name": "Plant_Leaves_Gear"
    },
    {
      "x": 2,
      "y": 13,
      "z": 5,
      "name": "Plant_Leaves_Gear"
    },
    {
      "x": 2,
      "y": 11,
      "z": 6,
      "name": "Plant_Leaves_Gear"
    },
    {
      "x": 2,
      "y": 12,
      "z": 6,
      "name": "Plant_Leaves_Gear"
    },
    {
      "x": 2,
      "y": 11,
      "z": 7,
      "name": "Plant_Leaves_Gear"
    },
    {
      "x": 3,
      "y": 11,
      "z": 2,
      "name": "Plant_Leaves_Gear"
    },
    {
      "x": 3,
      "y": 11,
      "z": 3,
      "name": "Plant_Leaves_Gear"
    },
    {
      "x": 3,
      "y": 12,
      "z": 3,
      "name": "Plant_Leaves_Gear"
    },
    {
      "x": 3,
      "y": 12,
      "z": 4,
      "name": "Plant_Leaves_Gear"
    },
    {
      "x": 3,
      "y": 13,
      "z": 4,
      "name": "Plant_Leaves_Gear"
    },
    {
      "x": 3,
      "y": 15,
      "z": 4,
      "name": "Plant_Leaves_Gear"
    },
    {
      "x": 3,
      "y": 11,
      "z": 5,
      "name": "Wood_Gear_Branch_Long",
      "rotation": 5
    },
    {
      "x": 3,
      "y": 12,
      "z": 5,
      "name": "Plant_Leaves_Gear"
    },
    {
      "x": 3,
      "y": 13,
      "z": 5,
      "name": "Plant_Leaves_Gear"
    },
    {
      "x": 3,
      "y": 15,
      "z": 5,
      "name": "Plant_Leaves_Gear"
    },
    {
      "x": 3,
      "y": 16,
      "z": 5,
      "name": "Plant_Leaves_Gear"
    },
    {
      "x": 3,
      "y": 11,
      "z": 6,
      "name": "Plant_Leaves_Gear"
    },
    {
      "x": 3,
      "y": 12,
      "z": 6,
      "name": "Plant_Leaves_Gear"
    },
    {
      "x": 3,
      "y": 13,
      "z": 6,
      "name": "Plant_Leaves_Gear"
    },
    {
      "x": 3,
      "y": 15,
      "z": 6,
      "name": "Plant_Leaves_Gear"
    },
    {
      "x": 3,
      "y": 16,
      "z": 6,
      "name": "Plant_Leaves_Gear"
    },
    {
      "x": 3,
      "y": 11,
      "z": 7,
      "name": "Plant_Leaves_Gear"
    },
    {
      "x": 3,
      "y": 12,
      "z": 7,
      "name": "Plant_Leaves_Gear"
    },
    {
      "x": 4,
      "y": 11,
      "z": 2,
      "name": "Plant_Leaves_Gear"
    },
    {
      "x": 4,
      "y": 13,
      "z": 2,
      "name": "Plant_Leaves_Gear"
    },
    {
      "x": 4,
      "y": 11,
      "z": 3,
      "name": "Plant_Leaves_Gear"
    },
    {
      "x": 4,
      "y": 12,
      "z": 3,
      "name": "Plant_Leaves_Gear"
    },
    {
      "x": 4,
      "y": 13,
      "z": 3,
      "name": "Plant_Leaves_Gear"
    },
    {
      "x": 4,
      "y": 15,
      "z": 3,
      "name": "Plant_Leaves_Gear"
    },
    {
      "x": 4,
      "y": 16,
      "z": 3,
      "name": "Plant_Leaves_Gear"
    },
    {
      "x": 4,
      "y": 15,
      "z": 4,
      "name": "Plant_Leaves_Gear"
    },
    {
      "x": 4,
      "y": 16,
      "z": 4,
      "name": "Plant_Leaves_Gear"
    },
    {
      "x": 4,
      "y": 11,
      "z": 5,
      "name": "Wood_Gear_Branch_Long",
      "rotation": 5
    },
    {
      "x": 4,
      "y": 15,
      "z": 5,
      "name": "Plant_Leaves_Gear"
    },
    {
      "x": 4,
      "y": 16,
      "z": 5,
      "name": "Plant_Leaves_Gear"
    },
    {
      "x": 4,
      "y": 17,
      "z": 5,
      "name": "Plant_Leaves_Gear"
    },
    {
      "x": 4,
      "y": 18,
      "z": 5,
      "name": "Plant_Leaves_Gear"
    },
    {
      "x": 4,
      "y": 15,
      "z": 6,
      "name": "Plant_Leaves_Gear"
    },
    {
      "x": 4,
      "y": 17,
      "z": 6,
      "name": "Plant_Leaves_Gear"
    },
    {
      "x": 4,
      "y": 12,
      "z": 7,
      "name": "Plant_Leaves_Gear"
    },
    {
      "x": 4,
      "y": 12,
      "z": 8,
      "name": "Plant_Leaves_Gear"
    },
    {
      "x": 4,
      "y": 13,
      "z": 8,
      "name": "Plant_Leaves_Gear"
    },
    {
      "x": 5,
      "y": 13,
      "z": 0,
      "name": "Plant_Leaves_Gear"
    },
    {
      "x": 5,
      "y": 13,
      "z": 1,
      "name": "Plant_Leaves_Gear"
    },
    {
      "x": 5,
      "y": 9,
      "z": 2,
      "name": "Plant_Leaves_Gear"
    },
    {
      "x": 5,
      "y": 11,
      "z": 2,
      "name": "Plant_Leaves_Gear"
    },
    {
      "x": 5,
      "y": 13,
      "z": 2,
      "name": "Plant_Leaves_Gear"
    },
    {
      "x": 5,
      "y": 14,
      "z": 2,
      "name": "Plant_Leaves_Gear"
    },
    {
      "x": 5,
      "y": 11,
      "z": 3,
      "name": "Plant_Leaves_Gear"
    },
    {
      "x": 5,
      "y": 12,
      "z": 3,
      "name": "Plant_Leaves_Gear"
    },
    {
      "x": 5,
      "y": 13,
      "z": 3,
      "name": "Plant_Leaves_Gear"
    },
    {
      "x": 5,
      "y": 14,
      "z": 3,
      "name": "Plant_Leaves_Gear"
    },
    {
      "x": 5,
      "y": 16,
      "z": 3,
      "name": "Plant_Leaves_Gear"
    },
    {
      "x": 5,
      "y": 11,
      "z": 4,
      "name": "Wood_Gear_Branch_Long",
      "rotation": 4
    },
    {
      "x": 5,
      "y": 16,
      "z": 4,
      "name": "Plant_Leaves_Gear"
    },
    {
      "x": 5,
      "y": 17,
      "z": 4,
      "name": "Plant_Leaves_Gear"
    },
    {
      "x": 5,
      "y": 18,
      "z": 4,
      "name": "Plant_Leaves_Gear"
    },
    {
      "x": 5,
      "y": 19,
      "z": 4,
      "name": "Plant_Leaves_Gear"
    },
    {
      "x": 5,
      "y": 11,
      "z": 5,
      "name": "Wood_Gear_Trunk_Full"
    },
    {
      "x": 5,
      "y": 12,
      "z": 5,
      "name": "Wood_Gear_Branch_Long"
    },
    {
      "x": 5,
      "y": 13,
      "z": 5,
      "name": "Wood_Gear_Branch_Long"
    },
    {
      "x": 5,
      "y": 14,
      "z": 5,
      "name": "Wood_Gear_Branch_Long"
    },
    {
      "x": 5,
      "y": 15,
      "z": 5,
      "name": "Wood_Gear_Branch_Long"
    },
    {
      "x": 5,
      "y": 16,
      "z": 5,
      "name": "Plant_Leaves_Gear"
    },
    {
      "x": 5,
      "y": 17,
      "z": 5,
      "name": "Plant_Leaves_Gear"
    },
    {
      "x": 5,
      "y": 18,
      "z": 5,
      "name": "Plant_Leaves_Gear"
    },
    {
      "x": 5,
      "y": 19,
      "z": 5,
      "name": "Plant_Leaves_Gear"
    },
    {
      "x": 5,
      "y": 17,
      "z": 6,
      "name": "Plant_Leaves_Gear"
    },
    {
      "x": 5,
      "y": 18,
      "z": 6,
      "name": "Plant_Leaves_Gear"
    },
    {
      "x": 5,
      "y": 19,
      "z": 6,
      "name": "Plant_Leaves_Gear"
    },
    {
      "x": 5,
      "y": 12,
      "z": 7,
      "name": "Plant_Leaves_Gear"
    },
    {
      "x": 5,
      "y": 13,
      "z": 7,
      "name": "Plant_Leaves_Gear"
    },
    {
      "x": 5,
      "y": 15,
      "z": 7,
      "name": "Plant_Leaves_Gear"
    },
    {
      "x": 5,
      "y": 12,
      "z": 8,
      "name": "Plant_Leaves_Gear"
    },
    {
      "x": 5,
      "y": 12,
      "z": 9,
      "name": "Plant_Leaves_Gear"
    },
    {
      "x": 5,
      "y": 13,
      "z": 9,
      "name": "Plant_Leaves_Gear"
    },
    {
      "x": 6,
      "y": 13,
      "z": 0,
      "name": "Plant_Leaves_Gear"
    },
    {
      "x": 6,
      "y": 14,
      "z": 0,
      "name": "Plant_Leaves_Gear"
    },
    {
      "x": 6,
      "y": 9,
      "z": 1,
      "name": "Plant_Leaves_Gear"
    },
    {
      "x": 6,
      "y": 13,
      "z": 1,
      "name": "Plant_Leaves_Gear"
    },
    {
      "x": 6,
      "y": 14,
      "z": 1,
      "name": "Plant_Leaves_Gear"
    },
    {
      "x": 6,
      "y": 10,
      "z": 2,
      "name": "Plant_Leaves_Gear"
    },
    {
      "x": 6,
      "y": 13,
      "z": 2,
      "name": "Plant_Leaves_Gear"
    },
    {
      "x": 6,
      "y": 16,
      "z": 2,
      "name": "Plant_Leaves_Gear"
    },
    {
      "x": 6,
      "y": 10,
      "z": 3,
      "name": "Plant_Leaves_Gear"
    },
    {
      "x": 6,
      "y": 13,
      "z": 3,
      "name": "Wood_Oak_Branch_Long",
      "rotation": 5
    },
    {
      "x": 6,
      "y": 14,
      "z": 3,
      "name": "Plant_Leaves_Gear"
    },
    {
      "x": 6,
      "y": 16,
      "z": 3,
      "name": "Plant_Leaves_Gear"
    },
    {
      "x": 6,
      "y": 18,
      "z": 4,
      "name": "Plant_Leaves_Gear"
    },
    {
      "x": 6,
      "y": 19,
      "z": 4,
      "name": "Plant_Leaves_Gear"
    },
    {
      "x": 6,
      "y": 20,
      "z": 4,
      "name": "Plant_Leaves_Gear"
    },
    {
      "x": 6,
      "y": 11,
      "z": 5,
      "name": "Wood_Gear_Trunk_Full"
    },
    {
      "x": 6,
      "y": 18,
      "z": 5,
      "name": "Wood_Gear_Branch_Long",
      "rotation": 5
    },
    {
      "x": 6,
      "y": 19,
      "z": 5,
      "name": "Plant_Leaves_Gear"
    },
    {
      "x": 6,
      "y": 20,
      "z": 5,
      "name": "Plant_Leaves_Gear"
    },
    {
      "x": 6,
      "y": 12,
      "z": 7,
      "name": "Wood_Gear_Branch_Long",
      "rotation": 5
    },
    {
      "x": 6,
      "y": 15,
      "z": 7,
      "name": "Plant_Leaves_Gear"
    },
    {
      "x": 6,
      "y": 16,
      "z": 7,
      "name": "Plant_Leaves_Gear"
    },
    {
      "x": 6,
      "y": 18,
      "z": 7,
      "name": "Plant_Leaves_Gear"
    },
    {
      "x": 6,
      "y": 19,
      "z": 7,
      "name": "Plant_Leaves_Gear"
    },
    {
      "x": 6,
      "y": 15,
      "z": 8,
      "name": "Plant_Leaves_Gear"
    },
    {
      "x": 6,
      "y": 16,
      "z": 8,
      "name": "Plant_Leaves_Gear"
    },
    {
      "x": 6,
      "y": 18,
      "z": 8,
      "name": "Plant_Leaves_Gear"
    },
    {
      "x": 6,
      "y": 11,
      "z": 9,
      "name": "Plant_Leaves_Gear"
    },
    {
      "x": 6,
      "y": 12,
      "z": 9,
      "name": "Plant_Leaves_Gear"
    },
    {
      "x": 6,
      "y": 13,
      "z": 9,
      "name": "Plant_Leaves_Gear"
    },
    {
      "x": 6,
      "y": 14,
      "z": 9,
      "name": "Plant_Leaves_Gear"
    },
    {
      "x": 6,
      "y": 15,
      "z": 9,
      "name": "Plant_Leaves_Gear"
    },
    {
      "x": 6,
      "y": 11,
      "z": 10,
      "name": "Plant_Leaves_Gear"
    },
    {
      "x": 6,
      "y": 12,
      "z": 10,
      "name": "Plant_Leaves_Gear"
    },
    {
      "x": 6,
      "y": 13,
      "z": 10,
      "name": "Plant_Leaves_Gear"
    },
    {
      "x": 7,
      "y": 12,
      "z": 0,
      "name": "Plant_Leaves_Gear"
    },
    {
      "x": 7,
      "y": 13,
      "z": 0,
      "name": "Plant_Leaves_Gear"
    },
    {
      "x": 7,
      "y": 14,
      "z": 0,
      "name": "Plant_Leaves_Gear"
    },
    {
      "x": 7,
      "y": 9,
      "z": 1,
      "name": "Plant_Leaves_Gear"
    },
    {
      "x": 7,
      "y": 10,
      "z": 1,
      "name": "Plant_Leaves_Gear"
    },
    {
      "x": 7,
      "y": 12,
      "z": 1,
      "name": "Plant_Leaves_Gear"
    },
    {
      "x": 7,
      "y": 13,
      "z": 1,
      "name": "Wood_Gear_Branch_Long",
      "rotation": 4
    },
    {
      "x": 7,
      "y": 14,
      "z": 1,
      "name": "Plant_Leaves_Gear"
    },
    {
      "x": 7,
      "y": 15,
      "z": 1,
      "name": "Plant_Leaves_Gear"
    },
    {
      "x": 7,
      "y": 10,
      "z": 2,
      "name": "Plant_Leaves_Gear"
    },
    {
      "x": 7,
      "y": 13,
      "z": 2,
      "name": "Wood_Gear_Branch_Long",
      "rotation": 4
    },
    {
      "x": 7,
      "y": 16,
      "z": 2,
      "name": "Plant_Leaves_Gear"
    },
    {
      "x": 7,
      "y": 17,
      "z": 2,
      "name": "Plant_Leaves_Gear"
    },
    {
      "x": 7,
      "y": 18,
      "z": 2,
      "name": "Plant_Leaves_Gear"
    },
    {
      "x": 7,
      "y": 10,
      "z": 3,
      "name": "Wood_Gear_Branch_Long",
      "rotation": 4
    },
    {
      "x": 7,
      "y": 12,
      "z": 3,
      "name": "Wood_Gear_Trunk_Full"
    },
    {
      "x": 7,
      "y": 13,
      "z": 3,
      "name": "Wood_Gear_Trunk_Full"
    },
    {
      "x": 7,
      "y": 14,
      "z": 3,
      "name": "Wood_Gear_Branch_Long"
    },
    {
      "x": 7,
      "y": 15,
      "z": 3,
      "name": "Wood_Gear_Branch_Long"
    },
    {
      "x": 7,
      "y": 16,
      "z": 3,
      "name": "Plant_Leaves_Gear"
    },
    {
      "x": 7,
      "y": 17,
      "z": 3,
      "name": "Plant_Leaves_Gear"
    },
    {
      "x": 7,
      "y": 18,
      "z": 3,
      "name": "Plant_Leaves_Gear"
    },
    {
      "x": 7,
      "y": 19,
      "z": 3,
      "name": "Plant_Leaves_Gear"
    },
    {
      "x": 7,
      "y": 10,
      "z": 4,
      "name": "Wood_Gear_Branch_Long",
      "rotation": 4
    },
    {
      "x": 7,
      "y": 12,
      "z": 4,
      "name": "Wood_Gear_Trunk_Full"
    },
    {
      "x": 7,
      "y": 13,
      "z": 4,
      "name": "Deco_Nest"
    },
    {
      "x": 7,
      "y": 18,
      "z": 4,
      "name": "Wood_Gear_Branch_Long",
      "rotation": 4
    },
    {
      "x": 7,
      "y": 20,
      "z": 4,
      "name": "Plant_Leaves_Gear"
    },
    {
      "x": 7,
      "y": 21,
      "z": 4,
      "name": "Plant_Leaves_Gear"
    },
    {
      "x": 7,
      "y": 1,
      "z": 5,
      "name": "Wood_Gear_Trunk"
    },
    {
      "x": 7,
      "y": 2,
      "z": 5,
      "name": "Wood_Gear_Trunk"
    },
    {
      "x": 7,
      "y": 3,
      "z": 5,
      "name": "Wood_Gear_Trunk"
    },
    {
      "x": 7,
      "y": 4,
      "z": 5,
      "name": "Wood_Gear_Trunk"
    },
    {
      "x": 7,
      "y": 5,
      "z": 5,
      "name": "Wood_Gear_Trunk"
    },
    {
      "x": 7,
      "y": 6,
      "z": 5,
      "name": "Wood_Gear_Trunk"
    },
    {
      "x": 7,
      "y": 7,
      "z": 5,
      "name": "Wood_Gear_Trunk"
    },
    {
      "x": 7,
      "y": 8,
      "z": 5,
      "name": "Wood_Gear_Trunk"
    },
    {
      "x": 7,
      "y": 9,
      "z": 5,
      "name": "Wood_Gear_Trunk"
    },
    {
      "x": 7,
      "y": 10,
      "z": 5,
      "name": "Wood_Gear_Trunk"
    },
    {
      "x": 7,
      "y": 11,
      "z": 5,
      "name": "Wood_Gear_Trunk"
    },
    {
      "x": 7,
      "y": 12,
      "z": 5,
      "name": "Wood_Gear_Trunk"
    },
    {
      "x": 7,
      "y": 13,
      "z": 5,
      "name": "Wood_Gear_Trunk"
    },
    {
      "x": 7,
      "y": 14,
      "z": 5,
      "name": "Wood_Gear_Trunk"
    },
    {
      "x": 7,
      "y": 15,
      "z": 5,
      "name": "Wood_Gear_Trunk"
    },
    {
      "x": 7,
      "y": 16,
      "z": 5,
      "name": "Wood_Gear_Trunk"
    },
    {
      "x": 7,
      "y": 17,
      "z": 5,
      "name": "Wood_Gear_Trunk"
    },
    {
      "x": 7,
      "y": 18,
      "z": 5,
      "name": "Wood_Gear_Trunk_Full"
    },
    {
      "x": 7,
      "y": 19,
      "z": 5,
      "name": "Wood_Gear_Branch_Long"
    },
    {
      "x": 7,
      "y": 20,
      "z": 5,
      "name": "Wood_Gear_Branch_Long"
    },
    {
      "x": 7,
      "y": 21,
      "z": 5,
      "name": "Plant_Leaves_Gear"
    },
    {
      "x": 7,
      "y": 11,
      "z": 6,
      "name": "Wood_Gear_Trunk_Full"
    },
    {
      "x": 7,
      "y": 18,
      "z": 6,
      "name": "Wood_Gear_Branch_Long",
      "rotation": 4
    },
    {
      "x": 7,
      "y": 20,
      "z": 6,
      "name": "Plant_Leaves_Gear"
    },
    {
      "x": 7,
      "y": 11,
      "z": 7,
      "name": "Wood_Gear_Trunk_Full"
    },
    {
      "x": 7,
      "y": 12,
      "z": 7,
      "name": "Wood_Gear_Trunk_Full"
    },
    {
      "x": 7,
      "y": 13,
      "z": 7,
      "name": "Wood_Gear_Branch_Long"
    },
    {
      "x": 7,
      "y": 14,
      "z": 7,
      "name": "Wood_Gear_Branch_Long"
    },
    {
      "x": 7,
      "y": 15,
      "z": 7,
      "name": "Plant_Leaves_Gear"
    },
    {
      "x": 7,
      "y": 18,
      "z": 7,
      "name": "Wood_Gear_Branch_Long",
      "rotation": 4
    },
    {
      "x": 7,
      "y": 19,
      "z": 7,
      "name": "Plant_Leaves_Gear"
    },
    {
      "x": 7,
      "y": 12,
      "z": 8,
      "name": "Wood_Gear_Branch_Long",
      "rotation": 4
    },
    {
      "x": 7,
      "y": 15,
      "z": 8,
      "name": "Plant_Leaves_Gear"
    },
    {
      "x": 7,
      "y": 16,
      "z": 8,
      "name": "Plant_Leaves_Gear"
    },
    {
      "x": 7,
      "y": 17,
      "z": 8,
      "name": "Plant_Leaves_Gear"
    },
    {
      "x": 7,
      "y": 18,
      "z": 8,
      "name": "Plant_Leaves_Gear"
    },
    {
      "x": 7,
      "y": 19,
      "z": 8,
      "name": "Plant_Leaves_Gear"
    },
    {
      "x": 7,
      "y": 12,
      "z": 9,
      "name": "Wood_Gear_Branch_Long",
      "rotation": 4
    },
    {
      "x": 7,
      "y": 13,
      "z": 9,
      "name": "Plant_Leaves_Gear"
    },
    {
      "x": 7,
      "y": 14,
      "z": 9,
      "name": "Plant_Leaves_Gear"
    },
    {
      "x": 7,
      "y": 11,
      "z": 10,
      "name": "Plant_Leaves_Gear"
    },
    {
      "x": 7,
      "y": 12,
      "z": 10,
      "name": "Plant_Leaves_Gear"
    },
    {
      "x": 7,
      "y": 13,
      "z": 10,
      "name": "Plant_Leaves_Gear"
    },
    {
      "x": 8,
      "y": 12,
      "z": 0,
      "name": "Plant_Leaves_Gear"
    },
    {
      "x": 8,
      "y": 13,
      "z": 0,
      "name": "Plant_Leaves_Gear"
    },
    {
      "x": 8,
      "y": 14,
      "z": 0,
      "name": "Plant_Leaves_Gear"
    },
    {
      "x": 8,
      "y": 13,
      "z": 1,
      "name": "Plant_Leaves_Gear"
    },
    {
      "x": 8,
      "y": 14,
      "z": 1,
      "name": "Plant_Leaves_Gear"
    },
    {
      "x": 8,
      "y": 10,
      "z": 2,
      "name": "Plant_Leaves_Gear"
    },
    {
      "x": 8,
      "y": 16,
      "z": 2,
      "name": "Plant_Leaves_Gear"
    },
    {
      "x": 8,
      "y": 17,
      "z": 2,
      "name": "Plant_Leaves_Gear"
    },
    {
      "x": 8,
      "y": 10,
      "z": 3,
      "name": "Plant_Leaves_Gear"
    },
    {
      "x": 8,
      "y": 16,
      "z": 3,
      "name": "Plant_Leaves_Gear"
    },
    {
      "x": 8,
      "y": 17,
      "z": 3,
      "name": "Plant_Leaves_Gear"
    },
    {
      "x": 8,
      "y": 18,
      "z": 3,
      "name": "Plant_Leaves_Gear"
    },
    {
      "x": 8,
      "y": 19,
      "z": 3,
      "name": "Plant_Leaves_Gear"
    },
    {
      "x": 8,
      "y": 20,
      "z": 3,
      "name": "Plant_Leaves_Gear"
    },
    {
      "x": 8,
      "y": 20,
      "z": 4,
      "name": "Plant_Leaves_Gear"
    },
    {
      "x": 8,
      "y": 9,
      "z": 5,
      "name": "Wood_Gear_Branch_Long",
      "rotation": 5
    },
    {
      "x": 8,
      "y": 12,
      "z": 5,
      "name": "Wood_Gear_Trunk_Full"
    },
    {
      "x": 8,
      "y": 18,
      "z": 5,
      "name": "Wood_Gear_Branch_Long",
      "rotation": 5
    },
    {
      "x": 8,
      "y": 20,
      "z": 5,
      "name": "Plant_Leaves_Gear"
    },
    {
      "x": 8,
      "y": 21,
      "z": 5,
      "name": "Plant_Leaves_Gear"
    },
    {
      "x": 8,
      "y": 20,
      "z": 6,
      "name": "Plant_Leaves_Gear"
    },
    {
      "x": 8,
      "y": 21,
      "z": 6,
      "name": "Plant_Leaves_Gear"
    },
    {
      "x": 8,
      "y": 15,
      "z": 7,
      "name": "Plant_Leaves_Gear"
    },
    {
      "x": 8,
      "y": 18,
      "z": 7,
      "name": "Plant_Leaves_Gear"
    },
    {
      "x": 8,
      "y": 19,
      "z": 7,
      "name": "Plant_Leaves_Gear"
    },
    {
      "x": 8,
      "y": 15,
      "z": 8,
      "name": "Plant_Leaves_Gear"
    },
    {
      "x": 8,
      "y": 18,
      "z": 8,
      "name": "Plant_Leaves_Gear"
    },
    {
      "x": 8,
      "y": 11,
      "z": 9,
      "name": "Plant_Leaves_Gear"
    },
    {
      "x": 8,
      "y": 12,
      "z": 9,
      "name": "Plant_Leaves_Gear"
    },
    {
      "x": 8,
      "y": 13,
      "z": 9,
      "name": "Plant_Leaves_Gear"
    },
    {
      "x": 8,
      "y": 14,
      "z": 9,
      "name": "Plant_Leaves_Gear"
    },
    {
      "x": 8,
      "y": 11,
      "z": 10,
      "name": "Plant_Leaves_Gear"
    },
    {
      "x": 8,
      "y": 12,
      "z": 10,
      "name": "Plant_Leaves_Gear"
    },
    {
      "x": 9,
      "y": 13,
      "z": 0,
      "name": "Plant_Leaves_Gear"
    },
    {
      "x": 9,
      "y": 12,
      "z": 1,
      "name": "Plant_Leaves_Gear"
    },
    {
      "x": 9,
      "y": 13,
      "z": 1,
      "name": "Plant_Leaves_Gear"
    },
    {
      "x": 9,
      "y": 12,
      "z": 2,
      "name": "Plant_Leaves_Gear"
    },
    {
      "x": 9,
      "y": 13,
      "z": 2,
      "name": "Plant_Leaves_Gear"
    },
    {
      "x": 9,
      "y": 14,
      "z": 2,
      "name": "Plant_Leaves_Gear"
    },
    {
      "x": 9,
      "y": 16,
      "z": 2,
      "name": "Plant_Leaves_Gear"
    },
    {
      "x": 9,
      "y": 13,
      "z": 3,
      "name": "Wood_Gear_Branch_Long",
      "rotation": 4
    },
    {
      "x": 9,
      "y": 16,
      "z": 3,
      "name": "Plant_Leaves_Gear"
    },
    {
      "x": 9,
      "y": 17,
      "z": 3,
      "name": "Plant_Leaves_Gear"
    },
    {
      "x": 9,
      "y": 9,
      "z": 4,
      "name": "Plant_Leaves_Gear"
    },
    {
      "x": 9,
      "y": 13,
      "z": 4,
      "name": "Wood_Gear_Branch_Long",
      "rotation": 4
    },
    {
      "x": 9,
      "y": 17,
      "z": 4,
      "name": "Plant_Leaves_Gear"
    },
    {
      "x": 9,
      "y": 19,
      "z": 4,
      "name": "Plant_Leaves_Gear"
    },
    {
      "x": 9,
      "y": 9,
      "z": 5,
      "name": "Wood_Gear_Branch_Long",
      "rotation": 5
    },
    {
      "x": 9,
      "y": 10,
      "z": 5,
      "name": "Plant_Leaves_Gear"
    },
    {
      "x": 9,
      "y": 12,
      "z": 5,
      "name": "Wood_Gear_Trunk_Full"
    },
    {
      "x": 9,
      "y": 13,
      "z": 5,
      "name": "Wood_Gear_Trunk_Full"
    },
    {
      "x": 9,
      "y": 14,
      "z": 5,
      "name": "Wood_Gear_Branch_Long"
    },
    {
      "x": 9,
      "y": 15,
      "z": 5,
      "name": "Wood_Gear_Branch_Long"
    },
    {
      "x": 9,
      "y": 16,
      "z": 5,
      "name": "Wood_Gear_Branch_Long"
    },
    {
      "x": 9,
      "y": 17,
      "z": 5,
      "name": "Plant_Leaves_Gear"
    },
    {
      "x": 9,
      "y": 18,
      "z": 5,
      "name": "Plant_Leaves_Gear"
    },
    {
      "x": 9,
      "y": 19,
      "z": 5,
      "name": "Plant_Leaves_Gear"
    },
    {
      "x": 9,
      "y": 20,
      "z": 5,
      "name": "Plant_Leaves_Gear"
    },
    {
      "x": 9,
      "y": 10,
      "z": 6,
      "name": "Plant_Leaves_Gear"
    },
    {
      "x": 9,
      "y": 13,
      "z": 6,
      "name": "Wood_Gear_Branch_Long",
      "rotation": 4
    },
    {
      "x": 9,
      "y": 16,
      "z": 6,
      "name": "Plant_Leaves_Gear"
    },
    {
      "x": 9,
      "y": 18,
      "z": 6,
      "name": "Plant_Leaves_Gear"
    },
    {
      "x": 9,
      "y": 13,
      "z": 7,
      "name": "Wood_Gear_Branch_Long",
      "rotation": 4
    },
    {
      "x": 9,
      "y": 14,
      "z": 7,
      "name": "Plant_Leaves_Gear"
    },
    {
      "x": 9,
      "y": 16,
      "z": 7,
      "name": "Plant_Leaves_Gear"
    },
    {
      "x": 9,
      "y": 17,
      "z": 7,
      "name": "Plant_Leaves_Gear"
    },
    {
      "x": 9,
      "y": 18,
      "z": 7,
      "name": "Plant_Leaves_Gear"
    },
    {
      "x": 9,
      "y": 13,
      "z": 8,
      "name": "Plant_Leaves_Gear"
    },
    {
      "x": 9,
      "y": 12,
      "z": 9,
      "name": "Plant_Leaves_Gear"
    },
    {
      "x": 9,
      "y": 13,
      "z": 9,
      "name": "Plant_Leaves_Gear"
    },
    {
      "x": 10,
      "y": 12,
      "z": 1,
      "name": "Plant_Leaves_Gear"
    },
    {
      "x": 10,
      "y": 13,
      "z": 1,
      "name": "Plant_Leaves_Gear"
    },
    {
      "x": 10,
      "y": 12,
      "z": 2,
      "name": "Plant_Leaves_Gear"
    },
    {
      "x": 10,
      "y": 13,
      "z": 2,
      "name": "Plant_Leaves_Gear"
    },
    {
      "x": 10,
      "y": 14,
      "z": 2,
      "name": "Plant_Leaves_Gear"
    },
    {
      "x": 10,
      "y": 9,
      "z": 4,
      "name": "Plant_Leaves_Gear"
    },
    {
      "x": 10,
      "y": 16,
      "z": 4,
      "name": "Plant_Leaves_Gear"
    },
    {
      "x": 10,
      "y": 18,
      "z": 4,
      "name": "Plant_Leaves_Gear"
    },
    {
      "x": 10,
      "y": 9,
      "z": 5,
      "name": "Plant_Leaves_Gear"
    },
    {
      "x": 10,
      "y": 10,
      "z": 5,
      "name": "Plant_Leaves_Gear"
    },
    {
      "x": 10,
      "y": 13,
      "z": 5,
      "name": "Wood_Gear_Branch_Long",
      "rotation": 5
    },
    {
      "x": 10,
      "y": 16,
      "z": 5,
      "name": "Plant_Leaves_Gear"
    },
    {
      "x": 10,
      "y": 17,
      "z": 5,
      "name": "Plant_Leaves_Gear"
    },
    {
      "x": 10,
      "y": 18,
      "z": 5,
      "name": "Plant_Leaves_Gear"
    },
    {
      "x": 10,
      "y": 19,
      "z": 5,
      "name": "Plant_Leaves_Gear"
    },
    {
      "x": 10,
      "y": 9,
      "z": 6,
      "name": "Plant_Leaves_Gear"
    },
    {
      "x": 10,
      "y": 16,
      "z": 6,
      "name": "Plant_Leaves_Gear"
    },
    {
      "x": 10,
      "y": 17,
      "z": 6,
      "name": "Plant_Leaves_Gear"
    },
    {
      "x": 10,
      "y": 14,
      "z": 7,
      "name": "Plant_Leaves_Gear"
    },
    {
      "x": 10,
      "y": 13,
      "z": 8,
      "name": "Plant_Leaves_Gear"
    },
    {
      "x": 11,
      "y": 13,
      "z": 2,
      "name": "Plant_Leaves_Gear"
    },
    {
      "x": 11,
      "y": 12,
      "z": 3,
      "name": "Plant_Leaves_Gear"
    },
    {
      "x": 11,
      "y": 13,
      "z": 3,
      "name": "Plant_Leaves_Gear"
    },
    {
      "x": 11,
      "y": 11,
      "z": 4,
      "name": "Plant_Leaves_Gear"
    },
    {
      "x": 11,
      "y": 12,
      "z": 4,
      "name": "Plant_Leaves_Gear"
    },
    {
      "x": 11,
      "y": 13,
      "z": 4,
      "name": "Plant_Leaves_Gear"
    },
    {
      "x": 11,
      "y": 14,
      "z": 4,
      "name": "Plant_Leaves_Gear"
    },
    {
      "x": 11,
      "y": 15,
      "z": 4,
      "name": "Plant_Leaves_Gear"
    },
    {
      "x": 11,
      "y": 9,
      "z": 5,
      "name": "Plant_Leaves_Gear"
    },
    {
      "x": 11,
      "y": 13,
      "z": 5,
      "name": "Wood_Gear_Branch_Long",
      "rotation": 5
    },
    {
      "x": 11,
      "y": 14,
      "z": 5,
      "name": "Plant_Leaves_Gear"
    },
    {
      "x": 11,
      "y": 15,
      "z": 5,
      "name": "Plant_Leaves_Gear"
    },
    {
      "x": 11,
      "y": 13,
      "z": 6,
      "name": "Plant_Leaves_Gear"
    },
    {
      "x": 11,
      "y": 14,
      "z": 6,
      "name": "Plant_Leaves_Gear"
    },
    {
      "x": 11,
      "y": 13,
      "z": 7,
      "name": "Plant_Leaves_Gear"
    },
    {
      "x": 11,
      "y": 14,
      "z": 7,
      "name": "Plant_Leaves_Gear"
    },
    {
      "x": 12,
      "y": 13,
      "z": 4,
      "name": "Plant_Leaves_Gear"
    },
    {
      "x": 12,
      "y": 14,
      "z": 4,
      "name": "Plant_Leaves_Gear"
    },
    {
      "x": 12,
      "y": 11,
      "z": 5,
      "name": "Plant_Leaves_Gear"
    },
    {
      "x": 12,
      "y": 12,
      "z": 5,
      "name": "Plant_Leaves_Gear"
    },
    {
      "x": 12,
      "y": 13,
      "z": 5,
      "name": "Plant_Leaves_Gear"
    },
    {
      "x": 12,
      "y": 12,
      "z": 6,
      "name": "Plant_Leaves_Gear"
    },
    {
      "x": 12,
      "y": 13,
      "z": 6,
      "name": "Plant_Leaves_Gear"
    },
    {
      "x": 12,
      "y": 14,
      "z": 6,
      "name": "Plant_Leaves_Gear"
    },
    {
      "x": 12,
      "y": 13,
      "z": 7,
      "name": "Plant_Leaves_Gear"
    }
  ]
}