{
  "version": 8,
  "blockIdVersion": 11,
  "anchorX": 7,
  "anchorY": 9,
  "anchorZ": 7,
  "blocks": [
    {
      "x": 3,
      "y": 14,
      "z": 7,
      "name": "Plant_Leaves_Gear"
    },
    {
      "x": 4,
      "y": 13,
      "z": 6,
      "name": "Plant_Leaves_Gear"
    },
    {
      "x": 4,
      "y": 14,
      "z": 6,
      "name": "Plant_Leaves_Gear"
    },
    {
      "x": 4,
      "y": 15,
      "z": 6,
      "name": "Plant_Leaves_Gear"
    },
    {
      "x": 4,
      "y": 13,
      "z": 7,
      "name": "Plant_Leaves_Gear"
    },
    {
      "x": 4,
      "y": 14,
      "z": 7,
      "name": "Plant_Leaves_Gear"
    },
    {
      "x": 4,
      "y": 15,
      "z": 7,
      "name": "Plant_Leaves_Gear"
    },
    {
      "x": 4,
      "y": 17,
      "z": 7,
      "name": "Plant_Leaves_Gear"
    },
    {
      "x": 4,
      "y": 18,
      "z": 7,
      "name": "Plant_Leaves_Gear"
    },
    {
      "x": 4,
      "y": 19,
      "z": 7,
      "name": "Plant_Leaves_Gear"
    },
    {
      "x": 4,
      "y": 14,
      "z": 8,
      "name": "Plant_Leaves_Gear"
    },
    {
      "x": 4,
      "y": 15,
      "z": 8,
      "name": "Plant_Leaves_Gear"
    },
    {
      "x": 4,
      "y": 18,
      "z": 8,
      "name": "Plant_Leaves_Gear"
    },
    {
      "x": 5,
      "y": 19,
      "z": 4,
      "name": "Plant_Leaves_Gear"
    },
    {
      "x": 5,
      "y": 20,
      "z": 4,
      "name": "Plant_Leaves_Gear"
    },
    {
      "x": 5,
      "y": 13,
      "z": 5,
      "name": "Plant_Leaves_Gear"
    },
    {
      "x": 5,
      "y": 14,
      "z": 5,
      "name": "Plant_Leaves_Gear"
    },
    {
      "x": 5,
      "y": 20,
      "z": 5,
      "name": "Plant_Leaves_Gear"
    },
    {
      "x": 5,
      "y": 14,
      "z": 6,
      "name": "Plant_Leaves_Gear"
    },
    {
      "x": 5,
      "y": 15,
      "z": 6,
      "name": "Plant_Leaves_Gear"
    },
    {
      "x": 5,
      "y": 16,
      "z": 6,
      "name": "Plant_Leaves_Gear"
    },
    {
      "x": 5,
      "y": 18,
      "z": 6,
      "name": "Plant_Leaves_Gear"
    },
    {
      "x": 5,
      "y": 19,
      "z": 6,
      "name": "Plant_Leaves_Gear"
    },
    {
      "x": 5,
      "y": 21,
      "z": 6,
      "name": "Plant_Leaves_Gear"
    },
    {
      "x": 5,
      "y": 22,
      "z": 6,
      "name": "Plant_Leaves_Gear"
    },
    {
      "x": 5,
      "y": 14,
      "z": 7,
      "name": "Wood_Gear_Branch_Long",
      "rotation": 5
    },
    {
      "x": 5,
      "y": 15,
      "z": 7,
      "name": "Plant_Leaves_Gear"
    },
    {
      "x": 5,
      "y": 16,
      "z": 7,
      "name": "Plant_Leaves_Gear"
    },
    {
      "x": 5,
      "y": 17,
      "z": 7,
      "name": "Plant_Leaves_Gear"
    },
    {
      "x": 5,
      "y": 18,
      "z": 7,
      "name": "Plant_Leaves_Gear"
    },
    {
      "x": 5,
      "y": 19,
      "z": 7,
      "name": "Plant_Leaves_Gear"
    },
    {
      "x": 5,
      "y": 20,
      "z": 7,
      "name": "Plant_Leaves_Gear"
    },
    {
      "x": 5,
      "y": 22,
      "z": 7,
      "name": "Plant_Leaves_Gear"
    },
    {
      "x": 5,
      "y": 14,
      "z": 8,
      "name": "Plant_Leaves_Gear"
    },
    {
      "x": 5,
      "y": 15,
      "z": 8,
      "name": "Plant_Leaves_Gear"
    },
    {
      "x": 5,
      "y": 17,
      "z": 8,
      "name": "Plant_Leaves_Gear"
    },
    {
      "x": 5,
      "y": 18,
      "z": 8,
      "name": "Plant_Leaves_Gear"
    },
    {
      "x": 5,
      "y": 19,
      "z": 8,
      "name": "Plant_Leaves_Gear"
    },
    {
      "x": 5,
      "y": 17,
      "z": 9,
      "name": "Plant_Leaves_Gear"
    },
    {
      "x": 5,
      "y": 18,
      "z": 9,
      "name": "Plant_Leaves_Gear"
    },
    {
      "x": 5,
      "y": 20,
      "z": 9,
      "name": "Plant_Leaves_Gear"
    },
    {
      "x": 5,
      "y": 17,
      "z": 10,
      "name": "Plant_Leaves_Gear"
    },
    {
      "x": 5,
      "y": 17,
      "z": 11,
      "name": "Plant_Leaves_Gear"
    },
    {
      "x": 5,
      "y": 18,
      "z": 11,
      "name": "Plant_Leaves_Gear"
    },
    {
      "x": 6,
      "y": 19,
      "z": 3,
      "name": "Plant_Leaves_Gear"
    },
    {
      "x": 6,
      "y": 15,
      "z": 4,
      "name": "Plant_Leaves_Gear"
    },
    {
      "x": 6,
      "y": 18,
      "z": 4,
      "name": "Plant_Leaves_Gear"
    },
    {
      "x": 6,
      "y": 19,
      "z": 4,
      "name": "Plant_Leaves_Gear"
    },
    {
      "x": 6,
      "y": 20,
      "z": 4,
      "name": "Plant_Leaves_Gear"
    },
    {
      "x": 6,
      "y": 21,
      "z": 4,
      "name": "Plant_Leaves_Gear"
    },
    {
      "x": 6,
      "y": 15,
      "z": 5,
      "name": "Plant_Leaves_Gear"
    },
    {
      "x": 6,
      "y": 17,
      "z": 5,
      "name": "Plant_Leaves_Gear"
    },
    {
      "x": 6,
      "y": 20,
      "z": 5,
      "name": "Plant_Leaves_Gear"
    },
    {
      "x": 6,
      "y": 21,
      "z": 5,
      "name": "Plant_Leaves_Gear"
    },
    {
      "x": 6,
      "y": 22,
      "z": 5,
      "name": "Plant_Leaves_Gear"
    },
    {
      "x": 6,
      "y": 23,
      "z": 5,
      "name": "Plant_Leaves_Gear"
    },
    {
      "x": 6,
      "y": 24,
      "z": 5,
      "name": "Plant_Leaves_Gear"
    },
    {
      "x": 6,
      "y": 21,
      "z": 6,
      "name": "Plant_Leaves_Gear"
    },
    {
      "x": 6,
      "y": 22,
      "z": 6,
      "name": "Plant_Leaves_Gear"
    },
    {
      "x": 6,
      "y": 24,
      "z": 6,
      "name": "Plant_Leaves_Gear"
    },
    {
      "x": 6,
      "y": 25,
      "z": 6,
      "name": "Plant_Leaves_Gear"
    },
    {
      "x": 6,
      "y": 14,
      "z": 7,
      "name": "Wood_Gear_Branch_Long",
      "rotation": 5
    },
    {
      "x": 6,
      "y": 18,
      "z": 7,
      "name": "Wood_Gear_Branch_Long",
      "rotation": 5
    },
    {
      "x": 6,
      "y": 21,
      "z": 7,
      "name": "Wood_Gear_Branch_Long",
      "rotation": 5
    },
    {
      "x": 6,
      "y": 24,
      "z": 7,
      "name": "Plant_Leaves_Gear"
    },
    {
      "x": 6,
      "y": 22,
      "z": 8,
      "name": "Plant_Leaves_Gear"
    },
    {
      "x": 6,
      "y": 23,
      "z": 8,
      "name": "Plant_Leaves_Gear"
    },
    {
      "x": 6,
      "y": 15,
      "z": 9,
      "name": "Plant_Leaves_Gear"
    },
    {
      "x": 6,
      "y": 17,
      "z": 9,
      "name": "Wood_Gear_Branch_Long",
      "rotation": 5
    },
    {
      "x": 6,
      "y": 20,
      "z": 9,
      "name": "Plant_Leaves_Gear"
    },
    {
      "x": 6,
      "y": 21,
      "z": 9,
      "name": "Plant_Leaves_Gear"
    },
    {
      "x": 6,
      "y": 22,
      "z": 9,
      "name": "Plant_Leaves_Gear"
    },
    {
      "x": 6,
      "y": 23,
      "z": 9,
      "name": "Plant_Leaves_Gear"
    },
    {
      "x": 6,
      "y": 15,
      "z": 10,
      "name": "Plant_Leaves_Gear"
    },
    {
      "x": 6,
      "y": 16,
      "z": 10,
      "name": "Plant_Leaves_Gear"
    },
    {
      "x": 6,
      "y": 20,
      "z": 10,
      "name": "Plant_Leaves_Gear"
    },
    {
      "x": 6,
      "y": 21,
      "z": 10,
      "name": "Plant_Leaves_Gear"
    },
    {
      "x": 6,
      "y": 15,
      "z": 11,
      "name": "Plant_Leaves_Gear"
    },
    {
      "x": 6,
      "y": 16,
      "z": 11,
      "name": "Plant_Leaves_Gear"
    },
    {
      "x": 6,
      "y": 17,
      "z": 11,
      "name": "Plant_Leaves_Gear"
    },
    {
      "x": 6,
      "y": 18,
      "z": 11,
      "name": "Plant_Leaves_Gear"
    },
    {
      "x": 6,
      "y": 19,
      "z": 11,
      "name": "Plant_Leaves_Gear"
    },
    {
      "x": 6,
      "y": 20,
      "z": 11,
      "name": "Plant_Leaves_Gear"
    },
    {
      "x": 6,
      "y": 16,
      "z": 12,
      "name": "Plant_Leaves_Gear"
    },
    {
      "x": 6,
      "y": 17,
      "z": 12,
      "name": "Plant_Leaves_Gear"
    },
    {
      "x": 6,
      "y": 18,
      "z": 12,
      "name": "Plant_Leaves_Gear"
    },
    {
      "x": 7,
      "y": 15,
      "z": 3,
      "name": "Plant_Leaves_Gear"
    },
    {
      "x": 7,
      "y": 17,
      "z": 3,
      "name": "Plant_Leaves_Gear"
    },
    {
      "x": 7,
      "y": 18,
      "z": 3,
      "name": "Plant_Leaves_Gear"
    },
    {
      "x": 7,
      "y": 19,
      "z": 3,
      "name": "Plant_Leaves_Gear"
    },
    {
      "x": 7,
      "y": 21,
      "z": 3,
      "name": "Plant_Leaves_Gear"
    },
    {
      "x": 7,
      "y": 15,
      "z": 4,
      "name": "Plant_Leaves_Gear"
    },
    {
      "x": 7,
      "y": 16,
      "z": 4,
      "name": "Plant_Leaves_Gear"
    },
    {
      "x": 7,
      "y": 17,
      "z": 4,
      "name": "Plant_Leaves_Gear"
    },
    {
      "x": 7,
      "y": 18,
      "z": 4,
      "name": "Plant_Leaves_Gear"
    },
    {
      "x": 7,
      "y": 19,
      "z": 4,
      "name": "Plant_Leaves_Gear"
    },
    {
      "x": 7,
      "y": 20,
      "z": 4,
      "name": "Plant_Leaves_Gear"
    },
    {
      "x": 7,
      "y": 21,
      "z": 4,
      "name": "Plant_Leaves_Gear"
    },
    {
      "x": 7,
      "y": 15,
      "z": 5,
      "name": "Wood_Gear_Branch_Long",
      "rotation": 4
    },
    {
      "x": 7,
      "y": 16,
      "z": 5,
      "name": "Plant_Leaves_Gear"
    },
    {
      "x": 7,
      "y": 17,
      "z": 5,
      "name": "Plant_Leaves_Gear"
    },
    {
      "x": 7,
      "y": 18,
      "z": 5,
      "name": "Plant_Leaves_Gear"
    },
    {
      "x": 7,
      "y": 20,
      "z": 5,
      "name": "Plant_Leaves_Gear"
    },
    {
      "x": 7,
      "y": 21,
      "z": 5,
      "name": "Plant_Leaves_Gear"
    },
    {
      "x": 7,
      "y": 24,
      "z": 5,
      "name": "Plant_Leaves_Gear"
    },
    {
      "x": 7,
      "y": 25,
      "z": 5,
      "name": "Plant_Leaves_Gear"
    },
    {
      "x": 7,
      "y": 15,
      "z": 6,
      "name": "Wood_Gear_Branch_Long",
      "rotation": 4
    },
    {
      "x": 7,
      "y": 17,
      "z": 6,
      "name": "Wood_Gear_Branch_Long",
      "rotation": 4
    },
    {
      "x": 7,
      "y": 21,
      "z": 6,
      "name": "Wood_Gear_Branch_Corner",
      "rotation": 2
    },
    {
      "x": 7,
      "y": 22,
      "z": 6,
      "name": "Wood_Gear_Branch_Long"
    },
    {
      "x": 7,
      "y": 23,
      "z": 6,
      "name": "Wood_Gear_Branch_Long"
    },
    {
      "x": 7,
      "y": 24,
      "z": 6,
      "name": "Wood_Gear_Branch_Long"
    },
    {
      "x": 7,
      "y": 25,
      "z": 6,
      "name": "Plant_Leaves_Gear"
    },
    {
      "x": 7,
      "y": 6,
      "z": 7,
      "name": "Wood_Gear_Trunk"
    },
    {
      "x": 7,
      "y": 7,
      "z": 7,
      "name": "Wood_Gear_Trunk"
    },
    {
      "x": 7,
      "y": 8,
      "z": 7,
      "name": "Wood_Gear_Trunk"
    },
    {
      "x": 7,
      "y": 9,
      "z": 7,
      "name": "Wood_Gear_Trunk"
    },
    {
      "x": 7,
      "y": 10,
      "z": 7,
      "name": "Wood_Gear_Trunk"
    },
    {
      "x": 7,
      "y": 11,
      "z": 7,
      "name": "Wood_Gear_Trunk"
    },
    {
      "x": 7,
      "y": 12,
      "z": 7,
      "name": "Wood_Gear_Trunk"
    },
    {
      "x": 7,
      "y": 13,
      "z": 7,
      "name": "Wood_Gear_Trunk"
    },
    {
      "x": 7,
      "y": 14,
      "z": 7,
      "name": "Wood_Gear_Trunk"
    },
    {
      "x": 7,
      "y": 15,
      "z": 7,
      "name": "Wood_Gear_Trunk"
    },
    {
      "x": 7,
      "y": 16,
      "z": 7,
      "name": "Wood_Gear_Trunk"
    },
    {
      "x": 7,
      "y": 17,
      "z": 7,
      "name": "Wood_Gear_Trunk"
    },
    {
      "x": 7,
      "y": 18,
      "z": 7,
      "name": "Wood_Gear_Trunk"
    },
    {
      "x": 7,
      "y": 19,
      "z": 7,
      "name": "Wood_Gear_Trunk"
    },
    {
      "x": 7,
      "y": 20,
      "z": 7,
      "name": "Wood_Gear_Trunk"
    },
    {
      "x": 7,
      "y": 21,
      "z": 7,
      "name": "Wood_Gear_Trunk_Full"
    },
    {
      "x": 7,
      "y": 25,
      "z": 7,
      "name": "Plant_Leaves_Gear"
    },
    {
      "x": 7,
      "y": 16,
      "z": 8,
      "name": "Wood_Gear_Trunk_Full"
    },
    {
      "x": 7,
      "y": 20,
      "z": 8,
      "name": "Wood_Gear_Branch_Corner"
    },
    {
      "x": 7,
      "y": 21,
      "z": 8,
      "name": "Wood_Gear_Branch_Long"
    },
    {
      "x": 7,
      "y": 22,
      "z": 8,
      "name": "Wood_Gear_Branch_Long"
    },
    {
      "x": 7,
      "y": 23,
      "z": 8,
      "name": "Wood_Gear_Branch_Long"
    },
    {
      "x": 7,
      "y": 24,
      "z": 8,
      "name": "Plant_Leaves_Gear"
    },
    {
      "x": 7,
      "y": 16,
      "z": 9,
      "name": "Wood_Gear_Trunk_Full"
    },
    {
      "x": 7,
      "y": 17,
      "z": 9,
      "name": "Wood_Gear_Trunk_Full"
    },
    {
      "x": 7,
      "y": 18,
      "z": 9,
      "name": "Wood_Gear_Branch_Long"
    },
    {
      "x": 7,
      "y": 19,
      "z": 9,
      "name": "Wood_Gear_Branch_Long"
    },
    {
      "x": 7,
      "y": 20,
      "z": 9,
      "name": "Plant_Leaves_Gear"
    },
    {
      "x": 7,
      "y": 21,
      "z": 9,
      "name": "Plant_Leaves_Gear"
    },
    {
      "x": 7,
      "y": 23,
      "z": 9,
      "name": "Plant_Leaves_Gear"
    },
    {
      "x": 7,
      "y": 17,
      "z": 10,
      "name": "Wood_Gear_Branch_Long",
      "rotation": 4
    },
    {
      "x": 7,
      "y": 20,
      "z": 10,
      "name": "Plant_Leaves_Gear"
    },
    {
      "x": 7,
      "y": 21,
      "z": 10,
      "name": "Plant_Leaves_Gear"
    },
    {
      "x": 7,
      "y": 15,
      "z": 11,
      "name": "Plant_Leaves_Gear"
    },
    {
      "x": 7,
      "y": 16,
      "z": 11,
      "name": "Plant_Leaves_Gear"
    },
    {
      "x": 7,
      "y": 17,
      "z": 11,
      "name": "Wood_Gear_Branch_Long",
      "rotation": 4
    },
    {
      "x": 7,
      "y": 18,
      "z": 11,
      "name": "Plant_Leaves_Gear"
    },
    {
      "x": 7,
      "y": 19,
      "z": 11,
      "name": "Plant_Leaves_Gear"
    },
    {
      "x": 7,
      "y": 16,
      "z": 12,
      "name": "Plant_Leaves_Gear"
    },
    {
      "x": 7,
      "y": 17,
      "z": 12,
      "name": "Plant_Leaves_Gear"
    },
    {
      "x": 7,
      "y": 18,
      "z": 12,
      "name": "Plant_Leaves_Gear"
    },
    {
      "x": 8,
      "y": 19,
      "z": 3,
      "name": "Plant_Leaves_Gear"
    },
    {
      "x": 8,
      "y": 15,
      "z": 4,
      "name": "Plant_Leaves_Gear"
    },
    {
      "x": 8,
      "y": 17,
      "z": 4,
      "name": "Plant_Leaves_Gear"
    },
    {
      "x": 8,
      "y": 18,
      "z": 4,
      "name": "Plant_Leaves_Gear"
    },
    {
      "x": 8,
      "y": 20,
      "z": 4,
      "name": "Plant_Leaves_Gear"
    },
    {
      "x": 8,
      "y": 21,
      "z": 4,
      "name": "Plant_Leaves_Gear"
    },
    {
      "x": 8,
      "y": 16,
      "z": 5,
      "name": "Plant_Leaves_Gear"
    },
    {
      "x": 8,
      "y": 17,
      "z": 5,
      "name": "Plant_Leaves_Gear"
    },
    {
      "x": 8,
      "y": 18,
      "z": 5,
      "name": "Plant_Leaves_Gear"
    },
    {
      "x": 8,
      "y": 21,
      "z": 5,
      "name": "Plant_Leaves_Gear"
    },
    {
      "x": 8,
      "y": 22,
      "z": 5,
      "name": "Plant_Leaves_Gear"
    },
    {
      "x": 8,
      "y": 21,
      "z": 6,
      "name": "Plant_Leaves_Gear"
    },
    {
      "x": 8,
      "y": 22,
      "z": 6,
      "name": "Plant_Leaves_Gear"
    },
    {
      "x": 8,
      "y": 24,
      "z": 6,
      "name": "Plant_Leaves_Gear"
    },
    {
      "x": 8,
      "y": 25,
      "z": 6,
      "name": "Plant_Leaves_Gear"
    },
    {
      "x": 8,
      "y": 15,
      "z": 7,
      "name": "Wood_Gear_Trunk_Full"
    },
    {
      "x": 8,
      "y": 21,
      "z": 7,
      "name": "Wood_Gear_Branch_Corner",
      "rotation": 1
    },
    {
      "x": 8,
      "y": 22,
      "z": 7,
      "name": "Plant_Leaves_Gear"
    },
    {
      "x": 8,
      "y": 23,
      "z": 7,
      "name": "Plant_Leaves_Gear"
    },
    {
      "x": 8,
      "y": 25,
      "z": 7,
      "name": "Plant_Leaves_Gear"
    },
    {
      "x": 8,
      "y": 23,
      "z": 8,
      "name": "Plant_Leaves_Gear"
    },
    {
      "x": 8,
      "y": 24,
      "z": 8,
      "name": "Plant_Leaves_Gear"
    },
    {
      "x": 8,
      "y": 20,
      "z": 9,
      "name": "Plant_Leaves_Gear"
    },
    {
      "x": 8,
      "y": 23,
      "z": 9,
      "name": "Plant_Leaves_Gear"
    },
    {
      "x": 8,
      "y": 20,
      "z": 10,
      "name": "Plant_Leaves_Gear"
    },
    {
      "x": 8,
      "y": 16,
      "z": 11,
      "name": "Plant_Leaves_Gear"
    },
    {
      "x": 8,
      "y": 17,
      "z": 11,
      "name": "Plant_Leaves_Gear"
    },
    {
      "x": 8,
      "y": 18,
      "z": 11,
      "name": "Plant_Leaves_Gear"
    },
    {
      "x": 8,
      "y": 19,
      "z": 11,
      "name": "Plant_Leaves_Gear"
    },
    {
      "x": 8,
      "y": 16,
      "z": 12,
      "name": "Plant_Leaves_Gear"
    },
    {
      "x": 8,
      "y": 17,
      "z": 12,
      "name": "Plant_Leaves_Gear"
    },
    {
      "x": 9,
      "y": 16,
      "z": 4,
      "name": "Plant_Leaves_Gear"
    },
    {
      "x": 9,
      "y": 16,
      "z": 5,
      "name": "Plant_Leaves_Gear"
    },
    {
      "x": 9,
      "y": 17,
      "z": 5,
      "name": "Plant_Leaves_Gear"
    },
    {
      "x": 9,
      "y": 18,
      "z": 5,
      "name": "Plant_Leaves_Gear"
    },
    {
      "x": 9,
      "y": 22,
      "z": 5,
      "name": "Plant_Leaves_Gear"
    },
    {
      "x": 9,
      "y": 19,
      "z": 6,
      "name": "Plant_Leaves_Gear"
    },
    {
      "x": 9,
      "y": 22,
      "z": 6,
      "name": "Plant_Leaves_Gear"
    },
    {
      "x": 9,
      "y": 23,
      "z": 6,
      "name": "Plant_Leaves_Gear"
    },
    {
      "x": 9,
      "y": 15,
      "z": 7,
      "name": "Wood_Gear_Trunk_Full"
    },
    {
      "x": 9,
      "y": 16,
      "z": 7,
      "name": "Wood_Gear_Trunk_Full"
    },
    {
      "x": 9,
      "y": 17,
      "z": 7,
      "name": "Wood_Gear_Branch_Long"
    },
    {
      "x": 9,
      "y": 18,
      "z": 7,
      "name": "Wood_Gear_Branch_Long"
    },
    {
      "x": 9,
      "y": 19,
      "z": 7,
      "name": "Plant_Leaves_Gear"
    },
    {
      "x": 9,
      "y": 20,
      "z": 7,
      "name": "Plant_Leaves_Gear"
    },
    {
      "x": 9,
      "y": 22,
      "z": 7,
      "name": "Plant_Leaves_Gear"
    },
    {
      "x": 9,
      "y": 23,
      "z": 7,
      "name": "Plant_Leaves_Gear"
    },
    {
      "x": 9,
      "y": 16,
      "z": 8,
      "name": "Wood_Gear_Branch_Long",
      "rotation": 4
    },
    {
      "x": 9,
      "y": 19,
      "z": 8,
      "name": "Plant_Leaves_Gear"
    },
    {
      "x": 9,
      "y": 20,
      "z": 8,
      "name": "Plant_Leaves_Gear"
    },
    {
      "x": 9,
      "y": 22,
      "z": 8,
      "name": "Plant_Leaves_Gear"
    },
    {
      "x": 9,
      "y": 23,
      "z": 8,
      "name": "Plant_Leaves_Gear"
    },
    {
      "x": 9,
      "y": 16,
      "z": 9,
      "name": "Plant_Leaves_Gear"
    },
    {
      "x": 9,
      "y": 17,
      "z": 9,
      "name": "Plant_Leaves_Gear"
    },
    {
      "x": 9,
      "y": 19,
      "z": 9,
      "name": "Plant_Leaves_Gear"
    },
    {
      "x": 9,
      "y": 17,
      "z": 11,
      "name": "Plant_Leaves_Gear"
    },
    {
      "x": 9,
      "y": 18,
      "z": 11,
      "name": "Plant_Leaves_Gear"
    },
    {
      "x": 10,
      "y": 16,
      "z": 5,
      "name": "Plant_Leaves_Gear"
    },
    {
      "x": 10,
      "y": 17,
      "z": 5,
      "name": "Plant_Leaves_Gear"
    },
    {
      "x": 10,
      "y": 19,
      "z": 5,
      "name": "Plant_Leaves_Gear"
    },
    {
      "x": 10,
      "y": 21,
      "z": 5,
      "name": "Plant_Leaves_Gear"
    },
    {
      "x": 10,
      "y": 15,
      "z": 6,
      "name": "Plant_Leaves_Gear"
    },
    {
      "x": 10,
      "y": 16,
      "z": 6,
      "name": "Plant_Leaves_Gear"
    },
    {
      "x": 10,
      "y": 19,
      "z": 6,
      "name": "Plant_Leaves_Gear"
    },
    {
      "x": 10,
      "y": 20,
      "z": 6,
      "name": "Plant_Leaves_Gear"
    },
    {
      "x": 10,
      "y": 21,
      "z": 6,
      "name": "Plant_Leaves_Gear"
    },
    {
      "x": 10,
      "y": 22,
      "z": 6,
      "name": "Plant_Leaves_Gear"
    },
    {
      "x": 10,
      "y": 16,
      "z": 7,
      "name": "Wood_Gear_Branch_Long",
      "rotation": 5
    },
    {
      "x": 10,
      "y": 19,
      "z": 7,
      "name": "Plant_Leaves_Gear"
    },
    {
      "x": 10,
      "y": 20,
      "z": 7,
      "name": "Plant_Leaves_Gear"
    },
    {
      "x": 10,
      "y": 21,
      "z": 7,
      "name": "Plant_Leaves_Gear"
    },
    {
      "x": 10,
      "y": 22,
      "z": 7,
      "name": "Plant_Leaves_Gear"
    },
    {
      "x": 10,
      "y": 23,
      "z": 7,
      "name": "Plant_Leaves_Gear"
    },
    {
      "x": 10,
      "y": 19,
      "z": 8,
      "name": "Plant_Leaves_Gear"
    },
    {
      "x": 10,
      "y": 20,
      "z": 8,
      "name": "Plant_Leaves_Gear"
    },
    {
      "x": 10,
      "y": 22,
      "z": 8,
      "name": "Plant_Leaves_Gear"
    },
    {
      "x": 10,
      "y": 16,
      "z": 9,
      "name": "Plant_Leaves_Gear"
    },
    {
      "x": 11,
      "y": 16,
      "z": 5,
      "name": "Plant_Leaves_Gear"
    },
    {
      "x": 11,
      "y": 17,
      "z": 5,
      "name": "Plant_Leaves_Gear"
    },
    {
      "x": 11,
      "y": 15,
      "z": 6,
      "name": "Plant_Leaves_Gear"
    },
    {
      "x": 11,
      "y": 16,
      "z": 6,
      "name": "Plant_Leaves_Gear"
    },
    {
      "x": 11,
      "y": 17,
      "z": 6,
      "name": "Plant_Leaves_Gear"
    },
    {
      "x": 11,
      "y": 18,
      "z": 6,
      "name": "Plant_Leaves_Gear"
    },
    {
      "x": 11,
      "y": 19,
      "z": 6,
      "name": "Plant_Leaves_Gear"
    },
    {
      "x": 11,
      "y": 16,
      "z": 7,
      "name": "Wood_Gear_Branch_Long",
      "rotation": 5
    },
    {
      "x": 11,
      "y": 17,
      "z": 7,
      "name": "Plant_Leaves_Gear"
    },
    {
      "x": 11,
      "y": 18,
      "z": 7,
      "name": "Plant_Leaves_Gear"
    },
    {
      "x": 11,
      "y": 19,
      "z": 7,
      "name": "Plant_Leaves_Gear"
    },
    {
      "x": 11,
      "y": 20,
      "z": 7,
      "name": "Plant_Leaves_Gear"
    },
    {
      "x": 11,
      "y": 15,
      "z": 8,
      "name": "Plant_Leaves_Gear"
    },
    {
      "x": 11,
      "y": 16,
      "z": 8,
      "name": "Plant_Leaves_Gear"
    },
    {
      "x": 11,
      "y": 17,
      "z": 8,
      "name": "Plant_Leaves_Gear"
    },
    {
      "x": 11,
      "y": 18,
      "z": 8,
      "name": "Plant_Leaves_Gear"
    },
    {
      "x": 11,
      "y": 19,
      "z": 8,
      "name": "Plant_Leaves_Gear"
    },
    {
      "x": 11,
      "y": 16,
      "z": 9,
      "name": "Plant_Leaves_Gear"
    },
    {
      "x": 11,
      "y": 17,
      "z": 9,
      "name": "Plant_Leaves_Gear"
    },
    {
      "x": 12,
      "y": 15,
      "z": 6,
      "name": "Plant_Leaves_Gear"
    },
    {
      "x": 12,
      "y": 16,
      "z": 6,
      "name": "Plant_Leaves_Gear"
    },
    {
      "x": 12,
      "y": 15,
      "z": 7,
      "name": "Plant_Leaves_Gear"
    },
    {
      "x": 12,
      "y": 16,
      "z": 7,
      "name": "Plant_Leaves_Gear"
    },
    {
      "x": 12,
      "y": 17,
      "z": 7,
      "name": "Plant_Leaves_Gear"
    },
    {
      "x": 12,
      "y": 15,
      "z": 8,
      "name": "Plant_Leaves_Gear"
    },
    {
      "x": 12,
      "y": 16,
      "z": 8,
      "name": "Plant_Leaves_Gear"
    },
    {
      "x": 12,
      "y": 17,
      "z": 8,
      "name": "Plant_Leaves_Gear"
    }
  ]
}