{
  "version": 8,
  "blockIdVersion": 11,
  "anchorX": -48,
  "anchorY": 29,
  "anchorZ": 29,
  "blocks": [
    {
      "x": -63,
      "y": 27,
      "z": 30,
      "name": "Rock_Rusty_Metal",
      "rotation": 13
    },
    {
      "x": -63,
      "y": 31,
      "z": 30,
      "name": "Rock_Rusty_Metal",
      "rotation": 13
    },
    {
      "x": -63,
      "y": 27,
      "z": 31,
      "name": "Rock_Rusty_Metal",
      "rotation": 6
    },
    {
      "x": -63,
      "y": 31,
      "z": 31,
      "name": "Rock_Rusty_Metal",
      "rotation": 6
    },
    {
      "x": -62,
      "y": 22,
      "z": 30,
      "name": "Rock_Rusty_Metal",
      "rotation": 13
    },
    {
      "x": -62,
      "y": 23,
      "z": 30,
      "name": "Rock_Rusty_Metal",
      "rotation": 13
    },
    {
      "x": -62,
      "y": 26,
      "z": 30,
      "name": "Rock_Rusty_Metal",
      "rotation": 13
    },
    {
      "x": -62,
      "y": 27,
      "z": 30,
      "name": "Rock_Rusty_Metal",
      "rotation": 13
    },
    {
      "x": -62,
      "y": 28,
      "z": 30,
      "name": "Rock_Rusty_Metal",
      "rotation": 13
    },
    {
      "x": -62,
      "y": 30,
      "z": 30,
      "name": "Rock_Rusty_Metal",
      "rotation": 13
    },
    {
      "x": -62,
      "y": 31,
      "z": 30,
      "name": "Rock_Rusty_Metal",
      "rotation": 13
    },
    {
      "x": -62,
      "y": 32,
      "z": 30,
      "name": "Rock_Rusty_Metal",
      "rotation": 13
    },
    {
      "x": -62,
      "y": 35,
      "z": 30,
      "name": "Rock_Rusty_Metal",
      "rotation": 13
    },
    {
      "x": -62,
      "y": 36,
      "z": 30,
      "name": "Rock_Rusty_Metal",
      "rotation": 13
    },
    {
      "x": -62,
      "y": 22,
      "z": 31,
      "name": "Rock_Rusty_Metal",
      "rotation": 6
    },
    {
      "x": -62,
      "y": 23,
      "z": 31,
      "name": "Rock_Rusty_Metal",
      "rotation": 6
    },
    {
      "x": -62,
      "y": 26,
      "z": 31,
      "name": "Rock_Rusty_Metal",
      "rotation": 6
    },
    {
      "x": -62,
      "y": 27,
      "z": 31,
      "name": "Rock_Rusty_Metal",
      "rotation": 6
    },
    {
      "x": -62,
      "y": 28,
      "z": 31,
      "name": "Rock_Rusty_Metal",
      "rotation": 6
    },
    {
      "x": -62,
      "y": 30,
      "z": 31,
      "name": "Rock_Rusty_Metal",
      "rotation": 6
    },
    {
      "x": -62,
      "y": 31,
      "z": 31,
      "name": "Rock_Rusty_Metal",
      "rotation": 6
    },
    {
      "x": -62,
      "y": 32,
      "z": 31,
      "name": "Rock_Rusty_Metal",
      "rotation": 6
    },
    {
      "x": -62,
      "y": 35,
      "z": 31,
      "name": "Rock_Rusty_Metal",
      "rotation": 6
    },
    {
      "x": -62,
      "y": 36,
      "z": 31,
      "name": "Rock_Rusty_Metal",
      "rotation": 6
    },
    {
      "x": -61,
      "y": 21,
      "z": 30,
      "name": "Rock_Rusty_Metal",
      "rotation": 13
    },
    {
      "x": -61,
      "y": 22,
      "z": 30,
      "name": "Rock_Rusty_Metal",
      "rotation": 13
    },
    {
      "x": -61,
      "y": 23,
      "z": 30,
      "name": "Rock_Rusty_Metal",
      "rotation": 13
    },
    {
      "x": -61,
      "y": 24,
      "z": 30,
      "name": "Rock_Rusty_Metal",
      "rotation": 13
    },
    {
      "x": -61,
      "y": 26,
      "z": 30,
      "name": "Rock_Dark_Rusty_Metal",
      "rotation": 13
    },
    {
      "x": -61,
      "y": 27,
      "z": 30,
      "name": "Rock_Dark_Rusty_Metal",
      "rotation": 13
    },
    {
      "x": -61,
      "y": 28,
      "z": 30,
      "name": "Rock_Dark_Rusty_Metal",
      "rotation": 13
    },
    {
      "x": -61,
      "y": 29,
      "z": 30,
      "name": "Rock_Dark_Rusty_Metal",
      "rotation": 13
    },
    {
      "x": -61,
      "y": 30,
      "z": 30,
      "name": "Rock_Dark_Rusty_Metal",
      "rotation": 13
    },
    {
      "x": -61,
      "y": 31,
      "z": 30,
      "name": "Rock_Dark_Rusty_Metal",
      "rotation": 13
    },
    {
      "x": -61,
      "y": 32,
      "z": 30,
      "name": "Rock_Dark_Rusty_Metal",
      "rotation": 13
    },
    {
      "x": -61,
      "y": 34,
      "z": 30,
      "name": "Rock_Rusty_Metal",
      "rotation": 13
    },
    {
      "x": -61,
      "y": 35,
      "z": 30,
      "name": "Rock_Rusty_Metal",
      "rotation": 13
    },
    {
      "x": -61,
      "y": 36,
      "z": 30,
      "name": "Rock_Rusty_Metal",
      "rotation": 13
    },
    {
      "x": -61,
      "y": 37,
      "z": 30,
      "name": "Rock_Rusty_Metal",
      "rotation": 13
    },
    {
      "x": -61,
      "y": 21,
      "z": 31,
      "name": "Rock_Rusty_Metal",
      "rotation": 6
    },
    {
      "x": -61,
      "y": 22,
      "z": 31,
      "name": "Rock_Rusty_Metal",
      "rotation": 6
    },
    {
      "x": -61,
      "y": 23,
      "z": 31,
      "name": "Rock_Rusty_Metal",
      "rotation": 6
    },
    {
      "x": -61,
      "y": 24,
      "z": 31,
      "name": "Rock_Rusty_Metal",
      "rotation": 6
    },
    {
      "x": -61,
      "y": 26,
      "z": 31,
      "name": "Rock_Dark_Rusty_Metal",
      "rotation": 6
    },
    {
      "x": -61,
      "y": 27,
      "z": 31,
      "name": "Rock_Dark_Rusty_Metal",
      "rotation": 6
    },
    {
      "x": -61,
      "y": 28,
      "z": 31,
      "name": "Rock_Dark_Rusty_Metal",
      "rotation": 6
    },
    {
      "x": -61,
      "y": 29,
      "z": 31,
      "name": "Rock_Dark_Rusty_Metal",
      "rotation": 6
    },
    {
      "x": -61,
      "y": 30,
      "z": 31,
      "name": "Rock_Dark_Rusty_Metal",
      "rotation": 6
    },
    {
      "x": -61,
      "y": 31,
      "z": 31,
      "name": "Rock_Dark_Rusty_Metal",
      "rotation": 6
    },
    {
      "x": -61,
      "y": 32,
      "z": 31,
      "name": "Rock_Dark_Rusty_Metal",
      "rotation": 6
    },
    {
      "x": -61,
      "y": 34,
      "z": 31,
      "name": "Rock_Rusty_Metal",
      "rotation": 6
    },
    {
      "x": -61,
      "y": 35,
      "z": 31,
      "name": "Rock_Rusty_Metal",
      "rotation": 6
    },
    {
      "x": -61,
      "y": 36,
      "z": 31,
      "name": "Rock_Rusty_Metal",
      "rotation": 6
    },
    {
      "x": -61,
      "y": 37,
      "z": 31,
      "name": "Rock_Rusty_Metal",
      "rotation": 6
    },
    {
      "x": -60,
      "y": 26,
      "z": 29,
      "name": "Rock_Rusty_Metal",
      "rotation": 13
    },
    {
      "x": -60,
      "y": 27,
      "z": 29,
      "name": "Rock_Rusty_Metal",
      "rotation": 13
    },
    {
      "x": -60,
      "y": 28,
      "z": 29,
      "name": "Rock_Rusty_Metal",
      "rotation": 13
    },
    {
      "x": -60,
      "y": 29,
      "z": 29,
      "name": "Rock_Rusty_Metal",
      "rotation": 13
    },
    {
      "x": -60,
      "y": 30,
      "z": 29,
      "name": "Rock_Rusty_Metal",
      "rotation": 13
    },
    {
      "x": -60,
      "y": 31,
      "z": 29,
      "name": "Rock_Rusty_Metal",
      "rotation": 13
    },
    {
      "x": -60,
      "y": 32,
      "z": 29,
      "name": "Rock_Rusty_Metal",
      "rotation": 13
    },
    {
      "x": -60,
      "y": 22,
      "z": 30,
      "name": "Rock_Rusty_Metal",
      "rotation": 13
    },
    {
      "x": -60,
      "y": 23,
      "z": 30,
      "name": "Rock_Dark_Rusty_Metal",
      "rotation": 13
    },
    {
      "x": -60,
      "y": 24,
      "z": 30,
      "name": "Rock_Dark_Rusty_Metal",
      "rotation": 13
    },
    {
      "x": -60,
      "y": 25,
      "z": 30,
      "name": "Rock_Dark_Rusty_Metal",
      "rotation": 13
    },
    {
      "x": -60,
      "y": 26,
      "z": 30,
      "name": "Rock_Rusty_Metal",
      "rotation": 13
    },
    {
      "x": -60,
      "y": 27,
      "z": 30,
      "name": "Rock_Rusty_Metal",
      "rotation": 13
    },
    {
      "x": -60,
      "y": 28,
      "z": 30,
      "name": "Rock_Rusty_Metal",
      "rotation": 13
    },
    {
      "x": -60,
      "y": 29,
      "z": 30,
      "name": "Rock_Rusty_Metal",
      "rotation": 13
    },
    {
      "x": -60,
      "y": 30,
      "z": 30,
      "name": "Rock_Rusty_Metal",
      "rotation": 13
    },
    {
      "x": -60,
      "y": 31,
      "z": 30,
      "name": "Rock_Rusty_Metal",
      "rotation": 13
    },
    {
      "x": -60,
      "y": 32,
      "z": 30,
      "name": "Rock_Rusty_Metal",
      "rotation": 13
    },
    {
      "x": -60,
      "y": 33,
      "z": 30,
      "name": "Rock_Dark_Rusty_Metal",
      "rotation": 13
    },
    {
      "x": -60,
      "y": 34,
      "z": 30,
      "name": "Rock_Dark_Rusty_Metal",
      "rotation": 13
    },
    {
      "x": -60,
      "y": 35,
      "z": 30,
      "name": "Rock_Dark_Rusty_Metal",
      "rotation": 13
    },
    {
      "x": -60,
      "y": 36,
      "z": 30,
      "name": "Rock_Rusty_Metal",
      "rotation": 13
    },
    {
      "x": -60,
      "y": 22,
      "z": 31,
      "name": "Rock_Rusty_Metal",
      "rotation": 6
    },
    {
      "x": -60,
      "y": 23,
      "z": 31,
      "name": "Rock_Dark_Rusty_Metal",
      "rotation": 6
    },
    {
      "x": -60,
      "y": 24,
      "z": 31,
      "name": "Rock_Dark_Rusty_Metal",
      "rotation": 6
    },
    {
      "x": -60,
      "y": 25,
      "z": 31,
      "name": "Rock_Dark_Rusty_Metal",
      "rotation": 6
    },
    {
      "x": -60,
      "y": 26,
      "z": 31,
      "name": "Rock_Rusty_Metal",
      "rotation": 6
    },
    {
      "x": -60,
      "y": 27,
      "z": 31,
      "name": "Rock_Rusty_Metal",
      "rotation": 6
    },
    {
      "x": -60,
      "y": 28,
      "z": 31,
      "name": "Rock_Rusty_Metal",
      "rotation": 6
    },
    {
      "x": -60,
      "y": 29,
      "z": 31,
      "name": "Rock_Rusty_Metal",
      "rotation": 6
    },
    {
      "x": -60,
      "y": 30,
      "z": 31,
      "name": "Rock_Rusty_Metal",
      "rotation": 6
    },
    {
      "x": -60,
      "y": 31,
      "z": 31,
      "name": "Rock_Rusty_Metal",
      "rotation": 6
    },
    {
      "x": -60,
      "y": 32,
      "z": 31,
      "name": "Rock_Rusty_Metal",
      "rotation": 6
    },
    {
      "x": -60,
      "y": 33,
      "z": 31,
      "name": "Rock_Dark_Rusty_Metal",
      "rotation": 6
    },
    {
      "x": -60,
      "y": 34,
      "z": 31,
      "name": "Rock_Dark_Rusty_Metal",
      "rotation": 6
    },
    {
      "x": -60,
      "y": 35,
      "z": 31,
      "name": "Rock_Dark_Rusty_Metal",
      "rotation": 6
    },
    {
      "x": -60,
      "y": 36,
      "z": 31,
      "name": "Rock_Rusty_Metal",
      "rotation": 6
    },
    {
      "x": -60,
      "y": 26,
      "z": 32,
      "name": "Rock_Rusty_Metal",
      "rotation": 6
    },
    {
      "x": -60,
      "y": 27,
      "z": 32,
      "name": "Rock_Rusty_Metal",
      "rotation": 6
    },
    {
      "x": -60,
      "y": 28,
      "z": 32,
      "name": "Rock_Rusty_Metal",
      "rotation": 6
    },
    {
      "x": -60,
      "y": 29,
      "z": 32,
      "name": "Rock_Rusty_Metal",
      "rotation": 6
    },
    {
      "x": -60,
      "y": 30,
      "z": 32,
      "name": "Rock_Rusty_Metal",
      "rotation": 6
    },
    {
      "x": -60,
      "y": 31,
      "z": 32,
      "name": "Rock_Rusty_Metal",
      "rotation": 6
    },
    {
      "x": -60,
      "y": 32,
      "z": 32,
      "name": "Rock_Rusty_Metal",
      "rotation": 6
    },
    {
      "x": -59,
      "y": 23,
      "z": 29,
      "name": "Rock_Rusty_Metal",
      "rotation": 13
    },
    {
      "x": -59,
      "y": 24,
      "z": 29,
      "name": "Rock_Rusty_Metal",
      "rotation": 13
    },
    {
      "x": -59,
      "y": 25,
      "z": 29,
      "name": "Rock_Rusty_Metal",
      "rotation": 13
    },
    {
      "x": -59,
      "y": 26,
      "z": 29,
      "name": "Rock_Rusty_Metal",
      "rotation": 13
    },
    {
      "x": -59,
      "y": 27,
      "z": 29,
      "name": "Rock_Rusty_Metal",
      "rotation": 13
    },
    {
      "x": -59,
      "y": 28,
      "z": 29,
      "name": "Rock_Rusty_Metal",
      "rotation": 13
    },
    {
      "x": -59,
      "y": 29,
      "z": 29,
      "name": "Rock_Rusty_Metal",
      "rotation": 13
    },
    {
      "x": -59,
      "y": 30,
      "z": 29,
      "name": "Rock_Rusty_Metal",
      "rotation": 13
    },
    {
      "x": -59,
      "y": 31,
      "z": 29,
      "name": "Rock_Rusty_Metal",
      "rotation": 13
    },
    {
      "x": -59,
      "y": 32,
      "z": 29,
      "name": "Rock_Rusty_Metal",
      "rotation": 13
    },
    {
      "x": -59,
      "y": 33,
      "z": 29,
      "name": "Rock_Rusty_Metal",
      "rotation": 13
    },
    {
      "x": -59,
      "y": 34,
      "z": 29,
      "name": "Rock_Rusty_Metal",
      "rotation": 13
    },
    {
      "x": -59,
      "y": 35,
      "z": 29,
      "name": "Rock_Rusty_Metal",
      "rotation": 13
    },
    {
      "x": -59,
      "y": 18,
      "z": 30,
      "name": "Rock_Rusty_Metal",
      "rotation": 13
    },
    {
      "x": -59,
      "y": 19,
      "z": 30,
      "name": "Rock_Rusty_Metal",
      "rotation": 13
    },
    {
      "x": -59,
      "y": 21,
      "z": 30,
      "name": "Rock_Dark_Rusty_Metal",
      "rotation": 13
    },
    {
      "x": -59,
      "y": 22,
      "z": 30,
      "name": "Rock_Dark_Rusty_Metal",
      "rotation": 13
    },
    {
      "x": -59,
      "y": 23,
      "z": 30,
      "name": "Rock_Rusty_Metal",
      "rotation": 13
    },
    {
      "x": -59,
      "y": 24,
      "z": 30,
      "name": "Rock_Rusty_Metal",
      "rotation": 13
    },
    {
      "x": -59,
      "y": 25,
      "z": 30,
      "name": "Rock_Rusty_Metal",
      "rotation": 13
    },
    {
      "x": -59,
      "y": 26,
      "z": 30,
      "name": "Rock_Rusty_Metal",
      "rotation": 13
    },
    {
      "x": -59,
      "y": 27,
      "z": 30,
      "name": "Rock_Rusty_Metal",
      "rotation": 13
    },
    {
      "x": -59,
      "y": 28,
      "z": 30,
      "name": "Rock_Rusty_Metal",
      "rotation": 13
    },
    {
      "x": -59,
      "y": 29,
      "z": 30,
      "name": "Rock_Rusty_Metal",
      "rotation": 13
    },
    {
      "x": -59,
      "y": 30,
      "z": 30,
      "name": "Rock_Rusty_Metal",
      "rotation": 13
    },
    {
      "x": -59,
      "y": 31,
      "z": 30,
      "name": "Rock_Rusty_Metal",
      "rotation": 13
    },
    {
      "x": -59,
      "y": 32,
      "z": 30,
      "name": "Rock_Rusty_Metal",
      "rotation": 13
    },
    {
      "x": -59,
      "y": 33,
      "z": 30,
      "name": "Rock_Rusty_Metal",
      "rotation": 13
    },
    {
      "x": -59,
      "y": 34,
      "z": 30,
      "name": "Rock_Rusty_Metal",
      "rotation": 13
    },
    {
      "x": -59,
      "y": 35,
      "z": 30,
      "name": "Rock_Rusty_Metal",
      "rotation": 13
    },
    {
      "x": -59,
      "y": 36,
      "z": 30,
      "name": "Rock_Dark_Rusty_Metal",
      "rotation": 13
    },
    {
      "x": -59,
      "y": 37,
      "z": 30,
      "name": "Rock_Dark_Rusty_Metal",
      "rotation": 13
    },
    {
      "x": -59,
      "y": 39,
      "z": 30,
      "name": "Rock_Rusty_Metal",
      "rotation": 13
    },
    {
      "x": -59,
      "y": 40,
      "z": 30,
      "name": "Rock_Rusty_Metal",
      "rotation": 13
    },
    {
      "x": -59,
      "y": 18,
      "z": 31,
      "name": "Rock_Rusty_Metal",
      "rotation": 6
    },
    {
      "x": -59,
      "y": 19,
      "z": 31,
      "name": "Rock_Rusty_Metal",
      "rotation": 6
    },
    {
      "x": -59,
      "y": 21,
      "z": 31,
      "name": "Rock_Dark_Rusty_Metal",
      "rotation": 6
    },
    {
      "x": -59,
      "y": 22,
      "z": 31,
      "name": "Rock_Dark_Rusty_Metal",
      "rotation": 6
    },
    {
      "x": -59,
      "y": 23,
      "z": 31,
      "name": "Rock_Rusty_Metal",
      "rotation": 6
    },
    {
      "x": -59,
      "y": 24,
      "z": 31,
      "name": "Rock_Rusty_Metal",
      "rotation": 6
    },
    {
      "x": -59,
      "y": 25,
      "z": 31,
      "name": "Rock_Rusty_Metal",
      "rotation": 6
    },
    {
      "x": -59,
      "y": 26,
      "z": 31,
      "name": "Rock_Rusty_Metal",
      "rotation": 6
    },
    {
      "x": -59,
      "y": 27,
      "z": 31,
      "name": "Rock_Rusty_Metal",
      "rotation": 6
    },
    {
      "x": -59,
      "y": 28,
      "z": 31,
      "name": "Rock_Rusty_Metal",
      "rotation": 6
    },
    {
      "x": -59,
      "y": 29,
      "z": 31,
      "name": "Rock_Rusty_Metal",
      "rotation": 6
    },
    {
      "x": -59,
      "y": 30,
      "z": 31,
      "name": "Rock_Rusty_Metal",
      "rotation": 6
    },
    {
      "x": -59,
      "y": 31,
      "z": 31,
      "name": "Rock_Rusty_Metal",
      "rotation": 6
    },
    {
      "x": -59,
      "y": 32,
      "z": 31,
      "name": "Rock_Rusty_Metal",
      "rotation": 6
    },
    {
      "x": -59,
      "y": 33,
      "z": 31,
      "name": "Rock_Rusty_Metal",
      "rotation": 6
    },
    {
      "x": -59,
      "y": 34,
      "z": 31,
      "name": "Rock_Rusty_Metal",
      "rotation": 6
    },
    {
      "x": -59,
      "y": 35,
      "z": 31,
      "name": "Rock_Rusty_Metal",
      "rotation": 6
    },
    {
      "x": -59,
      "y": 36,
      "z": 31,
      "name": "Rock_Dark_Rusty_Metal",
      "rotation": 6
    },
    {
      "x": -59,
      "y": 37,
      "z": 31,
      "name": "Rock_Dark_Rusty_Metal",
      "rotation": 6
    },
    {
      "x": -59,
      "y": 39,
      "z": 31,
      "name": "Rock_Rusty_Metal",
      "rotation": 6
    },
    {
      "x": -59,
      "y": 40,
      "z": 31,
      "name": "Rock_Rusty_Metal",
      "rotation": 6
    },
    {
      "x": -59,
      "y": 23,
      "z": 32,
      "name": "Rock_Rusty_Metal",
      "rotation": 6
    },
    {
      "x": -59,
      "y": 24,
      "z": 32,
      "name": "Rock_Rusty_Metal",
      "rotation": 6
    },
    {
      "x": -59,
      "y": 25,
      "z": 32,
      "name": "Rock_Rusty_Metal",
      "rotation": 6
    },
    {
      "x": -59,
      "y": 26,
      "z": 32,
      "name": "Rock_Rusty_Metal",
      "rotation": 6
    },
    {
      "x": -59,
      "y": 27,
      "z": 32,
      "name": "Rock_Rusty_Metal",
      "rotation": 6
    },
    {
      "x": -59,
      "y": 28,
      "z": 32,
      "name": "Rock_Rusty_Metal",
      "rotation": 6
    },
    {
      "x": -59,
      "y": 29,
      "z": 32,
      "name": "Rock_Rusty_Metal",
      "rotation": 6
    },
    {
      "x": -59,
      "y": 30,
      "z": 32,
      "name": "Rock_Rusty_Metal",
      "rotation": 6
    },
    {
      "x": -59,
      "y": 31,
      "z": 32,
      "name": "Rock_Rusty_Metal",
      "rotation": 6
    },
    {
      "x": -59,
      "y": 32,
      "z": 32,
      "name": "Rock_Rusty_Metal",
      "rotation": 6
    },
    {
      "x": -59,
      "y": 33,
      "z": 32,
      "name": "Rock_Rusty_Metal",
      "rotation": 6
    },
    {
      "x": -59,
      "y": 34,
      "z": 32,
      "name": "Rock_Rusty_Metal",
      "rotation": 6
    },
    {
      "x": -59,
      "y": 35,
      "z": 32,
      "name": "Rock_Rusty_Metal",
      "rotation": 6
    },
    {
      "x": -58,
      "y": 21,
      "z": 29,
      "name": "Rock_Rusty_Metal",
      "rotation": 13
    },
    {
      "x": -58,
      "y": 22,
      "z": 29,
      "name": "Rock_Rusty_Metal",
      "rotation": 13
    },
    {
      "x": -58,
      "y": 23,
      "z": 29,
      "name": "Rock_Rusty_Metal",
      "rotation": 13
    },
    {
      "x": -58,
      "y": 24,
      "z": 29,
      "name": "Rock_Rusty_Metal",
      "rotation": 13
    },
    {
      "x": -58,
      "y": 25,
      "z": 29,
      "name": "Rock_Rusty_Metal",
      "rotation": 13
    },
    {
      "x": -58,
      "y": 29,
      "z": 29,
      "name": "Rock_Rusty_Metal",
      "rotation": 13
    },
    {
      "x": -58,
      "y": 33,
      "z": 29,
      "name": "Rock_Rusty_Metal",
      "rotation": 13
    },
    {
      "x": -58,
      "y": 34,
      "z": 29,
      "name": "Rock_Rusty_Metal",
      "rotation": 13
    },
    {
      "x": -58,
      "y": 35,
      "z": 29,
      "name": "Rock_Rusty_Metal",
      "rotation": 13
    },
    {
      "x": -58,
      "y": 36,
      "z": 29,
      "name": "Rock_Rusty_Metal",
      "rotation": 13
    },
    {
      "x": -58,
      "y": 17,
      "z": 30,
      "name": "Rock_Rusty_Metal",
      "rotation": 13
    },
    {
      "x": -58,
      "y": 18,
      "z": 30,
      "name": "Rock_Rusty_Metal",
      "rotation": 13
    },
    {
      "x": -58,
      "y": 19,
      "z": 30,
      "name": "Rock_Rusty_Metal",
      "rotation": 13
    },
    {
      "x": -58,
      "y": 20,
      "z": 30,
      "name": "Rock_Dark_Rusty_Metal",
      "rotation": 13
    },
    {
      "x": -58,
      "y": 21,
      "z": 30,
      "name": "Rock_Rusty_Metal",
      "rotation": 13
    },
    {
      "x": -58,
      "y": 22,
      "z": 30,
      "name": "Rock_Rusty_Metal",
      "rotation": 13
    },
    {
      "x": -58,
      "y": 23,
      "z": 30,
      "name": "Rock_Rusty_Metal",
      "rotation": 13
    },
    {
      "x": -58,
      "y": 24,
      "z": 30,
      "name": "Rock_Rusty_Metal",
      "rotation": 13
    },
    {
      "x": -58,
      "y": 25,
      "z": 30,
      "name": "Rock_Rusty_Metal",
      "rotation": 13
    },
    {
      "x": -58,
      "y": 26,
      "z": 30,
      "name": "Rock_Dark_Rusty_Metal",
      "rotation": 13
    },
    {
      "x": -58,
      "y": 27,
      "z": 30,
      "name": "Rock_Dark_Rusty_Metal",
      "rotation": 13
    },
    {
      "x": -58,
      "y": 28,
      "z": 30,
      "name": "Rock_Dark_Rusty_Metal",
      "rotation": 13
    },
    {
      "x": -58,
      "y": 29,
      "z": 30,
      "name": "Rock_Rusty_Metal",
      "rotation": 13
    },
    {
      "x": -58,
      "y": 30,
      "z": 30,
      "name": "Rock_Dark_Rusty_Metal",
      "rotation": 13
    },
    {
      "x": -58,
      "y": 31,
      "z": 30,
      "name": "Rock_Dark_Rusty_Metal",
      "rotation": 13
    },
    {
      "x": -58,
      "y": 32,
      "z": 30,
      "name": "Rock_Dark_Rusty_Metal",
      "rotation": 13
    },
    {
      "x": -58,
      "y": 33,
      "z": 30,
      "name": "Rock_Rusty_Metal",
      "rotation": 13
    },
    {
      "x": -58,
      "y": 34,
      "z": 30,
      "name": "Rock_Rusty_Metal",
      "rotation": 13
    },
    {
      "x": -58,
      "y": 35,
      "z": 30,
      "name": "Rock_Rusty_Metal",
      "rotation": 13
    },
    {
      "x": -58,
      "y": 36,
      "z": 30,
      "name": "Rock_Rusty_Metal",
      "rotation": 13
    },
    {
      "x": -58,
      "y": 37,
      "z": 30,
      "name": "Rock_Dark_Rusty_Metal",
      "rotation": 13
    },
    {
      "x": -58,
      "y": 38,
      "z": 30,
      "name": "Rock_Dark_Rusty_Metal",
      "rotation": 13
    },
    {
      "x": -58,
      "y": 39,
      "z": 30,
      "name": "Rock_Rusty_Metal",
      "rotation": 13
    },
    {
      "x": -58,
      "y": 40,
      "z": 30,
      "name": "Rock_Rusty_Metal",
      "rotation": 13
    },
    {
      "x": -58,
      "y": 41,
      "z": 30,
      "name": "Rock_Rusty_Metal",
      "rotation": 13
    },
    {
      "x": -58,
      "y": 17,
      "z": 31,
      "name": "Rock_Rusty_Metal",
      "rotation": 6
    },
    {
      "x": -58,
      "y": 18,
      "z": 31,
      "name": "Rock_Rusty_Metal",
      "rotation": 6
    },
    {
      "x": -58,
      "y": 19,
      "z": 31,
      "name": "Rock_Rusty_Metal",
      "rotation": 6
    },
    {
      "x": -58,
      "y": 20,
      "z": 31,
      "name": "Rock_Dark_Rusty_Metal",
      "rotation": 6
    },
    {
      "x": -58,
      "y": 21,
      "z": 31,
      "name": "Rock_Rusty_Metal",
      "rotation": 6
    },
    {
      "x": -58,
      "y": 22,
      "z": 31,
      "name": "Rock_Rusty_Metal",
      "rotation": 6
    },
    {
      "x": -58,
      "y": 23,
      "z": 31,
      "name": "Rock_Rusty_Metal",
      "rotation": 6
    },
    {
      "x": -58,
      "y": 24,
      "z": 31,
      "name": "Rock_Rusty_Metal",
      "rotation": 6
    },
    {
      "x": -58,
      "y": 25,
      "z": 31,
      "name": "Rock_Rusty_Metal",
      "rotation": 6
    },
    {
      "x": -58,
      "y": 26,
      "z": 31,
      "name": "Rock_Dark_Rusty_Metal",
      "rotation": 6
    },
    {
      "x": -58,
      "y": 27,
      "z": 31,
      "name": "Rock_Dark_Rusty_Metal",
      "rotation": 6
    },
    {
      "x": -58,
      "y": 28,
      "z": 31,
      "name": "Rock_Dark_Rusty_Metal",
      "rotation": 6
    },
    {
      "x": -58,
      "y": 29,
      "z": 31,
      "name": "Rock_Rusty_Metal",
      "rotation": 6
    },
    {
      "x": -58,
      "y": 30,
      "z": 31,
      "name": "Rock_Dark_Rusty_Metal",
      "rotation": 6
    },
    {
      "x": -58,
      "y": 31,
      "z": 31,
      "name": "Rock_Dark_Rusty_Metal",
      "rotation": 6
    },
    {
      "x": -58,
      "y": 32,
      "z": 31,
      "name": "Rock_Dark_Rusty_Metal",
      "rotation": 6
    },
    {
      "x": -58,
      "y": 33,
      "z": 31,
      "name": "Rock_Rusty_Metal",
      "rotation": 6
    },
    {
      "x": -58,
      "y": 34,
      "z": 31,
      "name": "Rock_Rusty_Metal",
      "rotation": 6
    },
    {
      "x": -58,
      "y": 35,
      "z": 31,
      "name": "Rock_Rusty_Metal",
      "rotation": 6
    },
    {
      "x": -58,
      "y": 36,
      "z": 31,
      "name": "Rock_Rusty_Metal",
      "rotation": 6
    },
    {
      "x": -58,
      "y": 37,
      "z": 31,
      "name": "Rock_Rusty_Metal",
      "rotation": 6
    },
    {
      "x": -58,
      "y": 38,
      "z": 31,
      "name": "Rock_Dark_Rusty_Metal",
      "rotation": 6
    },
    {
      "x": -58,
      "y": 39,
      "z": 31,
      "name": "Rock_Rusty_Metal",
      "rotation": 6
    },
    {
      "x": -58,
      "y": 40,
      "z": 31,
      "name": "Rock_Rusty_Metal",
      "rotation": 6
    },
    {
      "x": -58,
      "y": 41,
      "z": 31,
      "name": "Rock_Rusty_Metal",
      "rotation": 6
    },
    {
      "x": -58,
      "y": 21,
      "z": 32,
      "name": "Rock_Rusty_Metal",
      "rotation": 6
    },
    {
      "x": -58,
      "y": 22,
      "z": 32,
      "name": "Rock_Rusty_Metal",
      "rotation": 6
    },
    {
      "x": -58,
      "y": 23,
      "z": 32,
      "name": "Rock_Rusty_Metal",
      "rotation": 6
    },
    {
      "x": -58,
      "y": 24,
      "z": 32,
      "name": "Rock_Rusty_Metal",
      "rotation": 6
    },
    {
      "x": -58,
      "y": 25,
      "z": 32,
      "name": "Rock_Rusty_Metal",
      "rotation": 6
    },
    {
      "x": -58,
      "y": 29,
      "z": 32,
      "name": "Rock_Rusty_Metal",
      "rotation": 6
    },
    {
      "x": -58,
      "y": 33,
      "z": 32,
      "name": "Rock_Rusty_Metal",
      "rotation": 6
    },
    {
      "x": -58,
      "y": 34,
      "z": 32,
      "name": "Rock_Rusty_Metal",
      "rotation": 6
    },
    {
      "x": -58,
      "y": 35,
      "z": 32,
      "name": "Rock_Rusty_Metal",
      "rotation": 6
    },
    {
      "x": -58,
      "y": 36,
      "z": 32,
      "name": "Rock_Rusty_Metal",
      "rotation": 6
    },
    {
      "x": -58,
      "y": 37,
      "z": 32,
      "name": "Rock_Rusty_Metal",
      "rotation": 6
    },
    {
      "x": -57,
      "y": 20,
      "z": 29,
      "name": "Rock_Rusty_Metal",
      "rotation": 13
    },
    {
      "x": -57,
      "y": 21,
      "z": 29,
      "name": "Rock_Rusty_Metal",
      "rotation": 13
    },
    {
      "x": -57,
      "y": 22,
      "z": 29,
      "name": "Rock_Rusty_Metal",
      "rotation": 13
    },
    {
      "x": -57,
      "y": 29,
      "z": 29,
      "name": "Rock_Rusty_Metal",
      "rotation": 13
    },
    {
      "x": -57,
      "y": 36,
      "z": 29,
      "name": "Rock_Rusty_Metal",
      "rotation": 13
    },
    {
      "x": -57,
      "y": 37,
      "z": 29,
      "name": "Rock_Rusty_Metal",
      "rotation": 13
    },
    {
      "x": -57,
      "y": 38,
      "z": 29,
      "name": "Rock_Rusty_Metal",
      "rotation": 13
    },
    {
      "x": -57,
      "y": 17,
      "z": 30,
      "name": "Rock_Rusty_Metal",
      "rotation": 13
    },
    {
      "x": -57,
      "y": 18,
      "z": 30,
      "name": "Rock_Rusty_Metal",
      "rotation": 13
    },
    {
      "x": -57,
      "y": 19,
      "z": 30,
      "name": "Rock_Dark_Rusty_Metal",
      "rotation": 13
    },
    {
      "x": -57,
      "y": 20,
      "z": 30,
      "name": "Rock_Rusty_Metal",
      "rotation": 13
    },
    {
      "x": -57,
      "y": 21,
      "z": 30,
      "name": "Rock_Rusty_Metal",
      "rotation": 13
    },
    {
      "x": -57,
      "y": 22,
      "z": 30,
      "name": "Rock_Rusty_Metal",
      "rotation": 13
    },
    {
      "x": -57,
      "y": 23,
      "z": 30,
      "name": "Rock_Dark_Rusty_Metal",
      "rotation": 13
    },
    {
      "x": -57,
      "y": 24,
      "z": 30,
      "name": "Rock_Dark_Rusty_Metal",
      "rotation": 13
    },
    {
      "x": -57,
      "y": 25,
      "z": 30,
      "name": "Rock_Dark_Rusty_Metal",
      "rotation": 13
    },
    {
      "x": -57,
      "y": 28,
      "z": 30,
      "name": "Rock_Dark_Rusty_Metal",
      "rotation": 13
    },
    {
      "x": -57,
      "y": 29,
      "z": 30,
      "name": "Rock_Rusty_Metal",
      "rotation": 13
    },
    {
      "x": -57,
      "y": 30,
      "z": 30,
      "name": "Rock_Dark_Rusty_Metal",
      "rotation": 13
    },
    {
      "x": -57,
      "y": 33,
      "z": 30,
      "name": "Rock_Dark_Rusty_Metal",
      "rotation": 13
    },
    {
      "x": -57,
      "y": 34,
      "z": 30,
      "name": "Rock_Dark_Rusty_Metal",
      "rotation": 13
    },
    {
      "x": -57,
      "y": 35,
      "z": 30,
      "name": "Rock_Dark_Rusty_Metal",
      "rotation": 13
    },
    {
      "x": -57,
      "y": 36,
      "z": 30,
      "name": "Rock_Rusty_Metal",
      "rotation": 13
    },
    {
      "x": -57,
      "y": 37,
      "z": 30,
      "name": "Rock_Rusty_Metal",
      "rotation": 13
    },
    {
      "x": -57,
      "y": 38,
      "z": 30,
      "name": "Rock_Rusty_Metal",
      "rotation": 13
    },
    {
      "x": -57,
      "y": 39,
      "z": 30,
      "name": "Rock_Dark_Rusty_Metal",
      "rotation": 13
    },
    {
      "x": -57,
      "y": 40,
      "z": 30,
      "name": "Rock_Rusty_Metal",
      "rotation": 13
    },
    {
      "x": -57,
      "y": 41,
      "z": 30,
      "name": "Rock_Rusty_Metal",
      "rotation": 13
    },
    {
      "x": -57,
      "y": 17,
      "z": 31,
      "name": "Rock_Rusty_Metal",
      "rotation": 6
    },
    {
      "x": -57,
      "y": 18,
      "z": 31,
      "name": "Rock_Rusty_Metal",
      "rotation": 6
    },
    {
      "x": -57,
      "y": 19,
      "z": 31,
      "name": "Rock_Dark_Rusty_Metal",
      "rotation": 6
    },
    {
      "x": -57,
      "y": 20,
      "z": 31,
      "name": "Rock_Rusty_Metal",
      "rotation": 6
    },
    {
      "x": -57,
      "y": 21,
      "z": 31,
      "name": "Rock_Rusty_Metal",
      "rotation": 6
    },
    {
      "x": -57,
      "y": 22,
      "z": 31,
      "name": "Rock_Rusty_Metal",
      "rotation": 6
    },
    {
      "x": -57,
      "y": 23,
      "z": 31,
      "name": "Rock_Dark_Rusty_Metal",
      "rotation": 6
    },
    {
      "x": -57,
      "y": 24,
      "z": 31,
      "name": "Rock_Dark_Rusty_Metal",
      "rotation": 6
    },
    {
      "x": -57,
      "y": 25,
      "z": 31,
      "name": "Rock_Dark_Rusty_Metal",
      "rotation": 6
    },
    {
      "x": -57,
      "y": 28,
      "z": 31,
      "name": "Rock_Dark_Rusty_Metal",
      "rotation": 6
    },
    {
      "x": -57,
      "y": 29,
      "z": 31,
      "name": "Rock_Rusty_Metal",
      "rotation": 6
    },
    {
      "x": -57,
      "y": 30,
      "z": 31,
      "name": "Rock_Dark_Rusty_Metal",
      "rotation": 6
    },
    {
      "x": -57,
      "y": 33,
      "z": 31,
      "name": "Rock_Dark_Rusty_Metal",
      "rotation": 6
    },
    {
      "x": -57,
      "y": 34,
      "z": 31,
      "name": "Rock_Dark_Rusty_Metal",
      "rotation": 6
    },
    {
      "x": -57,
      "y": 35,
      "z": 31,
      "name": "Rock_Dark_Rusty_Metal",
      "rotation": 6
    },
    {
      "x": -57,
      "y": 36,
      "z": 31,
      "name": "Rock_Rusty_Metal",
      "rotation": 6
    },
    {
      "x": -57,
      "y": 37,
      "z": 31,
      "name": "Rock_Rusty_Metal",
      "rotation": 6
    },
    {
      "x": -57,
      "y": 38,
      "z": 31,
      "name": "Rock_Rusty_Metal",
      "rotation": 6
    },
    {
      "x": -57,
      "y": 39,
      "z": 31,
      "name": "Rock_Dark_Rusty_Metal",
      "rotation": 6
    },
    {
      "x": -57,
      "y": 40,
      "z": 31,
      "name": "Rock_Rusty_Metal",
      "rotation": 6
    },
    {
      "x": -57,
      "y": 41,
      "z": 31,
      "name": "Rock_Rusty_Metal",
      "rotation": 6
    },
    {
      "x": -57,
      "y": 20,
      "z": 32,
      "name": "Rock_Rusty_Metal",
      "rotation": 6
    },
    {
      "x": -57,
      "y": 21,
      "z": 32,
      "name": "Rock_Rusty_Metal",
      "rotation": 6
    },
    {
      "x": -57,
      "y": 22,
      "z": 32,
      "name": "Rock_Rusty_Metal",
      "rotation": 6
    },
    {
      "x": -57,
      "y": 29,
      "z": 32,
      "name": "Rock_Rusty_Metal",
      "rotation": 6
    },
    {
      "x": -57,
      "y": 36,
      "z": 32,
      "name": "Rock_Rusty_Metal",
      "rotation": 6
    },
    {
      "x": -57,
      "y": 37,
      "z": 32,
      "name": "Rock_Rusty_Metal",
      "rotation": 6
    },
    {
      "x": -57,
      "y": 38,
      "z": 32,
      "name": "Rock_Rusty_Metal",
      "rotation": 6
    },
    {
      "x": -56,
      "y": 19,
      "z": 29,
      "name": "Rock_Rusty_Metal",
      "rotation": 13
    },
    {
      "x": -56,
      "y": 20,
      "z": 29,
      "name": "Rock_Rusty_Metal",
      "rotation": 13
    },
    {
      "x": -56,
      "y": 21,
      "z": 29,
      "name": "Rock_Rusty_Metal",
      "rotation": 13
    },
    {
      "x": -56,
      "y": 29,
      "z": 29,
      "name": "Rock_Rusty_Metal",
      "rotation": 13
    },
    {
      "x": -56,
      "y": 37,
      "z": 29,
      "name": "Rock_Rusty_Metal",
      "rotation": 13
    },
    {
      "x": -56,
      "y": 38,
      "z": 29,
      "name": "Rock_Rusty_Metal",
      "rotation": 13
    },
    {
      "x": -56,
      "y": 39,
      "z": 29,
      "name": "Rock_Rusty_Metal",
      "rotation": 13
    },
    {
      "x": -56,
      "y": 18,
      "z": 30,
      "name": "Rock_Dark_Rusty_Metal",
      "rotation": 13
    },
    {
      "x": -56,
      "y": 19,
      "z": 30,
      "name": "Rock_Rusty_Metal",
      "rotation": 13
    },
    {
      "x": -56,
      "y": 20,
      "z": 30,
      "name": "Rock_Rusty_Metal",
      "rotation": 13
    },
    {
      "x": -56,
      "y": 21,
      "z": 30,
      "name": "Rock_Rusty_Metal",
      "rotation": 13
    },
    {
      "x": -56,
      "y": 22,
      "z": 30,
      "name": "Rock_Dark_Rusty_Metal",
      "rotation": 13
    },
    {
      "x": -56,
      "y": 28,
      "z": 30,
      "name": "Rock_Dark_Rusty_Metal",
      "rotation": 13
    },
    {
      "x": -56,
      "y": 29,
      "z": 30,
      "name": "Rock_Rusty_Metal",
      "rotation": 13
    },
    {
      "x": -56,
      "y": 30,
      "z": 30,
      "name": "Rock_Dark_Rusty_Metal",
      "rotation": 13
    },
    {
      "x": -56,
      "y": 36,
      "z": 30,
      "name": "Rock_Dark_Rusty_Metal",
      "rotation": 13
    },
    {
      "x": -56,
      "y": 37,
      "z": 30,
      "name": "Rock_Rusty_Metal",
      "rotation": 13
    },
    {
      "x": -56,
      "y": 38,
      "z": 30,
      "name": "Rock_Rusty_Metal",
      "rotation": 13
    },
    {
      "x": -56,
      "y": 39,
      "z": 30,
      "name": "Rock_Rusty_Metal",
      "rotation": 13
    },
    {
      "x": -56,
      "y": 40,
      "z": 30,
      "name": "Rock_Dark_Rusty_Metal",
      "rotation": 13
    },
    {
      "x": -56,
      "y": 18,
      "z": 31,
      "name": "Rock_Dark_Rusty_Metal",
      "rotation": 6
    },
    {
      "x": -56,
      "y": 19,
      "z": 31,
      "name": "Rock_Rusty_Metal",
      "rotation": 6
    },
    {
      "x": -56,
      "y": 20,
      "z": 31,
      "name": "Rock_Rusty_Metal",
      "rotation": 6
    },
    {
      "x": -56,
      "y": 21,
      "z": 31,
      "name": "Rock_Rusty_Metal",
      "rotation": 6
    },
    {
      "x": -56,
      "y": 22,
      "z": 31,
      "name": "Rock_Dark_Rusty_Metal",
      "rotation": 6
    },
    {
      "x": -56,
      "y": 28,
      "z": 31,
      "name": "Rock_Dark_Rusty_Metal",
      "rotation": 6
    },
    {
      "x": -56,
      "y": 29,
      "z": 31,
      "name": "Rock_Rusty_Metal",
      "rotation": 6
    },
    {
      "x": -56,
      "y": 30,
      "z": 31,
      "name": "Rock_Dark_Rusty_Metal",
      "rotation": 6
    },
    {
      "x": -56,
      "y": 36,
      "z": 31,
      "name": "Rock_Dark_Rusty_Metal",
      "rotation": 6
    },
    {
      "x": -56,
      "y": 37,
      "z": 31,
      "name": "Rock_Rusty_Metal",
      "rotation": 6
    },
    {
      "x": -56,
      "y": 38,
      "z": 31,
      "name": "Rock_Rusty_Metal",
      "rotation": 6
    },
    {
      "x": -56,
      "y": 39,
      "z": 31,
      "name": "Rock_Rusty_Metal",
      "rotation": 6
    },
    {
      "x": -56,
      "y": 40,
      "z": 31,
      "name": "Rock_Dark_Rusty_Metal",
      "rotation": 6
    },
    {
      "x": -56,
      "y": 19,
      "z": 32,
      "name": "Rock_Rusty_Metal",
      "rotation": 6
    },
    {
      "x": -56,
      "y": 20,
      "z": 32,
      "name": "Rock_Rusty_Metal",
      "rotation": 6
    },
    {
      "x": -56,
      "y": 21,
      "z": 32,
      "name": "Rock_Rusty_Metal",
      "rotation": 6
    },
    {
      "x": -56,
      "y": 29,
      "z": 32,
      "name": "Rock_Rusty_Metal",
      "rotation": 6
    },
    {
      "x": -56,
      "y": 37,
      "z": 32,
      "name": "Rock_Rusty_Metal",
      "rotation": 6
    },
    {
      "x": -56,
      "y": 38,
      "z": 32,
      "name": "Rock_Rusty_Metal",
      "rotation": 6
    },
    {
      "x": -56,
      "y": 39,
      "z": 32,
      "name": "Rock_Rusty_Metal",
      "rotation": 6
    },
    {
      "x": -55,
      "y": 18,
      "z": 29,
      "name": "Rock_Rusty_Metal",
      "rotation": 13
    },
    {
      "x": -55,
      "y": 19,
      "z": 29,
      "name": "Rock_Rusty_Metal",
      "rotation": 13
    },
    {
      "x": -55,
      "y": 20,
      "z": 29,
      "name": "Rock_Rusty_Metal",
      "rotation": 13
    },
    {
      "x": -55,
      "y": 21,
      "z": 29,
      "name": "Rock_Rusty_Metal",
      "rotation": 13
    },
    {
      "x": -55,
      "y": 29,
      "z": 29,
      "name": "Rock_Rusty_Metal",
      "rotation": 13
    },
    {
      "x": -55,
      "y": 37,
      "z": 29,
      "name": "Rock_Rusty_Metal",
      "rotation": 13
    },
    {
      "x": -55,
      "y": 38,
      "z": 29,
      "name": "Rock_Rusty_Metal",
      "rotation": 13
    },
    {
      "x": -55,
      "y": 39,
      "z": 29,
      "name": "Rock_Rusty_Metal",
      "rotation": 13
    },
    {
      "x": -55,
      "y": 15,
      "z": 30,
      "name": "Rock_Rusty_Metal",
      "rotation": 13
    },
    {
      "x": -55,
      "y": 17,
      "z": 30,
      "name": "Rock_Dark_Rusty_Metal",
      "rotation": 13
    },
    {
      "x": -55,
      "y": 18,
      "z": 30,
      "name": "Rock_Rusty_Metal",
      "rotation": 13
    },
    {
      "x": -55,
      "y": 19,
      "z": 30,
      "name": "Rock_Rusty_Metal",
      "rotation": 13
    },
    {
      "x": -55,
      "y": 20,
      "z": 30,
      "name": "Rock_Rusty_Metal",
      "rotation": 13
    },
    {
      "x": -55,
      "y": 21,
      "z": 30,
      "name": "Rock_Rusty_Metal",
      "rotation": 13
    },
    {
      "x": -55,
      "y": 22,
      "z": 30,
      "name": "Rock_Dark_Rusty_Metal",
      "rotation": 13
    },
    {
      "x": -55,
      "y": 28,
      "z": 30,
      "name": "Rock_Dark_Rusty_Metal",
      "rotation": 13
    },
    {
      "x": -55,
      "y": 29,
      "z": 30,
      "name": "Rock_Rusty_Metal",
      "rotation": 13
    },
    {
      "x": -55,
      "y": 30,
      "z": 30,
      "name": "Rock_Dark_Rusty_Metal",
      "rotation": 13
    },
    {
      "x": -55,
      "y": 36,
      "z": 30,
      "name": "Rock_Dark_Rusty_Metal",
      "rotation": 13
    },
    {
      "x": -55,
      "y": 37,
      "z": 30,
      "name": "Rock_Rusty_Metal",
      "rotation": 13
    },
    {
      "x": -55,
      "y": 38,
      "z": 30,
      "name": "Rock_Rusty_Metal",
      "rotation": 13
    },
    {
      "x": -55,
      "y": 39,
      "z": 30,
      "name": "Rock_Rusty_Metal",
      "rotation": 13
    },
    {
      "x": -55,
      "y": 40,
      "z": 30,
      "name": "Rock_Dark_Rusty_Metal",
      "rotation": 13
    },
    {
      "x": -55,
      "y": 41,
      "z": 30,
      "name": "Rock_Dark_Rusty_Metal",
      "rotation": 13
    },
    {
      "x": -55,
      "y": 43,
      "z": 30,
      "name": "Rock_Rusty_Metal",
      "rotation": 13
    },
    {
      "x": -55,
      "y": 15,
      "z": 31,
      "name": "Rock_Rusty_Metal",
      "rotation": 6
    },
    {
      "x": -55,
      "y": 17,
      "z": 31,
      "name": "Rock_Dark_Rusty_Metal",
      "rotation": 6
    },
    {
      "x": -55,
      "y": 18,
      "z": 31,
      "name": "Rock_Rusty_Metal",
      "rotation": 6
    },
    {
      "x": -55,
      "y": 19,
      "z": 31,
      "name": "Rock_Rusty_Metal",
      "rotation": 6
    },
    {
      "x": -55,
      "y": 20,
      "z": 31,
      "name": "Rock_Rusty_Metal",
      "rotation": 6
    },
    {
      "x": -55,
      "y": 21,
      "z": 31,
      "name": "Rock_Rusty_Metal",
      "rotation": 6
    },
    {
      "x": -55,
      "y": 22,
      "z": 31,
      "name": "Rock_Dark_Rusty_Metal",
      "rotation": 6
    },
    {
      "x": -55,
      "y": 28,
      "z": 31,
      "name": "Rock_Dark_Rusty_Metal",
      "rotation": 6
    },
    {
      "x": -55,
      "y": 29,
      "z": 31,
      "name": "Rock_Rusty_Metal",
      "rotation": 6
    },
    {
      "x": -55,
      "y": 30,
      "z": 31,
      "name": "Rock_Dark_Rusty_Metal",
      "rotation": 6
    },
    {
      "x": -55,
      "y": 36,
      "z": 31,
      "name": "Rock_Dark_Rusty_Metal",
      "rotation": 6
    },
    {
      "x": -55,
      "y": 37,
      "z": 31,
      "name": "Rock_Rusty_Metal",
      "rotation": 6
    },
    {
      "x": -55,
      "y": 38,
      "z": 31,
      "name": "Rock_Rusty_Metal",
      "rotation": 6
    },
    {
      "x": -55,
      "y": 39,
      "z": 31,
      "name": "Rock_Rusty_Metal",
      "rotation": 6
    },
    {
      "x": -55,
      "y": 40,
      "z": 31,
      "name": "Rock_Rusty_Metal",
      "rotation": 6
    },
    {
      "x": -55,
      "y": 41,
      "z": 31,
      "name": "Rock_Dark_Rusty_Metal",
      "rotation": 6
    },
    {
      "x": -55,
      "y": 43,
      "z": 31,
      "name": "Rock_Rusty_Metal",
      "rotation": 6
    },
    {
      "x": -55,
      "y": 18,
      "z": 32,
      "name": "Rock_Rusty_Metal",
      "rotation": 6
    },
    {
      "x": -55,
      "y": 19,
      "z": 32,
      "name": "Rock_Rusty_Metal",
      "rotation": 6
    },
    {
      "x": -55,
      "y": 20,
      "z": 32,
      "name": "Rock_Rusty_Metal",
      "rotation": 6
    },
    {
      "x": -55,
      "y": 21,
      "z": 32,
      "name": "Rock_Rusty_Metal",
      "rotation": 6
    },
    {
      "x": -55,
      "y": 29,
      "z": 32,
      "name": "Rock_Rusty_Metal",
      "rotation": 6
    },
    {
      "x": -55,
      "y": 37,
      "z": 32,
      "name": "Rock_Rusty_Metal",
      "rotation": 6
    },
    {
      "x": -55,
      "y": 38,
      "z": 32,
      "name": "Rock_Rusty_Metal",
      "rotation": 6
    },
    {
      "x": -55,
      "y": 39,
      "z": 32,
      "name": "Rock_Rusty_Metal",
      "rotation": 6
    },
    {
      "x": -55,
      "y": 40,
      "z": 32,
      "name": "Rock_Rusty_Metal",
      "rotation": 6
    },
    {
      "x": -54,
      "y": 18,
      "z": 29,
      "name": "Rock_Rusty_Metal",
      "rotation": 13
    },
    {
      "x": -54,
      "y": 19,
      "z": 29,
      "name": "Rock_Rusty_Metal",
      "rotation": 13
    },
    {
      "x": -54,
      "y": 22,
      "z": 29,
      "name": "Rock_Rusty_Metal",
      "rotation": 13
    },
    {
      "x": -54,
      "y": 29,
      "z": 29,
      "name": "Rock_Rusty_Metal",
      "rotation": 13
    },
    {
      "x": -54,
      "y": 36,
      "z": 29,
      "name": "Rock_Rusty_Metal",
      "rotation": 13
    },
    {
      "x": -54,
      "y": 39,
      "z": 29,
      "name": "Rock_Rusty_Metal",
      "rotation": 13
    },
    {
      "x": -54,
      "y": 40,
      "z": 29,
      "name": "Rock_Rusty_Metal",
      "rotation": 13
    },
    {
      "x": -54,
      "y": 14,
      "z": 30,
      "name": "Rock_Rusty_Metal",
      "rotation": 13
    },
    {
      "x": -54,
      "y": 15,
      "z": 30,
      "name": "Rock_Rusty_Metal",
      "rotation": 13
    },
    {
      "x": -54,
      "y": 16,
      "z": 30,
      "name": "Rock_Rusty_Metal",
      "rotation": 13
    },
    {
      "x": -54,
      "y": 17,
      "z": 30,
      "name": "Rock_Dark_Rusty_Metal",
      "rotation": 13
    },
    {
      "x": -54,
      "y": 18,
      "z": 30,
      "name": "Rock_Rusty_Metal",
      "rotation": 13
    },
    {
      "x": -54,
      "y": 19,
      "z": 30,
      "name": "Rock_Rusty_Metal",
      "rotation": 13
    },
    {
      "x": -54,
      "y": 20,
      "z": 30,
      "name": "Rock_Dark_Rusty_Metal",
      "rotation": 13
    },
    {
      "x": -54,
      "y": 21,
      "z": 30,
      "name": "Rock_Dark_Rusty_Metal",
      "rotation": 13
    },
    {
      "x": -54,
      "y": 22,
      "z": 30,
      "name": "Rock_Rusty_Metal",
      "rotation": 13
    },
    {
      "x": -54,
      "y": 23,
      "z": 30,
      "name": "Rock_Dark_Rusty_Metal",
      "rotation": 13
    },
    {
      "x": -54,
      "y": 28,
      "z": 30,
      "name": "Rock_Dark_Rusty_Metal",
      "rotation": 13
    },
    {
      "x": -54,
      "y": 29,
      "z": 30,
      "name": "Rock_Rusty_Metal",
      "rotation": 13
    },
    {
      "x": -54,
      "y": 30,
      "z": 30,
      "name": "Rock_Dark_Rusty_Metal",
      "rotation": 13
    },
    {
      "x": -54,
      "y": 35,
      "z": 30,
      "name": "Rock_Dark_Rusty_Metal",
      "rotation": 13
    },
    {
      "x": -54,
      "y": 36,
      "z": 30,
      "name": "Rock_Rusty_Metal",
      "rotation": 13
    },
    {
      "x": -54,
      "y": 37,
      "z": 30,
      "name": "Rock_Dark_Rusty_Metal",
      "rotation": 13
    },
    {
      "x": -54,
      "y": 38,
      "z": 30,
      "name": "Rock_Dark_Rusty_Metal",
      "rotation": 13
    },
    {
      "x": -54,
      "y": 39,
      "z": 30,
      "name": "Rock_Rusty_Metal",
      "rotation": 13
    },
    {
      "x": -54,
      "y": 40,
      "z": 30,
      "name": "Rock_Rusty_Metal",
      "rotation": 13
    },
    {
      "x": -54,
      "y": 41,
      "z": 30,
      "name": "Rock_Dark_Rusty_Metal",
      "rotation": 13
    },
    {
      "x": -54,
      "y": 42,
      "z": 30,
      "name": "Rock_Rusty_Metal",
      "rotation": 13
    },
    {
      "x": -54,
      "y": 43,
      "z": 30,
      "name": "Rock_Rusty_Metal",
      "rotation": 13
    },
    {
      "x": -54,
      "y": 44,
      "z": 30,
      "name": "Rock_Rusty_Metal",
      "rotation": 13
    },
    {
      "x": -54,
      "y": 14,
      "z": 31,
      "name": "Rock_Rusty_Metal",
      "rotation": 6
    },
    {
      "x": -54,
      "y": 15,
      "z": 31,
      "name": "Rock_Rusty_Metal",
      "rotation": 6
    },
    {
      "x": -54,
      "y": 16,
      "z": 31,
      "name": "Rock_Rusty_Metal",
      "rotation": 6
    },
    {
      "x": -54,
      "y": 17,
      "z": 31,
      "name": "Rock_Dark_Rusty_Metal",
      "rotation": 6
    },
    {
      "x": -54,
      "y": 18,
      "z": 31,
      "name": "Rock_Rusty_Metal",
      "rotation": 6
    },
    {
      "x": -54,
      "y": 19,
      "z": 31,
      "name": "Rock_Rusty_Metal",
      "rotation": 6
    },
    {
      "x": -54,
      "y": 20,
      "z": 31,
      "name": "Rock_Dark_Rusty_Metal",
      "rotation": 6
    },
    {
      "x": -54,
      "y": 21,
      "z": 31,
      "name": "Rock_Dark_Rusty_Metal",
      "rotation": 6
    },
    {
      "x": -54,
      "y": 22,
      "z": 31,
      "name": "Rock_Rusty_Metal",
      "rotation": 6
    },
    {
      "x": -54,
      "y": 23,
      "z": 31,
      "name": "Rock_Dark_Rusty_Metal",
      "rotation": 6
    },
    {
      "x": -54,
      "y": 28,
      "z": 31,
      "name": "Rock_Dark_Rusty_Metal",
      "rotation": 6
    },
    {
      "x": -54,
      "y": 29,
      "z": 31,
      "name": "Rock_Rusty_Metal",
      "rotation": 6
    },
    {
      "x": -54,
      "y": 30,
      "z": 31,
      "name": "Rock_Dark_Rusty_Metal",
      "rotation": 6
    },
    {
      "x": -54,
      "y": 35,
      "z": 31,
      "name": "Rock_Dark_Rusty_Metal",
      "rotation": 6
    },
    {
      "x": -54,
      "y": 36,
      "z": 31,
      "name": "Rock_Rusty_Metal",
      "rotation": 6
    },
    {
      "x": -54,
      "y": 37,
      "z": 31,
      "name": "Rock_Dark_Rusty_Metal",
      "rotation": 6
    },
    {
      "x": -54,
      "y": 38,
      "z": 31,
      "name": "Rock_Dark_Rusty_Metal",
      "rotation": 6
    },
    {
      "x": -54,
      "y": 39,
      "z": 31,
      "name": "Rock_Rusty_Metal",
      "rotation": 6
    },
    {
      "x": -54,
      "y": 40,
      "z": 31,
      "name": "Rock_Rusty_Metal",
      "rotation": 6
    },
    {
      "x": -54,
      "y": 41,
      "z": 31,
      "name": "Rock_Dark_Rusty_Metal",
      "rotation": 6
    },
    {
      "x": -54,
      "y": 42,
      "z": 31,
      "name": "Rock_Rusty_Metal",
      "rotation": 6
    },
    {
      "x": -54,
      "y": 43,
      "z": 31,
      "name": "Rock_Rusty_Metal",
      "rotation": 6
    },
    {
      "x": -54,
      "y": 44,
      "z": 31,
      "name": "Rock_Rusty_Metal",
      "rotation": 6
    },
    {
      "x": -54,
      "y": 18,
      "z": 32,
      "name": "Rock_Rusty_Metal",
      "rotation": 6
    },
    {
      "x": -54,
      "y": 19,
      "z": 32,
      "name": "Rock_Rusty_Metal",
      "rotation": 6
    },
    {
      "x": -54,
      "y": 22,
      "z": 32,
      "name": "Rock_Rusty_Metal",
      "rotation": 6
    },
    {
      "x": -54,
      "y": 29,
      "z": 32,
      "name": "Rock_Rusty_Metal",
      "rotation": 6
    },
    {
      "x": -54,
      "y": 36,
      "z": 32,
      "name": "Rock_Rusty_Metal",
      "rotation": 6
    },
    {
      "x": -54,
      "y": 39,
      "z": 32,
      "name": "Rock_Rusty_Metal",
      "rotation": 6
    },
    {
      "x": -54,
      "y": 40,
      "z": 32,
      "name": "Rock_Rusty_Metal",
      "rotation": 6
    },
    {
      "x": -53,
      "y": 17,
      "z": 29,
      "name": "Rock_Rusty_Metal",
      "rotation": 13
    },
    {
      "x": -53,
      "y": 18,
      "z": 29,
      "name": "Rock_Rusty_Metal",
      "rotation": 13
    },
    {
      "x": -53,
      "y": 23,
      "z": 29,
      "name": "Rock_Rusty_Metal",
      "rotation": 13
    },
    {
      "x": -53,
      "y": 29,
      "z": 29,
      "name": "Rock_Rusty_Metal",
      "rotation": 13
    },
    {
      "x": -53,
      "y": 35,
      "z": 29,
      "name": "Rock_Rusty_Metal",
      "rotation": 13
    },
    {
      "x": -53,
      "y": 40,
      "z": 29,
      "name": "Rock_Rusty_Metal",
      "rotation": 13
    },
    {
      "x": -53,
      "y": 41,
      "z": 29,
      "name": "Rock_Rusty_Metal",
      "rotation": 13
    },
    {
      "x": -53,
      "y": 14,
      "z": 30,
      "name": "Rock_Rusty_Metal",
      "rotation": 13
    },
    {
      "x": -53,
      "y": 15,
      "z": 30,
      "name": "Rock_Rusty_Metal",
      "rotation": 13
    },
    {
      "x": -53,
      "y": 16,
      "z": 30,
      "name": "Rock_Dark_Rusty_Metal",
      "rotation": 13
    },
    {
      "x": -53,
      "y": 17,
      "z": 30,
      "name": "Rock_Rusty_Metal",
      "rotation": 13
    },
    {
      "x": -53,
      "y": 18,
      "z": 30,
      "name": "Rock_Rusty_Metal",
      "rotation": 13
    },
    {
      "x": -53,
      "y": 19,
      "z": 30,
      "name": "Rock_Dark_Rusty_Metal",
      "rotation": 13
    },
    {
      "x": -53,
      "y": 22,
      "z": 30,
      "name": "Rock_Dark_Rusty_Metal",
      "rotation": 13
    },
    {
      "x": -53,
      "y": 23,
      "z": 30,
      "name": "Rock_Rusty_Metal",
      "rotation": 13
    },
    {
      "x": -53,
      "y": 24,
      "z": 30,
      "name": "Rock_Dark_Rusty_Metal",
      "rotation": 13
    },
    {
      "x": -53,
      "y": 28,
      "z": 30,
      "name": "Rock_Dark_Rusty_Metal",
      "rotation": 13
    },
    {
      "x": -53,
      "y": 29,
      "z": 30,
      "name": "Rock_Rusty_Metal",
      "rotation": 13
    },
    {
      "x": -53,
      "y": 30,
      "z": 30,
      "name": "Rock_Dark_Rusty_Metal",
      "rotation": 13
    },
    {
      "x": -53,
      "y": 34,
      "z": 30,
      "name": "Rock_Dark_Rusty_Metal",
      "rotation": 13
    },
    {
      "x": -53,
      "y": 35,
      "z": 30,
      "name": "Rock_Rusty_Metal",
      "rotation": 13
    },
    {
      "x": -53,
      "y": 36,
      "z": 30,
      "name": "Rock_Dark_Rusty_Metal",
      "rotation": 13
    },
    {
      "x": -53,
      "y": 39,
      "z": 30,
      "name": "Rock_Dark_Rusty_Metal",
      "rotation": 13
    },
    {
      "x": -53,
      "y": 40,
      "z": 30,
      "name": "Rock_Rusty_Metal",
      "rotation": 13
    },
    {
      "x": -53,
      "y": 41,
      "z": 30,
      "name": "Rock_Rusty_Metal",
      "rotation": 13
    },
    {
      "x": -53,
      "y": 42,
      "z": 30,
      "name": "Rock_Dark_Rusty_Metal",
      "rotation": 13
    },
    {
      "x": -53,
      "y": 43,
      "z": 30,
      "name": "Rock_Rusty_Metal",
      "rotation": 13
    },
    {
      "x": -53,
      "y": 44,
      "z": 30,
      "name": "Rock_Rusty_Metal",
      "rotation": 13
    },
    {
      "x": -53,
      "y": 14,
      "z": 31,
      "name": "Rock_Rusty_Metal",
      "rotation": 6
    },
    {
      "x": -53,
      "y": 15,
      "z": 31,
      "name": "Rock_Rusty_Metal",
      "rotation": 6
    },
    {
      "x": -53,
      "y": 16,
      "z": 31,
      "name": "Rock_Dark_Rusty_Metal",
      "rotation": 6
    },
    {
      "x": -53,
      "y": 17,
      "z": 31,
      "name": "Rock_Rusty_Metal",
      "rotation": 6
    },
    {
      "x": -53,
      "y": 18,
      "z": 31,
      "name": "Rock_Rusty_Metal",
      "rotation": 6
    },
    {
      "x": -53,
      "y": 19,
      "z": 31,
      "name": "Rock_Dark_Rusty_Metal",
      "rotation": 6
    },
    {
      "x": -53,
      "y": 22,
      "z": 31,
      "name": "Rock_Dark_Rusty_Metal",
      "rotation": 6
    },
    {
      "x": -53,
      "y": 23,
      "z": 31,
      "name": "Rock_Rusty_Metal",
      "rotation": 6
    },
    {
      "x": -53,
      "y": 24,
      "z": 31,
      "name": "Rock_Dark_Rusty_Metal",
      "rotation": 6
    },
    {
      "x": -53,
      "y": 28,
      "z": 31,
      "name": "Rock_Dark_Rusty_Metal",
      "rotation": 6
    },
    {
      "x": -53,
      "y": 29,
      "z": 31,
      "name": "Rock_Rusty_Metal",
      "rotation": 6
    },
    {
      "x": -53,
      "y": 30,
      "z": 31,
      "name": "Rock_Dark_Rusty_Metal",
      "rotation": 6
    },
    {
      "x": -53,
      "y": 34,
      "z": 31,
      "name": "Rock_Dark_Rusty_Metal",
      "rotation": 6
    },
    {
      "x": -53,
      "y": 35,
      "z": 31,
      "name": "Rock_Rusty_Metal",
      "rotation": 6
    },
    {
      "x": -53,
      "y": 36,
      "z": 31,
      "name": "Rock_Dark_Rusty_Metal",
      "rotation": 6
    },
    {
      "x": -53,
      "y": 39,
      "z": 31,
      "name": "Rock_Dark_Rusty_Metal",
      "rotation": 6
    },
    {
      "x": -53,
      "y": 40,
      "z": 31,
      "name": "Rock_Rusty_Metal",
      "rotation": 6
    },
    {
      "x": -53,
      "y": 41,
      "z": 31,
      "name": "Rock_Rusty_Metal",
      "rotation": 6
    },
    {
      "x": -53,
      "y": 42,
      "z": 31,
      "name": "Rock_Dark_Rusty_Metal",
      "rotation": 6
    },
    {
      "x": -53,
      "y": 43,
      "z": 31,
      "name": "Rock_Rusty_Metal",
      "rotation": 6
    },
    {
      "x": -53,
      "y": 44,
      "z": 31,
      "name": "Rock_Rusty_Metal",
      "rotation": 6
    },
    {
      "x": -53,
      "y": 17,
      "z": 32,
      "name": "Rock_Rusty_Metal",
      "rotation": 6
    },
    {
      "x": -53,
      "y": 18,
      "z": 32,
      "name": "Rock_Rusty_Metal",
      "rotation": 6
    },
    {
      "x": -53,
      "y": 23,
      "z": 32,
      "name": "Rock_Rusty_Metal",
      "rotation": 6
    },
    {
      "x": -53,
      "y": 29,
      "z": 32,
      "name": "Rock_Rusty_Metal",
      "rotation": 6
    },
    {
      "x": -53,
      "y": 35,
      "z": 32,
      "name": "Rock_Rusty_Metal",
      "rotation": 6
    },
    {
      "x": -53,
      "y": 40,
      "z": 32,
      "name": "Rock_Rusty_Metal",
      "rotation": 6
    },
    {
      "x": -53,
      "y": 41,
      "z": 32,
      "name": "Rock_Rusty_Metal",
      "rotation": 6
    },
    {
      "x": -52,
      "y": 17,
      "z": 29,
      "name": "Rock_Rusty_Metal",
      "rotation": 13
    },
    {
      "x": -52,
      "y": 18,
      "z": 29,
      "name": "Rock_Rusty_Metal",
      "rotation": 13
    },
    {
      "x": -52,
      "y": 24,
      "z": 29,
      "name": "Rock_Rusty_Metal",
      "rotation": 13
    },
    {
      "x": -52,
      "y": 29,
      "z": 29,
      "name": "Rock_Rusty_Metal",
      "rotation": 13
    },
    {
      "x": -52,
      "y": 34,
      "z": 29,
      "name": "Rock_Rusty_Metal",
      "rotation": 13
    },
    {
      "x": -52,
      "y": 40,
      "z": 29,
      "name": "Rock_Rusty_Metal",
      "rotation": 13
    },
    {
      "x": -52,
      "y": 41,
      "z": 29,
      "name": "Rock_Rusty_Metal",
      "rotation": 13
    },
    {
      "x": -52,
      "y": 15,
      "z": 30,
      "name": "Rock_Rusty_Metal",
      "rotation": 13
    },
    {
      "x": -52,
      "y": 16,
      "z": 30,
      "name": "Rock_Dark_Rusty_Metal",
      "rotation": 13
    },
    {
      "x": -52,
      "y": 17,
      "z": 30,
      "name": "Rock_Rusty_Metal",
      "rotation": 13
    },
    {
      "x": -52,
      "y": 18,
      "z": 30,
      "name": "Rock_Rusty_Metal",
      "rotation": 13
    },
    {
      "x": -52,
      "y": 19,
      "z": 30,
      "name": "Rock_Dark_Rusty_Metal",
      "rotation": 13
    },
    {
      "x": -52,
      "y": 23,
      "z": 30,
      "name": "Rock_Dark_Rusty_Metal",
      "rotation": 13
    },
    {
      "x": -52,
      "y": 24,
      "z": 30,
      "name": "Rock_Rusty_Metal",
      "rotation": 13
    },
    {
      "x": -52,
      "y": 25,
      "z": 30,
      "name": "Rock_Dark_Rusty_Metal",
      "rotation": 13
    },
    {
      "x": -52,
      "y": 28,
      "z": 30,
      "name": "Rock_Dark_Rusty_Metal",
      "rotation": 13
    },
    {
      "x": -52,
      "y": 29,
      "z": 30,
      "name": "Rock_Rusty_Metal",
      "rotation": 13
    },
    {
      "x": -52,
      "y": 30,
      "z": 30,
      "name": "Rock_Dark_Rusty_Metal",
      "rotation": 13
    },
    {
      "x": -52,
      "y": 33,
      "z": 30,
      "name": "Rock_Dark_Rusty_Metal",
      "rotation": 13
    },
    {
      "x": -52,
      "y": 34,
      "z": 30,
      "name": "Rock_Rusty_Metal",
      "rotation": 13
    },
    {
      "x": -52,
      "y": 35,
      "z": 30,
      "name": "Rock_Dark_Rusty_Metal",
      "rotation": 13
    },
    {
      "x": -52,
      "y": 39,
      "z": 30,
      "name": "Rock_Dark_Rusty_Metal",
      "rotation": 13
    },
    {
      "x": -52,
      "y": 40,
      "z": 30,
      "name": "Rock_Rusty_Metal",
      "rotation": 13
    },
    {
      "x": -52,
      "y": 41,
      "z": 30,
      "name": "Rock_Rusty_Metal",
      "rotation": 13
    },
    {
      "x": -52,
      "y": 42,
      "z": 30,
      "name": "Rock_Dark_Rusty_Metal",
      "rotation": 13
    },
    {
      "x": -52,
      "y": 43,
      "z": 30,
      "name": "Rock_Rusty_Metal",
      "rotation": 13
    },
    {
      "x": -52,
      "y": 15,
      "z": 31,
      "name": "Rock_Rusty_Metal",
      "rotation": 6
    },
    {
      "x": -52,
      "y": 16,
      "z": 31,
      "name": "Rock_Dark_Rusty_Metal",
      "rotation": 6
    },
    {
      "x": -52,
      "y": 17,
      "z": 31,
      "name": "Rock_Rusty_Metal",
      "rotation": 6
    },
    {
      "x": -52,
      "y": 18,
      "z": 31,
      "name": "Rock_Rusty_Metal",
      "rotation": 6
    },
    {
      "x": -52,
      "y": 19,
      "z": 31,
      "name": "Rock_Dark_Rusty_Metal",
      "rotation": 6
    },
    {
      "x": -52,
      "y": 23,
      "z": 31,
      "name": "Rock_Dark_Rusty_Metal",
      "rotation": 6
    },
    {
      "x": -52,
      "y": 24,
      "z": 31,
      "name": "Rock_Rusty_Metal",
      "rotation": 6
    },
    {
      "x": -52,
      "y": 25,
      "z": 31,
      "name": "Rock_Dark_Rusty_Metal",
      "rotation": 6
    },
    {
      "x": -52,
      "y": 28,
      "z": 31,
      "name": "Rock_Dark_Rusty_Metal",
      "rotation": 6
    },
    {
      "x": -52,
      "y": 29,
      "z": 31,
      "name": "Rock_Rusty_Metal",
      "rotation": 6
    },
    {
      "x": -52,
      "y": 30,
      "z": 31,
      "name": "Rock_Dark_Rusty_Metal",
      "rotation": 6
    },
    {
      "x": -52,
      "y": 33,
      "z": 31,
      "name": "Rock_Dark_Rusty_Metal",
      "rotation": 6
    },
    {
      "x": -52,
      "y": 34,
      "z": 31,
      "name": "Rock_Rusty_Metal",
      "rotation": 6
    },
    {
      "x": -52,
      "y": 35,
      "z": 31,
      "name": "Rock_Dark_Rusty_Metal",
      "rotation": 6
    },
    {
      "x": -52,
      "y": 39,
      "z": 31,
      "name": "Rock_Dark_Rusty_Metal",
      "rotation": 6
    },
    {
      "x": -52,
      "y": 40,
      "z": 31,
      "name": "Rock_Rusty_Metal",
      "rotation": 6
    },
    {
      "x": -52,
      "y": 41,
      "z": 31,
      "name": "Rock_Rusty_Metal",
      "rotation": 6
    },
    {
      "x": -52,
      "y": 42,
      "z": 31,
      "name": "Rock_Dark_Rusty_Metal",
      "rotation": 6
    },
    {
      "x": -52,
      "y": 43,
      "z": 31,
      "name": "Rock_Rusty_Metal",
      "rotation": 6
    },
    {
      "x": -52,
      "y": 17,
      "z": 32,
      "name": "Rock_Rusty_Metal",
      "rotation": 6
    },
    {
      "x": -52,
      "y": 18,
      "z": 32,
      "name": "Rock_Rusty_Metal",
      "rotation": 6
    },
    {
      "x": -52,
      "y": 24,
      "z": 32,
      "name": "Rock_Rusty_Metal",
      "rotation": 6
    },
    {
      "x": -52,
      "y": 29,
      "z": 32,
      "name": "Rock_Rusty_Metal",
      "rotation": 6
    },
    {
      "x": -52,
      "y": 34,
      "z": 32,
      "name": "Rock_Rusty_Metal",
      "rotation": 6
    },
    {
      "x": -52,
      "y": 40,
      "z": 32,
      "name": "Rock_Rusty_Metal",
      "rotation": 6
    },
    {
      "x": -52,
      "y": 41,
      "z": 32,
      "name": "Rock_Rusty_Metal",
      "rotation": 6
    },
    {
      "x": -51,
      "y": 17,
      "z": 29,
      "name": "Rock_Rusty_Metal",
      "rotation": 13
    },
    {
      "x": -51,
      "y": 18,
      "z": 29,
      "name": "Rock_Rusty_Metal",
      "rotation": 13
    },
    {
      "x": -51,
      "y": 25,
      "z": 29,
      "name": "Rock_Rusty_Metal",
      "rotation": 13
    },
    {
      "x": -51,
      "y": 33,
      "z": 29,
      "name": "Rock_Rusty_Metal",
      "rotation": 13
    },
    {
      "x": -51,
      "y": 40,
      "z": 29,
      "name": "Rock_Rusty_Metal",
      "rotation": 13
    },
    {
      "x": -51,
      "y": 41,
      "z": 29,
      "name": "Rock_Rusty_Metal",
      "rotation": 13
    },
    {
      "x": -51,
      "y": 16,
      "z": 30,
      "name": "Rock_Dark_Rusty_Metal",
      "rotation": 13
    },
    {
      "x": -51,
      "y": 17,
      "z": 30,
      "name": "Rock_Rusty_Metal",
      "rotation": 13
    },
    {
      "x": -51,
      "y": 18,
      "z": 30,
      "name": "Rock_Rusty_Metal",
      "rotation": 13
    },
    {
      "x": -51,
      "y": 19,
      "z": 30,
      "name": "Rock_Dark_Rusty_Metal",
      "rotation": 13
    },
    {
      "x": -51,
      "y": 24,
      "z": 30,
      "name": "Rock_Dark_Rusty_Metal",
      "rotation": 13
    },
    {
      "x": -51,
      "y": 25,
      "z": 30,
      "name": "Rock_Rusty_Metal",
      "rotation": 13
    },
    {
      "x": -51,
      "y": 26,
      "z": 30,
      "name": "Rock_Dark_Rusty_Metal",
      "rotation": 13
    },
    {
      "x": -51,
      "y": 28,
      "z": 30,
      "name": "Rock_Bronze_Metal",
      "rotation": 13
    },
    {
      "x": -51,
      "y": 29,
      "z": 30,
      "name": "Rock_Bronze_Metal",
      "rotation": 13
    },
    {
      "x": -51,
      "y": 30,
      "z": 30,
      "name": "Rock_Bronze_Metal",
      "rotation": 13
    },
    {
      "x": -51,
      "y": 32,
      "z": 30,
      "name": "Rock_Dark_Rusty_Metal",
      "rotation": 13
    },
    {
      "x": -51,
      "y": 33,
      "z": 30,
      "name": "Rock_Rusty_Metal",
      "rotation": 13
    },
    {
      "x": -51,
      "y": 34,
      "z": 30,
      "name": "Rock_Dark_Rusty_Metal",
      "rotation": 13
    },
    {
      "x": -51,
      "y": 39,
      "z": 30,
      "name": "Rock_Dark_Rusty_Metal",
      "rotation": 13
    },
    {
      "x": -51,
      "y": 40,
      "z": 30,
      "name": "Rock_Rusty_Metal",
      "rotation": 13
    },
    {
      "x": -51,
      "y": 41,
      "z": 30,
      "name": "Rock_Rusty_Metal",
      "rotation": 13
    },
    {
      "x": -51,
      "y": 42,
      "z": 30,
      "name": "Rock_Dark_Rusty_Metal",
      "rotation": 13
    },
    {
      "x": -51,
      "y": 16,
      "z": 31,
      "name": "Rock_Dark_Rusty_Metal",
      "rotation": 6
    },
    {
      "x": -51,
      "y": 17,
      "z": 31,
      "name": "Rock_Rusty_Metal",
      "rotation": 6
    },
    {
      "x": -51,
      "y": 18,
      "z": 31,
      "name": "Rock_Rusty_Metal",
      "rotation": 6
    },
    {
      "x": -51,
      "y": 19,
      "z": 31,
      "name": "Rock_Dark_Rusty_Metal",
      "rotation": 6
    },
    {
      "x": -51,
      "y": 24,
      "z": 31,
      "name": "Rock_Dark_Rusty_Metal",
      "rotation": 6
    },
    {
      "x": -51,
      "y": 25,
      "z": 31,
      "name": "Rock_Rusty_Metal",
      "rotation": 6
    },
    {
      "x": -51,
      "y": 26,
      "z": 31,
      "name": "Rock_Dark_Rusty_Metal",
      "rotation": 6
    },
    {
      "x": -51,
      "y": 28,
      "z": 31,
      "name": "Rock_Bronze_Metal",
      "rotation": 6
    },
    {
      "x": -51,
      "y": 29,
      "z": 31,
      "name": "Rock_Bronze_Metal",
      "rotation": 6
    },
    {
      "x": -51,
      "y": 30,
      "z": 31,
      "name": "Rock_Bronze_Metal",
      "rotation": 6
    },
    {
      "x": -51,
      "y": 32,
      "z": 31,
      "name": "Rock_Dark_Rusty_Metal",
      "rotation": 6
    },
    {
      "x": -51,
      "y": 33,
      "z": 31,
      "name": "Rock_Rusty_Metal",
      "rotation": 6
    },
    {
      "x": -51,
      "y": 34,
      "z": 31,
      "name": "Rock_Dark_Rusty_Metal",
      "rotation": 6
    },
    {
      "x": -51,
      "y": 39,
      "z": 31,
      "name": "Rock_Dark_Rusty_Metal",
      "rotation": 6
    },
    {
      "x": -51,
      "y": 40,
      "z": 31,
      "name": "Rock_Rusty_Metal",
      "rotation": 6
    },
    {
      "x": -51,
      "y": 41,
      "z": 31,
      "name": "Rock_Rusty_Metal",
      "rotation": 6
    },
    {
      "x": -51,
      "y": 42,
      "z": 31,
      "name": "Rock_Dark_Rusty_Metal",
      "rotation": 6
    },
    {
      "x": -51,
      "y": 17,
      "z": 32,
      "name": "Rock_Rusty_Metal",
      "rotation": 6
    },
    {
      "x": -51,
      "y": 18,
      "z": 32,
      "name": "Rock_Rusty_Metal",
      "rotation": 6
    },
    {
      "x": -51,
      "y": 25,
      "z": 32,
      "name": "Rock_Rusty_Metal",
      "rotation": 6
    },
    {
      "x": -51,
      "y": 33,
      "z": 32,
      "name": "Rock_Rusty_Metal",
      "rotation": 6
    },
    {
      "x": -51,
      "y": 40,
      "z": 32,
      "name": "Rock_Rusty_Metal",
      "rotation": 6
    },
    {
      "x": -51,
      "y": 41,
      "z": 32,
      "name": "Rock_Rusty_Metal",
      "rotation": 6
    },
    {
      "x": -50,
      "y": 16,
      "z": 29,
      "name": "Rock_Rusty_Metal",
      "rotation": 13
    },
    {
      "x": -50,
      "y": 17,
      "z": 29,
      "name": "Rock_Rusty_Metal",
      "rotation": 13
    },
    {
      "x": -50,
      "y": 41,
      "z": 29,
      "name": "Rock_Rusty_Metal",
      "rotation": 13
    },
    {
      "x": -50,
      "y": 42,
      "z": 29,
      "name": "Rock_Rusty_Metal",
      "rotation": 13
    },
    {
      "x": -50,
      "y": 14,
      "z": 30,
      "name": "Rock_Rusty_Metal",
      "rotation": 13
    },
    {
      "x": -50,
      "y": 15,
      "z": 30,
      "name": "Rock_Dark_Rusty_Metal",
      "rotation": 13
    },
    {
      "x": -50,
      "y": 16,
      "z": 30,
      "name": "Rock_Rusty_Metal",
      "rotation": 13
    },
    {
      "x": -50,
      "y": 17,
      "z": 30,
      "name": "Rock_Rusty_Metal",
      "rotation": 13
    },
    {
      "x": -50,
      "y": 18,
      "z": 30,
      "name": "Rock_Dark_Rusty_Metal",
      "rotation": 13
    },
    {
      "x": -50,
      "y": 25,
      "z": 30,
      "name": "Rock_Dark_Rusty_Metal",
      "rotation": 13
    },
    {
      "x": -50,
      "y": 26,
      "z": 30,
      "name": "Rock_Bronze_Metal",
      "rotation": 13
    },
    {
      "x": -50,
      "y": 27,
      "z": 30,
      "name": "Rock_Bronze_Metal",
      "rotation": 13
    },
    {
      "x": -50,
      "y": 28,
      "z": 30,
      "name": "Rock_Bronze_Metal",
      "rotation": 13
    },
    {
      "x": -50,
      "y": 29,
      "z": 30,
      "name": "Rock_Bronze_Metal",
      "rotation": 13
    },
    {
      "x": -50,
      "y": 30,
      "z": 30,
      "name": "Rock_Bronze_Metal",
      "rotation": 13
    },
    {
      "x": -50,
      "y": 31,
      "z": 30,
      "name": "Rock_Bronze_Metal",
      "rotation": 13
    },
    {
      "x": -50,
      "y": 32,
      "z": 30,
      "name": "Rock_Bronze_Metal",
      "rotation": 13
    },
    {
      "x": -50,
      "y": 33,
      "z": 30,
      "name": "Rock_Dark_Rusty_Metal",
      "rotation": 13
    },
    {
      "x": -50,
      "y": 40,
      "z": 30,
      "name": "Rock_Dark_Rusty_Metal",
      "rotation": 13
    },
    {
      "x": -50,
      "y": 41,
      "z": 30,
      "name": "Rock_Rusty_Metal",
      "rotation": 13
    },
    {
      "x": -50,
      "y": 42,
      "z": 30,
      "name": "Rock_Rusty_Metal",
      "rotation": 13
    },
    {
      "x": -50,
      "y": 43,
      "z": 30,
      "name": "Rock_Dark_Rusty_Metal",
      "rotation": 13
    },
    {
      "x": -50,
      "y": 44,
      "z": 30,
      "name": "Rock_Rusty_Metal",
      "rotation": 13
    },
    {
      "x": -50,
      "y": 14,
      "z": 31,
      "name": "Rock_Rusty_Metal",
      "rotation": 6
    },
    {
      "x": -50,
      "y": 15,
      "z": 31,
      "name": "Rock_Dark_Rusty_Metal",
      "rotation": 6
    },
    {
      "x": -50,
      "y": 16,
      "z": 31,
      "name": "Rock_Rusty_Metal",
      "rotation": 6
    },
    {
      "x": -50,
      "y": 17,
      "z": 31,
      "name": "Rock_Rusty_Metal",
      "rotation": 6
    },
    {
      "x": -50,
      "y": 18,
      "z": 31,
      "name": "Rock_Dark_Rusty_Metal",
      "rotation": 6
    },
    {
      "x": -50,
      "y": 25,
      "z": 31,
      "name": "Rock_Dark_Rusty_Metal",
      "rotation": 6
    },
    {
      "x": -50,
      "y": 26,
      "z": 31,
      "name": "Rock_Bronze_Metal",
      "rotation": 6
    },
    {
      "x": -50,
      "y": 27,
      "z": 31,
      "name": "Rock_Bronze_Metal",
      "rotation": 6
    },
    {
      "x": -50,
      "y": 28,
      "z": 31,
      "name": "Rock_Bronze_Metal",
      "rotation": 6
    },
    {
      "x": -50,
      "y": 29,
      "z": 31,
      "name": "Rock_Bronze_Metal",
      "rotation": 6
    },
    {
      "x": -50,
      "y": 30,
      "z": 31,
      "name": "Rock_Bronze_Metal",
      "rotation": 6
    },
    {
      "x": -50,
      "y": 31,
      "z": 31,
      "name": "Rock_Bronze_Metal",
      "rotation": 6
    },
    {
      "x": -50,
      "y": 32,
      "z": 31,
      "name": "Rock_Bronze_Metal",
      "rotation": 6
    },
    {
      "x": -50,
      "y": 33,
      "z": 31,
      "name": "Rock_Dark_Rusty_Metal",
      "rotation": 6
    },
    {
      "x": -50,
      "y": 40,
      "z": 31,
      "name": "Rock_Dark_Rusty_Metal",
      "rotation": 6
    },
    {
      "x": -50,
      "y": 41,
      "z": 31,
      "name": "Rock_Rusty_Metal",
      "rotation": 6
    },
    {
      "x": -50,
      "y": 42,
      "z": 31,
      "name": "Rock_Rusty_Metal",
      "rotation": 6
    },
    {
      "x": -50,
      "y": 43,
      "z": 31,
      "name": "Rock_Dark_Rusty_Metal",
      "rotation": 6
    },
    {
      "x": -50,
      "y": 44,
      "z": 31,
      "name": "Rock_Rusty_Metal",
      "rotation": 6
    },
    {
      "x": -50,
      "y": 16,
      "z": 32,
      "name": "Rock_Rusty_Metal",
      "rotation": 6
    },
    {
      "x": -50,
      "y": 17,
      "z": 32,
      "name": "Rock_Rusty_Metal",
      "rotation": 6
    },
    {
      "x": -50,
      "y": 41,
      "z": 32,
      "name": "Rock_Rusty_Metal",
      "rotation": 6
    },
    {
      "x": -50,
      "y": 42,
      "z": 32,
      "name": "Rock_Rusty_Metal",
      "rotation": 6
    },
    {
      "x": -49,
      "y": 16,
      "z": 29,
      "name": "Rock_Rusty_Metal",
      "rotation": 13
    },
    {
      "x": -49,
      "y": 17,
      "z": 29,
      "name": "Rock_Rusty_Metal",
      "rotation": 13
    },
    {
      "x": -49,
      "y": 28,
      "z": 29,
      "name": "Rock_Dark_Rusty_Metal",
      "rotation": 13
    },
    {
      "x": -49,
      "y": 29,
      "z": 29,
      "name": "Rock_Dark_Rusty_Metal",
      "rotation": 13
    },
    {
      "x": -49,
      "y": 30,
      "z": 29,
      "name": "Rock_Dark_Rusty_Metal",
      "rotation": 13
    },
    {
      "x": -49,
      "y": 41,
      "z": 29,
      "name": "Rock_Rusty_Metal",
      "rotation": 13
    },
    {
      "x": -49,
      "y": 42,
      "z": 29,
      "name": "Rock_Rusty_Metal",
      "rotation": 13
    },
    {
      "x": -49,
      "y": 13,
      "z": 30,
      "name": "Rock_Rusty_Metal",
      "rotation": 13
    },
    {
      "x": -49,
      "y": 14,
      "z": 30,
      "name": "Rock_Rusty_Metal",
      "rotation": 13
    },
    {
      "x": -49,
      "y": 15,
      "z": 30,
      "name": "Rock_Dark_Rusty_Metal",
      "rotation": 13
    },
    {
      "x": -49,
      "y": 16,
      "z": 30,
      "name": "Rock_Rusty_Metal",
      "rotation": 13
    },
    {
      "x": -49,
      "y": 17,
      "z": 30,
      "name": "Rock_Rusty_Metal",
      "rotation": 13
    },
    {
      "x": -49,
      "y": 18,
      "z": 30,
      "name": "Rock_Dark_Rusty_Metal",
      "rotation": 13
    },
    {
      "x": -49,
      "y": 26,
      "z": 30,
      "name": "Rock_Bronze_Metal",
      "rotation": 13
    },
    {
      "x": -49,
      "y": 27,
      "z": 30,
      "name": "Rock_Bronze_Metal",
      "rotation": 13
    },
    {
      "x": -49,
      "y": 28,
      "z": 30,
      "name": "Rock_Bronze_Metal",
      "rotation": 13
    },
    {
      "x": -49,
      "y": 29,
      "z": 30,
      "name": "Rock_Bronze_Metal",
      "rotation": 13
    },
    {
      "x": -49,
      "y": 30,
      "z": 30,
      "name": "Rock_Bronze_Metal",
      "rotation": 13
    },
    {
      "x": -49,
      "y": 31,
      "z": 30,
      "name": "Rock_Bronze_Metal",
      "rotation": 13
    },
    {
      "x": -49,
      "y": 32,
      "z": 30,
      "name": "Rock_Bronze_Metal",
      "rotation": 13
    },
    {
      "x": -49,
      "y": 40,
      "z": 30,
      "name": "Rock_Dark_Rusty_Metal",
      "rotation": 13
    },
    {
      "x": -49,
      "y": 41,
      "z": 30,
      "name": "Rock_Rusty_Metal",
      "rotation": 13
    },
    {
      "x": -49,
      "y": 42,
      "z": 30,
      "name": "Rock_Rusty_Metal",
      "rotation": 13
    },
    {
      "x": -49,
      "y": 43,
      "z": 30,
      "name": "Rock_Dark_Rusty_Metal",
      "rotation": 13
    },
    {
      "x": -49,
      "y": 44,
      "z": 30,
      "name": "Rock_Rusty_Metal",
      "rotation": 13
    },
    {
      "x": -49,
      "y": 45,
      "z": 30,
      "name": "Rock_Rusty_Metal",
      "rotation": 13
    },
    {
      "x": -49,
      "y": 13,
      "z": 31,
      "name": "Rock_Rusty_Metal",
      "rotation": 6
    },
    {
      "x": -49,
      "y": 14,
      "z": 31,
      "name": "Rock_Rusty_Metal",
      "rotation": 6
    },
    {
      "x": -49,
      "y": 15,
      "z": 31,
      "name": "Rock_Dark_Rusty_Metal",
      "rotation": 6
    },
    {
      "x": -49,
      "y": 16,
      "z": 31,
      "name": "Rock_Rusty_Metal",
      "rotation": 6
    },
    {
      "x": -49,
      "y": 17,
      "z": 31,
      "name": "Rock_Rusty_Metal",
      "rotation": 6
    },
    {
      "x": -49,
      "y": 18,
      "z": 31,
      "name": "Rock_Dark_Rusty_Metal",
      "rotation": 6
    },
    {
      "x": -49,
      "y": 26,
      "z": 31,
      "name": "Rock_Bronze_Metal",
      "rotation": 6
    },
    {
      "x": -49,
      "y": 27,
      "z": 31,
      "name": "Rock_Bronze_Metal",
      "rotation": 6
    },
    {
      "x": -49,
      "y": 28,
      "z": 31,
      "name": "Rock_Bronze_Metal",
      "rotation": 6
    },
    {
      "x": -49,
      "y": 29,
      "z": 31,
      "name": "Rock_Bronze_Metal",
      "rotation": 6
    },
    {
      "x": -49,
      "y": 30,
      "z": 31,
      "name": "Rock_Bronze_Metal",
      "rotation": 6
    },
    {
      "x": -49,
      "y": 31,
      "z": 31,
      "name": "Rock_Bronze_Metal",
      "rotation": 6
    },
    {
      "x": -49,
      "y": 32,
      "z": 31,
      "name": "Rock_Bronze_Metal",
      "rotation": 6
    },
    {
      "x": -49,
      "y": 40,
      "z": 31,
      "name": "Rock_Dark_Rusty_Metal",
      "rotation": 6
    },
    {
      "x": -49,
      "y": 41,
      "z": 31,
      "name": "Rock_Rusty_Metal",
      "rotation": 6
    },
    {
      "x": -49,
      "y": 42,
      "z": 31,
      "name": "Rock_Rusty_Metal",
      "rotation": 6
    },
    {
      "x": -49,
      "y": 43,
      "z": 31,
      "name": "Rock_Dark_Rusty_Metal",
      "rotation": 6
    },
    {
      "x": -49,
      "y": 44,
      "z": 31,
      "name": "Rock_Rusty_Metal",
      "rotation": 6
    },
    {
      "x": -49,
      "y": 45,
      "z": 31,
      "name": "Rock_Rusty_Metal",
      "rotation": 6
    },
    {
      "x": -49,
      "y": 16,
      "z": 32,
      "name": "Rock_Rusty_Metal",
      "rotation": 6
    },
    {
      "x": -49,
      "y": 17,
      "z": 32,
      "name": "Rock_Rusty_Metal",
      "rotation": 6
    },
    {
      "x": -49,
      "y": 28,
      "z": 32,
      "name": "Rock_Dark_Rusty_Metal",
      "rotation": 6
    },
    {
      "x": -49,
      "y": 29,
      "z": 32,
      "name": "Rock_Dark_Rusty_Metal",
      "rotation": 6
    },
    {
      "x": -49,
      "y": 30,
      "z": 32,
      "name": "Rock_Dark_Rusty_Metal",
      "rotation": 6
    },
    {
      "x": -49,
      "y": 41,
      "z": 32,
      "name": "Rock_Rusty_Metal",
      "rotation": 6
    },
    {
      "x": -49,
      "y": 42,
      "z": 32,
      "name": "Rock_Rusty_Metal",
      "rotation": 6
    },
    {
      "x": -48,
      "y": 16,
      "z": 29,
      "name": "Rock_Rusty_Metal",
      "rotation": 13
    },
    {
      "x": -48,
      "y": 17,
      "z": 29,
      "name": "Rock_Rusty_Metal",
      "rotation": 13
    },
    {
      "x": -48,
      "y": 27,
      "z": 29,
      "name": "Rock_Dark_Rusty_Metal",
      "rotation": 13
    },
    {
      "x": -48,
      "y": 28,
      "z": 29,
      "name": "Rock_Bronze_Metal",
      "rotation": 13
    },
    {
      "x": -48,
      "y": 29,
      "z": 29,
      "name": "Rock_Bronze_Metal",
      "rotation": 13
    },
    {
      "x": -48,
      "y": 30,
      "z": 29,
      "name": "Rock_Bronze_Metal",
      "rotation": 13
    },
    {
      "x": -48,
      "y": 31,
      "z": 29,
      "name": "Rock_Dark_Rusty_Metal",
      "rotation": 13
    },
    {
      "x": -48,
      "y": 41,
      "z": 29,
      "name": "Rock_Rusty_Metal",
      "rotation": 13
    },
    {
      "x": -48,
      "y": 42,
      "z": 29,
      "name": "Rock_Rusty_Metal",
      "rotation": 13
    },
    {
      "x": -48,
      "y": 14,
      "z": 30,
      "name": "Rock_Rusty_Metal",
      "rotation": 13
    },
    {
      "x": -48,
      "y": 15,
      "z": 30,
      "name": "Rock_Dark_Rusty_Metal",
      "rotation": 13
    },
    {
      "x": -48,
      "y": 16,
      "z": 30,
      "name": "Rock_Rusty_Metal",
      "rotation": 13
    },
    {
      "x": -48,
      "y": 17,
      "z": 30,
      "name": "Rock_Rusty_Metal",
      "rotation": 13
    },
    {
      "x": -48,
      "y": 18,
      "z": 30,
      "name": "Rock_Dark_Rusty_Metal",
      "rotation": 13
    },
    {
      "x": -48,
      "y": 19,
      "z": 30,
      "name": "Rock_Dark_Rusty_Metal",
      "rotation": 13
    },
    {
      "x": -48,
      "y": 20,
      "z": 30,
      "name": "Rock_Dark_Rusty_Metal",
      "rotation": 13
    },
    {
      "x": -48,
      "y": 21,
      "z": 30,
      "name": "Rock_Dark_Rusty_Metal",
      "rotation": 13
    },
    {
      "x": -48,
      "y": 22,
      "z": 30,
      "name": "Rock_Dark_Rusty_Metal",
      "rotation": 13
    },
    {
      "x": -48,
      "y": 23,
      "z": 30,
      "name": "Rock_Dark_Rusty_Metal",
      "rotation": 13
    },
    {
      "x": -48,
      "y": 24,
      "z": 30,
      "name": "Rock_Dark_Rusty_Metal",
      "rotation": 13
    },
    {
      "x": -48,
      "y": 25,
      "z": 30,
      "name": "Rock_Bronze_Metal",
      "rotation": 13
    },
    {
      "x": -48,
      "y": 26,
      "z": 30,
      "name": "Rock_Bronze_Metal",
      "rotation": 13
    },
    {
      "x": -48,
      "y": 27,
      "z": 30,
      "name": "Rock_Bronze_Metal",
      "rotation": 13
    },
    {
      "x": -48,
      "y": 28,
      "z": 30,
      "name": "Rock_Bronze_Metal",
      "rotation": 13
    },
    {
      "x": -48,
      "y": 29,
      "z": 30,
      "name": "Rock_Bronze_Metal",
      "rotation": 13
    },
    {
      "x": -48,
      "y": 30,
      "z": 30,
      "name": "Rock_Bronze_Metal",
      "rotation": 13
    },
    {
      "x": -48,
      "y": 31,
      "z": 30,
      "name": "Rock_Bronze_Metal",
      "rotation": 13
    },
    {
      "x": -48,
      "y": 32,
      "z": 30,
      "name": "Rock_Bronze_Metal",
      "rotation": 13
    },
    {
      "x": -48,
      "y": 33,
      "z": 30,
      "name": "Rock_Bronze_Metal",
      "rotation": 13
    },
    {
      "x": -48,
      "y": 34,
      "z": 30,
      "name": "Rock_Dark_Rusty_Metal",
      "rotation": 13
    },
    {
      "x": -48,
      "y": 35,
      "z": 30,
      "name": "Rock_Dark_Rusty_Metal",
      "rotation": 13
    },
    {
      "x": -48,
      "y": 36,
      "z": 30,
      "name": "Rock_Dark_Rusty_Metal",
      "rotation": 13
    },
    {
      "x": -48,
      "y": 37,
      "z": 30,
      "name": "Rock_Dark_Rusty_Metal",
      "rotation": 13
    },
    {
      "x": -48,
      "y": 38,
      "z": 30,
      "name": "Rock_Dark_Rusty_Metal",
      "rotation": 13
    },
    {
      "x": -48,
      "y": 39,
      "z": 30,
      "name": "Rock_Dark_Rusty_Metal",
      "rotation": 13
    },
    {
      "x": -48,
      "y": 40,
      "z": 30,
      "name": "Rock_Dark_Rusty_Metal",
      "rotation": 13
    },
    {
      "x": -48,
      "y": 41,
      "z": 30,
      "name": "Rock_Rusty_Metal",
      "rotation": 13
    },
    {
      "x": -48,
      "y": 42,
      "z": 30,
      "name": "Rock_Rusty_Metal",
      "rotation": 13
    },
    {
      "x": -48,
      "y": 43,
      "z": 30,
      "name": "Rock_Dark_Rusty_Metal",
      "rotation": 13
    },
    {
      "x": -48,
      "y": 44,
      "z": 30,
      "name": "Rock_Rusty_Metal",
      "rotation": 13
    },
    {
      "x": -48,
      "y": 14,
      "z": 31,
      "name": "Rock_Rusty_Metal",
      "rotation": 6
    },
    {
      "x": -48,
      "y": 15,
      "z": 31,
      "name": "Rock_Dark_Rusty_Metal",
      "rotation": 6
    },
    {
      "x": -48,
      "y": 16,
      "z": 31,
      "name": "Rock_Rusty_Metal",
      "rotation": 6
    },
    {
      "x": -48,
      "y": 17,
      "z": 31,
      "name": "Rock_Rusty_Metal",
      "rotation": 6
    },
    {
      "x": -48,
      "y": 18,
      "z": 31,
      "name": "Rock_Dark_Rusty_Metal",
      "rotation": 6
    },
    {
      "x": -48,
      "y": 19,
      "z": 31,
      "name": "Rock_Dark_Rusty_Metal",
      "rotation": 6
    },
    {
      "x": -48,
      "y": 20,
      "z": 31,
      "name": "Rock_Dark_Rusty_Metal",
      "rotation": 6
    },
    {
      "x": -48,
      "y": 21,
      "z": 31,
      "name": "Rock_Dark_Rusty_Metal",
      "rotation": 6
    },
    {
      "x": -48,
      "y": 22,
      "z": 31,
      "name": "Rock_Dark_Rusty_Metal",
      "rotation": 6
    },
    {
      "x": -48,
      "y": 23,
      "z": 31,
      "name": "Rock_Dark_Rusty_Metal",
      "rotation": 6
    },
    {
      "x": -48,
      "y": 24,
      "z": 31,
      "name": "Rock_Dark_Rusty_Metal",
      "rotation": 6
    },
    {
      "x": -48,
      "y": 25,
      "z": 31,
      "name": "Rock_Bronze_Metal",
      "rotation": 6
    },
    {
      "x": -48,
      "y": 26,
      "z": 31,
      "name": "Rock_Bronze_Metal",
      "rotation": 6
    },
    {
      "x": -48,
      "y": 27,
      "z": 31,
      "name": "Rock_Bronze_Metal",
      "rotation": 6
    },
    {
      "x": -48,
      "y": 28,
      "z": 31,
      "name": "Rock_Bronze_Metal",
      "rotation": 6
    },
    {
      "x": -48,
      "y": 29,
      "z": 31,
      "name": "Rock_Bronze_Metal",
      "rotation": 6
    },
    {
      "x": -48,
      "y": 30,
      "z": 31,
      "name": "Rock_Bronze_Metal",
      "rotation": 6
    },
    {
      "x": -48,
      "y": 31,
      "z": 31,
      "name": "Rock_Bronze_Metal",
      "rotation": 6
    },
    {
      "x": -48,
      "y": 32,
      "z": 31,
      "name": "Rock_Bronze_Metal",
      "rotation": 6
    },
    {
      "x": -48,
      "y": 33,
      "z": 31,
      "name": "Rock_Bronze_Metal",
      "rotation": 6
    },
    {
      "x": -48,
      "y": 34,
      "z": 31,
      "name": "Rock_Dark_Rusty_Metal",
      "rotation": 6
    },
    {
      "x": -48,
      "y": 35,
      "z": 31,
      "name": "Rock_Dark_Rusty_Metal",
      "rotation": 6
    },
    {
      "x": -48,
      "y": 36,
      "z": 31,
      "name": "Rock_Dark_Rusty_Metal",
      "rotation": 6
    },
    {
      "x": -48,
      "y": 37,
      "z": 31,
      "name": "Rock_Dark_Rusty_Metal",
      "rotation": 6
    },
    {
      "x": -48,
      "y": 38,
      "z": 31,
      "name": "Rock_Dark_Rusty_Metal",
      "rotation": 6
    },
    {
      "x": -48,
      "y": 39,
      "z": 31,
      "name": "Rock_Dark_Rusty_Metal",
      "rotation": 6
    },
    {
      "x": -48,
      "y": 40,
      "z": 31,
      "name": "Rock_Dark_Rusty_Metal",
      "rotation": 6
    },
    {
      "x": -48,
      "y": 41,
      "z": 31,
      "name": "Rock_Rusty_Metal",
      "rotation": 6
    },
    {
      "x": -48,
      "y": 42,
      "z": 31,
      "name": "Rock_Rusty_Metal",
      "rotation": 6
    },
    {
      "x": -48,
      "y": 43,
      "z": 31,
      "name": "Rock_Dark_Rusty_Metal",
      "rotation": 6
    },
    {
      "x": -48,
      "y": 44,
      "z": 31,
      "name": "Rock_Rusty_Metal",
      "rotation": 6
    },
    {
      "x": -48,
      "y": 16,
      "z": 32,
      "name": "Rock_Rusty_Metal",
      "rotation": 6
    },
    {
      "x": -48,
      "y": 17,
      "z": 32,
      "name": "Rock_Rusty_Metal",
      "rotation": 6
    },
    {
      "x": -48,
      "y": 27,
      "z": 32,
      "name": "Rock_Dark_Rusty_Metal",
      "rotation": 6
    },
    {
      "x": -48,
      "y": 28,
      "z": 32,
      "name": "Rock_Bronze_Metal",
      "rotation": 6
    },
    {
      "x": -48,
      "y": 29,
      "z": 32,
      "name": "Rock_Bronze_Metal",
      "rotation": 6
    },
    {
      "x": -48,
      "y": 30,
      "z": 32,
      "name": "Rock_Bronze_Metal",
      "rotation": 6
    },
    {
      "x": -48,
      "y": 31,
      "z": 32,
      "name": "Rock_Dark_Rusty_Metal",
      "rotation": 6
    },
    {
      "x": -48,
      "y": 41,
      "z": 32,
      "name": "Rock_Rusty_Metal",
      "rotation": 6
    },
    {
      "x": -48,
      "y": 42,
      "z": 32,
      "name": "Rock_Rusty_Metal",
      "rotation": 6
    },
    {
      "x": -47,
      "y": 16,
      "z": 29,
      "name": "Rock_Rusty_Metal",
      "rotation": 13
    },
    {
      "x": -47,
      "y": 17,
      "z": 29,
      "name": "Rock_Rusty_Metal",
      "rotation": 13
    },
    {
      "x": -47,
      "y": 18,
      "z": 29,
      "name": "Rock_Rusty_Metal",
      "rotation": 13
    },
    {
      "x": -47,
      "y": 19,
      "z": 29,
      "name": "Rock_Rusty_Metal",
      "rotation": 13
    },
    {
      "x": -47,
      "y": 20,
      "z": 29,
      "name": "Rock_Rusty_Metal",
      "rotation": 13
    },
    {
      "x": -47,
      "y": 21,
      "z": 29,
      "name": "Rock_Rusty_Metal",
      "rotation": 13
    },
    {
      "x": -47,
      "y": 22,
      "z": 29,
      "name": "Rock_Rusty_Metal",
      "rotation": 13
    },
    {
      "x": -47,
      "y": 23,
      "z": 29,
      "name": "Rock_Rusty_Metal",
      "rotation": 13
    },
    {
      "x": -47,
      "y": 24,
      "z": 29,
      "name": "Rock_Rusty_Metal",
      "rotation": 13
    },
    {
      "x": -47,
      "y": 27,
      "z": 29,
      "name": "Rock_Dark_Rusty_Metal",
      "rotation": 13
    },
    {
      "x": -47,
      "y": 28,
      "z": 29,
      "name": "Rock_Bronze_Metal",
      "rotation": 13
    },
    {
      "x": -47,
      "y": 30,
      "z": 29,
      "name": "Rock_Bronze_Metal",
      "rotation": 13
    },
    {
      "x": -47,
      "y": 31,
      "z": 29,
      "name": "Rock_Dark_Rusty_Metal",
      "rotation": 13
    },
    {
      "x": -47,
      "y": 34,
      "z": 29,
      "name": "Rock_Rusty_Metal",
      "rotation": 13
    },
    {
      "x": -47,
      "y": 35,
      "z": 29,
      "name": "Rock_Rusty_Metal",
      "rotation": 13
    },
    {
      "x": -47,
      "y": 36,
      "z": 29,
      "name": "Rock_Rusty_Metal",
      "rotation": 13
    },
    {
      "x": -47,
      "y": 37,
      "z": 29,
      "name": "Rock_Rusty_Metal",
      "rotation": 13
    },
    {
      "x": -47,
      "y": 38,
      "z": 29,
      "name": "Rock_Rusty_Metal",
      "rotation": 6
    },
    {
      "x": -47,
      "y": 39,
      "z": 29,
      "name": "Rock_Rusty_Metal",
      "rotation": 13
    },
    {
      "x": -47,
      "y": 40,
      "z": 29,
      "name": "Rock_Rusty_Metal",
      "rotation": 13
    },
    {
      "x": -47,
      "y": 41,
      "z": 29,
      "name": "Rock_Rusty_Metal",
      "rotation": 13
    },
    {
      "x": -47,
      "y": 42,
      "z": 29,
      "name": "Rock_Rusty_Metal",
      "rotation": 13
    },
    {
      "x": -47,
      "y": 15,
      "z": 30,
      "name": "Rock_Dark_Rusty_Metal",
      "rotation": 13
    },
    {
      "x": -47,
      "y": 16,
      "z": 30,
      "name": "Rock_Rusty_Metal",
      "rotation": 13
    },
    {
      "x": -47,
      "y": 17,
      "z": 30,
      "name": "Rock_Rusty_Metal",
      "rotation": 13
    },
    {
      "x": -47,
      "y": 18,
      "z": 30,
      "name": "Rock_Rusty_Metal",
      "rotation": 13
    },
    {
      "x": -47,
      "y": 19,
      "z": 30,
      "name": "Rock_Rusty_Metal",
      "rotation": 13
    },
    {
      "x": -47,
      "y": 20,
      "z": 30,
      "name": "Rock_Rusty_Metal",
      "rotation": 13
    },
    {
      "x": -47,
      "y": 21,
      "z": 30,
      "name": "Rock_Rusty_Metal",
      "rotation": 13
    },
    {
      "x": -47,
      "y": 22,
      "z": 30,
      "name": "Rock_Rusty_Metal",
      "rotation": 13
    },
    {
      "x": -47,
      "y": 23,
      "z": 30,
      "name": "Rock_Rusty_Metal",
      "rotation": 13
    },
    {
      "x": -47,
      "y": 24,
      "z": 30,
      "name": "Rock_Rusty_Metal",
      "rotation": 13
    },
    {
      "x": -47,
      "y": 25,
      "z": 30,
      "name": "Rock_Bronze_Metal",
      "rotation": 13
    },
    {
      "x": -47,
      "y": 26,
      "z": 30,
      "name": "Rock_Bronze_Metal",
      "rotation": 13
    },
    {
      "x": -47,
      "y": 27,
      "z": 30,
      "name": "Rock_Bronze_Metal",
      "rotation": 13
    },
    {
      "x": -47,
      "y": 28,
      "z": 30,
      "name": "Rock_Bronze_Metal",
      "rotation": 13
    },
    {
      "x": -47,
      "y": 30,
      "z": 30,
      "name": "Rock_Bronze_Metal",
      "rotation": 13
    },
    {
      "x": -47,
      "y": 31,
      "z": 30,
      "name": "Rock_Bronze_Metal",
      "rotation": 13
    },
    {
      "x": -47,
      "y": 32,
      "z": 30,
      "name": "Rock_Bronze_Metal",
      "rotation": 13
    },
    {
      "x": -47,
      "y": 33,
      "z": 30,
      "name": "Rock_Bronze_Metal",
      "rotation": 13
    },
    {
      "x": -47,
      "y": 34,
      "z": 30,
      "name": "Rock_Rusty_Metal",
      "rotation": 13
    },
    {
      "x": -47,
      "y": 35,
      "z": 30,
      "name": "Rock_Rusty_Metal",
      "rotation": 13
    },
    {
      "x": -47,
      "y": 36,
      "z": 30,
      "name": "Rock_Rusty_Metal",
      "rotation": 13
    },
    {
      "x": -47,
      "y": 37,
      "z": 30,
      "name": "Rock_Rusty_Metal",
      "rotation": 13
    },
    {
      "x": -47,
      "y": 38,
      "z": 30,
      "name": "Rock_Rusty_Metal",
      "rotation": 13
    },
    {
      "x": -47,
      "y": 39,
      "z": 30,
      "name": "Rock_Rusty_Metal",
      "rotation": 13
    },
    {
      "x": -47,
      "y": 40,
      "z": 30,
      "name": "Rock_Rusty_Metal",
      "rotation": 13
    },
    {
      "x": -47,
      "y": 41,
      "z": 30,
      "name": "Rock_Rusty_Metal",
      "rotation": 13
    },
    {
      "x": -47,
      "y": 42,
      "z": 30,
      "name": "Rock_Rusty_Metal",
      "rotation": 13
    },
    {
      "x": -47,
      "y": 43,
      "z": 30,
      "name": "Rock_Dark_Rusty_Metal",
      "rotation": 13
    },
    {
      "x": -47,
      "y": 15,
      "z": 31,
      "name": "Rock_Dark_Rusty_Metal",
      "rotation": 6
    },
    {
      "x": -47,
      "y": 16,
      "z": 31,
      "name": "Rock_Rusty_Metal",
      "rotation": 6
    },
    {
      "x": -47,
      "y": 17,
      "z": 31,
      "name": "Rock_Rusty_Metal",
      "rotation": 6
    },
    {
      "x": -47,
      "y": 18,
      "z": 31,
      "name": "Rock_Rusty_Metal",
      "rotation": 6
    },
    {
      "x": -47,
      "y": 19,
      "z": 31,
      "name": "Rock_Rusty_Metal",
      "rotation": 6
    },
    {
      "x": -47,
      "y": 20,
      "z": 31,
      "name": "Rock_Rusty_Metal",
      "rotation": 6
    },
    {
      "x": -47,
      "y": 21,
      "z": 31,
      "name": "Rock_Rusty_Metal",
      "rotation": 6
    },
    {
      "x": -47,
      "y": 22,
      "z": 31,
      "name": "Rock_Rusty_Metal",
      "rotation": 6
    },
    {
      "x": -47,
      "y": 23,
      "z": 31,
      "name": "Rock_Rusty_Metal",
      "rotation": 6
    },
    {
      "x": -47,
      "y": 24,
      "z": 31,
      "name": "Rock_Rusty_Metal",
      "rotation": 6
    },
    {
      "x": -47,
      "y": 25,
      "z": 31,
      "name": "Rock_Bronze_Metal",
      "rotation": 6
    },
    {
      "x": -47,
      "y": 26,
      "z": 31,
      "name": "Rock_Bronze_Metal",
      "rotation": 6
    },
    {
      "x": -47,
      "y": 27,
      "z": 31,
      "name": "Rock_Bronze_Metal",
      "rotation": 6
    },
    {
      "x": -47,
      "y": 28,
      "z": 31,
      "name": "Rock_Bronze_Metal",
      "rotation": 6
    },
    {
      "x": -47,
      "y": 30,
      "z": 31,
      "name": "Rock_Bronze_Metal",
      "rotation": 6
    },
    {
      "x": -47,
      "y": 31,
      "z": 31,
      "name": "Rock_Bronze_Metal",
      "rotation": 6
    },
    {
      "x": -47,
      "y": 32,
      "z": 31,
      "name": "Rock_Bronze_Metal",
      "rotation": 6
    },
    {
      "x": -47,
      "y": 33,
      "z": 31,
      "name": "Rock_Bronze_Metal",
      "rotation": 6
    },
    {
      "x": -47,
      "y": 34,
      "z": 31,
      "name": "Rock_Rusty_Metal",
      "rotation": 6
    },
    {
      "x": -47,
      "y": 35,
      "z": 31,
      "name": "Rock_Rusty_Metal",
      "rotation": 6
    },
    {
      "x": -47,
      "y": 36,
      "z": 31,
      "name": "Rock_Rusty_Metal",
      "rotation": 6
    },
    {
      "x": -47,
      "y": 37,
      "z": 31,
      "name": "Rock_Rusty_Metal",
      "rotation": 6
    },
    {
      "x": -47,
      "y": 38,
      "z": 31,
      "name": "Rock_Rusty_Metal",
      "rotation": 6
    },
    {
      "x": -47,
      "y": 39,
      "z": 31,
      "name": "Rock_Rusty_Metal",
      "rotation": 6
    },
    {
      "x": -47,
      "y": 40,
      "z": 31,
      "name": "Rock_Rusty_Metal",
      "rotation": 6
    },
    {
      "x": -47,
      "y": 41,
      "z": 31,
      "name": "Rock_Rusty_Metal",
      "rotation": 6
    },
    {
      "x": -47,
      "y": 42,
      "z": 31,
      "name": "Rock_Rusty_Metal",
      "rotation": 6
    },
    {
      "x": -47,
      "y": 43,
      "z": 31,
      "name": "Rock_Dark_Rusty_Metal",
      "rotation": 6
    },
    {
      "x": -47,
      "y": 16,
      "z": 32,
      "name": "Rock_Rusty_Metal",
      "rotation": 6
    },
    {
      "x": -47,
      "y": 17,
      "z": 32,
      "name": "Rock_Rusty_Metal",
      "rotation": 6
    },
    {
      "x": -47,
      "y": 18,
      "z": 32,
      "name": "Rock_Rusty_Metal",
      "rotation": 6
    },
    {
      "x": -47,
      "y": 19,
      "z": 32,
      "name": "Rock_Rusty_Metal",
      "rotation": 6
    },
    {
      "x": -47,
      "y": 20,
      "z": 32,
      "name": "Rock_Rusty_Metal",
      "rotation": 6
    },
    {
      "x": -47,
      "y": 21,
      "z": 32,
      "name": "Rock_Rusty_Metal",
      "rotation": 6
    },
    {
      "x": -47,
      "y": 22,
      "z": 32,
      "name": "Rock_Rusty_Metal",
      "rotation": 6
    },
    {
      "x": -47,
      "y": 23,
      "z": 32,
      "name": "Rock_Rusty_Metal",
      "rotation": 6
    },
    {
      "x": -47,
      "y": 24,
      "z": 32,
      "name": "Rock_Rusty_Metal",
      "rotation": 6
    },
    {
      "x": -47,
      "y": 27,
      "z": 32,
      "name": "Rock_Dark_Rusty_Metal",
      "rotation": 6
    },
    {
      "x": -47,
      "y": 28,
      "z": 32,
      "name": "Rock_Bronze_Metal",
      "rotation": 6
    },
    {
      "x": -47,
      "y": 30,
      "z": 32,
      "name": "Rock_Bronze_Metal",
      "rotation": 6
    },
    {
      "x": -47,
      "y": 31,
      "z": 32,
      "name": "Rock_Dark_Rusty_Metal",
      "rotation": 6
    },
    {
      "x": -47,
      "y": 34,
      "z": 32,
      "name": "Rock_Rusty_Metal",
      "rotation": 6
    },
    {
      "x": -47,
      "y": 35,
      "z": 32,
