{
  "version": 8,
  "blockIdVersion": 11,
  "anchorX": 0,
  "anchorY": -1,
  "anchorZ": -1,
  "blocks": [
    {
      "x": -15,
      "y": -1,
      "z": -3,
      "name": "Rock_Rusty_Metal"
    },
    {
      "x": -15,
      "y": 0,
      "z": -3,
      "name": "Rock_Rusty_Metal"
    },
    {
      "x": -15,
      "y": 1,
      "z": -3,
      "name": "Rock_Rusty_Metal"
    },
    {
      "x": -15,
      "y": 2,
      "z": -3,
      "name": "Rock_Rusty_Metal"
    },
    {
      "x": -15,
      "y": -1,
      "z": -2,
      "name": "Rock_Rusty_Metal"
    },
    {
      "x": -15,
      "y": 0,
      "z": -2,
      "name": "Rock_Rusty_Metal"
    },
    {
      "x": -15,
      "y": 1,
      "z": -2,
      "name": "Rock_Rusty_Metal"
    },
    {
      "x": -15,
      "y": 2,
      "z": -2,
      "name": "Rock_Rusty_Metal"
    },
    {
      "x": -15,
      "y": -1,
      "z": -1,
      "name": "Rock_Rusty_Metal"
    },
    {
      "x": -15,
      "y": 0,
      "z": -1,
      "name": "Rock_Rusty_Metal"
    },
    {
      "x": -15,
      "y": 1,
      "z": -1,
      "name": "Rock_Rusty_Metal"
    },
    {
      "x": -15,
      "y": 2,
      "z": -1,
      "name": "Rock_Rusty_Metal"
    },
    {
      "x": -15,
      "y": 11,
      "z": -1,
      "name": "Rock_Bronze_Metal"
    },
    {
      "x": -15,
      "y": 12,
      "z": -1,
      "name": "Rock_Bronze_Metal"
    },
    {
      "x": -15,
      "y": 13,
      "z": -1,
      "name": "Rock_Bronze_Metal"
    },
    {
      "x": -15,
      "y": 14,
      "z": -1,
      "name": "Rock_Bronze_Metal"
    },
    {
      "x": -15,
      "y": 15,
      "z": -1,
      "name": "Rock_Bronze_Metal"
    },
    {
      "x": -15,
      "y": 16,
      "z": -1,
      "name": "Rock_Bronze_Metal"
    },
    {
      "x": -15,
      "y": 17,
      "z": -1,
      "name": "Rock_Bronze_Metal"
    },
    {
      "x": -15,
      "y": 18,
      "z": -1,
      "name": "Rock_Bronze_Metal"
    },
    {
      "x": -15,
      "y": -1,
      "z": 0,
      "name": "Rock_Rusty_Metal"
    },
    {
      "x": -15,
      "y": 0,
      "z": 0,
      "name": "Rock_Rusty_Metal"
    },
    {
      "x": -15,
      "y": 1,
      "z": 0,
      "name": "Rock_Rusty_Metal"
    },
    {
      "x": -15,
      "y": 2,
      "z": 0,
      "name": "Rock_Rusty_Metal"
    },
    {
      "x": -15,
      "y": 9,
      "z": 0,
      "name": "Rock_Bronze_Metal"
    },
    {
      "x": -15,
      "y": 10,
      "z": 0,
      "name": "Rock_Bronze_Metal"
    },
    {
      "x": -15,
      "y": 11,
      "z": 0,
      "name": "Rock_Bronze_Metal"
    },
    {
      "x": -15,
      "y": 12,
      "z": 0,
      "name": "Rock_Bronze_Metal"
    },
    {
      "x": -15,
      "y": 13,
      "z": 0,
      "name": "Rock_Bronze_Metal"
    },
    {
      "x": -15,
      "y": 14,
      "z": 0,
      "name": "Rock_Bronze_Metal"
    },
    {
      "x": -15,
      "y": 15,
      "z": 0,
      "name": "Rock_Bronze_Metal"
    },
    {
      "x": -15,
      "y": 16,
      "z": 0,
      "name": "Rock_Bronze_Metal"
    },
    {
      "x": -15,
      "y": 17,
      "z": 0,
      "name": "Rock_Bronze_Metal"
    },
    {
      "x": -15,
      "y": 18,
      "z": 0,
      "name": "Rock_Bronze_Metal"
    },
    {
      "x": -15,
      "y": 19,
      "z": 0,
      "name": "Rock_Bronze_Metal"
    },
    {
      "x": -15,
      "y": -1,
      "z": 1,
      "name": "Rock_Rusty_Metal"
    },
    {
      "x": -15,
      "y": 0,
      "z": 1,
      "name": "Rock_Rusty_Metal"
    },
    {
      "x": -15,
      "y": 1,
      "z": 1,
      "name": "Rock_Rusty_Metal"
    },
    {
      "x": -15,
      "y": 2,
      "z": 1,
      "name": "Rock_Rusty_Metal"
    },
    {
      "x": -15,
      "y": 11,
      "z": 1,
      "name": "Rock_Bronze_Metal"
    },
    {
      "x": -15,
      "y": 12,
      "z": 1,
      "name": "Rock_Bronze_Metal"
    },
    {
      "x": -15,
      "y": 13,
      "z": 1,
      "name": "Rock_Bronze_Metal"
    },
    {
      "x": -15,
      "y": 14,
      "z": 1,
      "name": "Rock_Bronze_Metal"
    },
    {
      "x": -15,
      "y": 15,
      "z": 1,
      "name": "Rock_Bronze_Metal"
    },
    {
      "x": -15,
      "y": 16,
      "z": 1,
      "name": "Rock_Bronze_Metal"
    },
    {
      "x": -15,
      "y": 17,
      "z": 1,
      "name": "Rock_Bronze_Metal"
    },
    {
      "x": -15,
      "y": 18,
      "z": 1,
      "name": "Rock_Bronze_Metal"
    },
    {
      "x": -15,
      "y": -1,
      "z": 2,
      "name": "Rock_Rusty_Metal"
    },
    {
      "x": -15,
      "y": 0,
      "z": 2,
      "name": "Rock_Rusty_Metal"
    },
    {
      "x": -15,
      "y": 1,
      "z": 2,
      "name": "Rock_Rusty_Metal"
    },
    {
      "x": -15,
      "y": 2,
      "z": 2,
      "name": "Rock_Rusty_Metal"
    },
    {
      "x": -15,
      "y": -1,
      "z": 3,
      "name": "Rock_Rusty_Metal"
    },
    {
      "x": -15,
      "y": 0,
      "z": 3,
      "name": "Rock_Rusty_Metal"
    },
    {
      "x": -15,
      "y": 1,
      "z": 3,
      "name": "Rock_Rusty_Metal"
    },
    {
      "x": -15,
      "y": 2,
      "z": 3,
      "name": "Rock_Rusty_Metal"
    },
    {
      "x": -14,
      "y": -1,
      "z": -6,
      "name": "Rock_Dark_Rusty_Metal"
    },
    {
      "x": -14,
      "y": 0,
      "z": -6,
      "name": "Rock_Dark_Rusty_Metal"
    },
    {
      "x": -14,
      "y": 1,
      "z": -6,
      "name": "Rock_Dark_Rusty_Metal"
    },
    {
      "x": -14,
      "y": 2,
      "z": -6,
      "name": "Rock_Dark_Rusty_Metal"
    },
    {
      "x": -14,
      "y": -1,
      "z": -5,
      "name": "Rock_Rusty_Metal"
    },
    {
      "x": -14,
      "y": 0,
      "z": -5,
      "name": "Rock_Rusty_Metal"
    },
    {
      "x": -14,
      "y": 1,
      "z": -5,
      "name": "Rock_Rusty_Metal"
    },
    {
      "x": -14,
      "y": 2,
      "z": -5,
      "name": "Rock_Rusty_Metal"
    },
    {
      "x": -14,
      "y": -1,
      "z": -4,
      "name": "Rock_Rusty_Metal"
    },
    {
      "x": -14,
      "y": 0,
      "z": -4,
      "name": "Rock_Rusty_Metal"
    },
    {
      "x": -14,
      "y": 1,
      "z": -4,
      "name": "Rock_Rusty_Metal"
    },
    {
      "x": -14,
      "y": 2,
      "z": -4,
      "name": "Rock_Rusty_Metal"
    },
    {
      "x": -14,
      "y": -1,
      "z": -3,
      "name": "Rock_Rusty_Metal"
    },
    {
      "x": -14,
      "y": 5,
      "z": -3,
      "name": "Rock_Dark_Rusty_Metal"
    },
    {
      "x": -14,
      "y": 6,
      "z": -3,
      "name": "Rock_Dark_Rusty_Metal"
    },
    {
      "x": -14,
      "y": 7,
      "z": -3,
      "name": "Rock_Dark_Rusty_Metal"
    },
    {
      "x": -14,
      "y": 8,
      "z": -3,
      "name": "Rock_Dark_Rusty_Metal"
    },
    {
      "x": -14,
      "y": 9,
      "z": -3,
      "name": "Rock_Dark_Rusty_Metal"
    },
    {
      "x": -14,
      "y": 10,
      "z": -3,
      "name": "Rock_Dark_Rusty_Metal"
    },
    {
      "x": -14,
      "y": 11,
      "z": -3,
      "name": "Rock_Dark_Rusty_Metal"
    },
    {
      "x": -14,
      "y": 12,
      "z": -3,
      "name": "Rock_Dark_Rusty_Metal"
    },
    {
      "x": -14,
      "y": 13,
      "z": -3,
      "name": "Rock_Dark_Rusty_Metal"
    },
    {
      "x": -14,
      "y": -1,
      "z": -2,
      "name": "Rock_Rusty_Metal"
    },
    {
      "x": -14,
      "y": 5,
      "z": -2,
      "name": "Rock_Dark_Rusty_Metal"
    },
    {
      "x": -14,
      "y": 6,
      "z": -2,
      "name": "Rock_Dark_Rusty_Metal"
    },
    {
      "x": -14,
      "y": 7,
      "z": -2,
      "name": "Rock_Dark_Rusty_Metal"
    },
    {
      "x": -14,
      "y": 8,
      "z": -2,
      "name": "Rock_Dark_Rusty_Metal"
    },
    {
      "x": -14,
      "y": 9,
      "z": -2,
      "name": "Rock_Dark_Rusty_Metal"
    },
    {
      "x": -14,
      "y": 10,
      "z": -2,
      "name": "Rock_Dark_Rusty_Metal"
    },
    {
      "x": -14,
      "y": 11,
      "z": -2,
      "name": "Rock_Dark_Rusty_Metal"
    },
    {
      "x": -14,
      "y": 12,
      "z": -2,
      "name": "Rock_Dark_Rusty_Metal"
    },
    {
      "x": -14,
      "y": 13,
      "z": -2,
      "name": "Rock_Dark_Rusty_Metal"
    },
    {
      "x": -14,
      "y": 14,
      "z": -2,
      "name": "Rock_Dark_Rusty_Metal"
    },
    {
      "x": -14,
      "y": -1,
      "z": -1,
      "name": "Rock_Rusty_Metal"
    },
    {
      "x": -14,
      "y": 5,
      "z": -1,
      "name": "Rock_Dark_Rusty_Metal"
    },
    {
      "x": -14,
      "y": 6,
      "z": -1,
      "name": "Rock_Dark_Rusty_Metal"
    },
    {
      "x": -14,
      "y": 7,
      "z": -1,
      "name": "Rock_Dark_Rusty_Metal"
    },
    {
      "x": -14,
      "y": 8,
      "z": -1,
      "name": "Rock_Dark_Rusty_Metal"
    },
    {
      "x": -14,
      "y": 9,
      "z": -1,
      "name": "Rock_Dark_Rusty_Metal"
    },
    {
      "x": -14,
      "y": 10,
      "z": -1,
      "name": "Rock_Dark_Rusty_Metal"
    },
    {
      "x": -14,
      "y": 11,
      "z": -1,
      "name": "Rock_Bronze_Metal"
    },
    {
      "x": -14,
      "y": 12,
      "z": -1,
      "name": "Rock_Bronze_Metal"
    },
    {
      "x": -14,
      "y": 13,
      "z": -1,
      "name": "Rock_Bronze_Metal"
    },
    {
      "x": -14,
      "y": 14,
      "z": -1,
      "name": "Rock_Bronze_Metal"
    },
    {
      "x": -14,
      "y": 15,
      "z": -1,
      "name": "Rock_Bronze_Metal"
    },
    {
      "x": -14,
      "y": 16,
      "z": -1,
      "name": "Rock_Bronze_Metal"
    },
    {
      "x": -14,
      "y": 17,
      "z": -1,
      "name": "Rock_Bronze_Metal"
    },
    {
      "x": -14,
      "y": 18,
      "z": -1,
      "name": "Rock_Bronze_Metal"
    },
    {
      "x": -14,
      "y": -1,
      "z": 0,
      "name": "Rock_Rusty_Metal"
    },
    {
      "x": -14,
      "y": 5,
      "z": 0,
      "name": "Rock_Dark_Rusty_Metal"
    },
    {
      "x": -14,
      "y": 6,
      "z": 0,
      "name": "Rock_Dark_Rusty_Metal"
    },
    {
      "x": -14,
      "y": 7,
      "z": 0,
      "name": "Rock_Dark_Rusty_Metal"
    },
    {
      "x": -14,
      "y": 8,
      "z": 0,
      "name": "Rock_Dark_Rusty_Metal"
    },
    {
      "x": -14,
      "y": 9,
      "z": 0,
      "name": "Rock_Dark_Rusty_Metal"
    },
    {
      "x": -14,
      "y": 10,
      "z": 0,
      "name": "Rock_Dark_Rusty_Metal"
    },
    {
      "x": -14,
      "y": 11,
      "z": 0,
      "name": "Rock_Bronze_Metal"
    },
    {
      "x": -14,
      "y": 12,
      "z": 0,
      "name": "Rock_Bronze_Metal"
    },
    {
      "x": -14,
      "y": 13,
      "z": 0,
      "name": "Rock_Bronze_Metal"
    },
    {
      "x": -14,
      "y": 14,
      "z": 0,
      "name": "Rock_Bronze_Metal"
    },
    {
      "x": -14,
      "y": 15,
      "z": 0,
      "name": "Rock_Bronze_Metal"
    },
    {
      "x": -14,
      "y": 16,
      "z": 0,
      "name": "Rock_Bronze_Metal"
    },
    {
      "x": -14,
      "y": 17,
      "z": 0,
      "name": "Rock_Bronze_Metal"
    },
    {
      "x": -14,
      "y": 18,
      "z": 0,
      "name": "Rock_Bronze_Metal"
    },
    {
      "x": -14,
      "y": 19,
      "z": 0,
      "name": "Rock_Bronze_Metal"
    },
    {
      "x": -14,
      "y": -1,
      "z": 1,
      "name": "Rock_Rusty_Metal"
    },
    {
      "x": -14,
      "y": 5,
      "z": 1,
      "name": "Rock_Dark_Rusty_Metal"
    },
    {
      "x": -14,
      "y": 6,
      "z": 1,
      "name": "Rock_Dark_Rusty_Metal"
    },
    {
      "x": -14,
      "y": 7,
      "z": 1,
      "name": "Rock_Dark_Rusty_Metal"
    },
    {
      "x": -14,
      "y": 8,
      "z": 1,
      "name": "Rock_Dark_Rusty_Metal"
    },
    {
      "x": -14,
      "y": 9,
      "z": 1,
      "name": "Rock_Dark_Rusty_Metal"
    },
    {
      "x": -14,
      "y": 10,
      "z": 1,
      "name": "Rock_Dark_Rusty_Metal"
    },
    {
      "x": -14,
      "y": 11,
      "z": 1,
      "name": "Rock_Bronze_Metal"
    },
    {
      "x": -14,
      "y": 12,
      "z": 1,
      "name": "Rock_Bronze_Metal"
    },
    {
      "x": -14,
      "y": 13,
      "z": 1,
      "name": "Rock_Bronze_Metal"
    },
    {
      "x": -14,
      "y": 14,
      "z": 1,
      "name": "Rock_Bronze_Metal"
    },
    {
      "x": -14,
      "y": 15,
      "z": 1,
      "name": "Rock_Bronze_Metal"
    },
    {
      "x": -14,
      "y": 16,
      "z": 1,
      "name": "Rock_Bronze_Metal"
    },
    {
      "x": -14,
      "y": 17,
      "z": 1,
      "name": "Rock_Bronze_Metal"
    },
    {
      "x": -14,
      "y": 18,
      "z": 1,
      "name": "Rock_Bronze_Metal"
    },
    {
      "x": -14,
      "y": -1,
      "z": 2,
      "name": "Rock_Rusty_Metal"
    },
    {
      "x": -14,
      "y": 5,
      "z": 2,
      "name": "Rock_Dark_Rusty_Metal"
    },
    {
      "x": -14,
      "y": 6,
      "z": 2,
      "name": "Rock_Dark_Rusty_Metal"
    },
    {
      "x": -14,
      "y": 7,
      "z": 2,
      "name": "Rock_Dark_Rusty_Metal"
    },
    {
      "x": -14,
      "y": 8,
      "z": 2,
      "name": "Rock_Dark_Rusty_Metal"
    },
    {
      "x": -14,
      "y": 9,
      "z": 2,
      "name": "Rock_Dark_Rusty_Metal"
    },
    {
      "x": -14,
      "y": 10,
      "z": 2,
      "name": "Rock_Dark_Rusty_Metal"
    },
    {
      "x": -14,
      "y": 11,
      "z": 2,
      "name": "Rock_Dark_Rusty_Metal"
    },
    {
      "x": -14,
      "y": 12,
      "z": 2,
      "name": "Rock_Dark_Rusty_Metal"
    },
    {
      "x": -14,
      "y": 13,
      "z": 2,
      "name": "Rock_Dark_Rusty_Metal"
    },
    {
      "x": -14,
      "y": 14,
      "z": 2,
      "name": "Rock_Dark_Rusty_Metal"
    },
    {
      "x": -14,
      "y": -1,
      "z": 3,
      "name": "Rock_Rusty_Metal"
    },
    {
      "x": -14,
      "y": 5,
      "z": 3,
      "name": "Rock_Dark_Rusty_Metal"
    },
    {
      "x": -14,
      "y": 6,
      "z": 3,
      "name": "Rock_Dark_Rusty_Metal"
    },
    {
      "x": -14,
      "y": 7,
      "z": 3,
      "name": "Rock_Dark_Rusty_Metal"
    },
    {
      "x": -14,
      "y": 8,
      "z": 3,
      "name": "Rock_Dark_Rusty_Metal"
    },
    {
      "x": -14,
      "y": 9,
      "z": 3,
      "name": "Rock_Dark_Rusty_Metal"
    },
    {
      "x": -14,
      "y": 10,
      "z": 3,
      "name": "Rock_Dark_Rusty_Metal"
    },
    {
      "x": -14,
      "y": 11,
      "z": 3,
      "name": "Rock_Dark_Rusty_Metal"
    },
    {
      "x": -14,
      "y": 12,
      "z": 3,
      "name": "Rock_Dark_Rusty_Metal"
    },
    {
      "x": -14,
      "y": 13,
      "z": 3,
      "name": "Rock_Dark_Rusty_Metal"
    },
    {
      "x": -14,
      "y": -1,
      "z": 4,
      "name": "Rock_Rusty_Metal"
    },
    {
      "x": -14,
      "y": 0,
      "z": 4,
      "name": "Rock_Rusty_Metal"
    },
    {
      "x": -14,
      "y": 1,
      "z": 4,
      "name": "Rock_Rusty_Metal"
    },
    {
      "x": -14,
      "y": 2,
      "z": 4,
      "name": "Rock_Rusty_Metal"
    },
    {
      "x": -14,
      "y": -1,
      "z": 5,
      "name": "Rock_Rusty_Metal"
    },
    {
      "x": -14,
      "y": 0,
      "z": 5,
      "name": "Rock_Rusty_Metal"
    },
    {
      "x": -14,
      "y": 1,
      "z": 5,
      "name": "Rock_Rusty_Metal"
    },
    {
      "x": -14,
      "y": 2,
      "z": 5,
      "name": "Rock_Rusty_Metal"
    },
    {
      "x": -14,
      "y": -1,
      "z": 6,
      "name": "Rock_Dark_Rusty_Metal"
    },
    {
      "x": -14,
      "y": 0,
      "z": 6,
      "name": "Rock_Dark_Rusty_Metal"
    },
    {
      "x": -14,
      "y": 1,
      "z": 6,
      "name": "Rock_Dark_Rusty_Metal"
    },
    {
      "x": -14,
      "y": 2,
      "z": 6,
      "name": "Rock_Dark_Rusty_Metal"
    },
    {
      "x": -13,
      "y": -1,
      "z": -8,
      "name": "Rock_Rusty_Metal"
    },
    {
      "x": -13,
      "y": 0,
      "z": -8,
      "name": "Rock_Rusty_Metal"
    },
    {
      "x": -13,
      "y": 1,
      "z": -8,
      "name": "Rock_Rusty_Metal"
    },
    {
      "x": -13,
      "y": 2,
      "z": -8,
      "name": "Rock_Rusty_Metal"
    },
    {
      "x": -13,
      "y": -1,
      "z": -7,
      "name": "Rock_Rusty_Metal"
    },
    {
      "x": -13,
      "y": 0,
      "z": -7,
      "name": "Rock_Rusty_Metal"
    },
    {
      "x": -13,
      "y": 1,
      "z": -7,
      "name": "Rock_Rusty_Metal"
    },
    {
      "x": -13,
      "y": 2,
      "z": -7,
      "name": "Rock_Rusty_Metal"
    },
    {
      "x": -13,
      "y": -1,
      "z": -6,
      "name": "Rock_Rusty_Metal"
    },
    {
      "x": -13,
      "y": 5,
      "z": -6,
      "name": "Rock_Dark_Rusty_Metal"
    },
    {
      "x": -13,
      "y": 6,
      "z": -6,
      "name": "Rock_Dark_Rusty_Metal"
    },
    {
      "x": -13,
      "y": 7,
      "z": -6,
      "name": "Rock_Dark_Rusty_Metal"
    },
    {
      "x": -13,
      "y": 8,
      "z": -6,
      "name": "Rock_Dark_Rusty_Metal"
    },
    {
      "x": -13,
      "y": 12,
      "z": -6,
      "name": "Rock_Dark_Rusty_Metal"
    },
    {
      "x": -13,
      "y": 13,
      "z": -6,
      "name": "Rock_Dark_Rusty_Metal"
    },
    {
      "x": -13,
      "y": -1,
      "z": -5,
      "name": "Rock_Rusty_Metal"
    },
    {
      "x": -13,
      "y": 5,
      "z": -5,
      "name": "Rock_Dark_Rusty_Metal"
    },
    {
      "x": -13,
      "y": 6,
      "z": -5,
      "name": "Rock_Dark_Rusty_Metal"
    },
    {
      "x": -13,
      "y": 7,
      "z": -5,
      "name": "Rock_Dark_Rusty_Metal"
    },
    {
      "x": -13,
      "y": 8,
      "z": -5,
      "name": "Rock_Dark_Rusty_Metal"
    },
    {
      "x": -13,
      "y": 12,
      "z": -5,
      "name": "Rock_Dark_Rusty_Metal"
    },
    {
      "x": -13,
      "y": 13,
      "z": -5,
      "name": "Rock_Dark_Rusty_Metal"
    },
    {
      "x": -13,
      "y": 14,
      "z": -5,
      "name": "Rock_Dark_Rusty_Metal"
    },
    {
      "x": -13,
      "y": 15,
      "z": -5,
      "name": "Rock_Dark_Rusty_Metal"
    },
    {
      "x": -13,
      "y": -1,
      "z": -4,
      "name": "Rock_Rusty_Metal"
    },
    {
      "x": -13,
      "y": 5,
      "z": -4,
      "name": "Rock_Dark_Rusty_Metal"
    },
    {
      "x": -13,
      "y": 6,
      "z": -4,
      "name": "Rock_Dark_Rusty_Metal"
    },
    {
      "x": -13,
      "y": 7,
      "z": -4,
      "name": "Rock_Dark_Rusty_Metal"
    },
    {
      "x": -13,
      "y": 8,
      "z": -4,
      "name": "Rock_Dark_Rusty_Metal"
    },
    {
      "x": -13,
      "y": 12,
      "z": -4,
      "name": "Rock_Dark_Rusty_Metal"
    },
    {
      "x": -13,
      "y": 13,
      "z": -4,
      "name": "Rock_Dark_Rusty_Metal"
    },
    {
      "x": -13,
      "y": 14,
      "z": -4,
      "name": "Rock_Dark_Rusty_Metal"
    },
    {
      "x": -13,
      "y": 15,
      "z": -4,
      "name": "Rock_Dark_Rusty_Metal"
    },
    {
      "x": -13,
      "y": 16,
      "z": -4,
      "name": "Rock_Dark_Rusty_Metal"
    },
    {
      "x": -13,
      "y": -1,
      "z": -3,
      "name": "Rock_Rusty_Metal"
    },
    {
      "x": -13,
      "y": 8,
      "z": -3,
      "name": "Rock_Dark_Rusty_Metal"
    },
    {
      "x": -13,
      "y": 9,
      "z": -3,
      "name": "Rock_Dark_Rusty_Metal"
    },
    {
      "x": -13,
      "y": 10,
      "z": -3,
      "name": "Rock_Dark_Rusty_Metal"
    },
    {
      "x": -13,
      "y": 11,
      "z": -3,
      "name": "Rock_Dark_Rusty_Metal"
    },
    {
      "x": -13,
      "y": 12,
      "z": -3,
      "name": "Rock_Dark_Rusty_Metal"
    },
    {
      "x": -13,
      "y": 13,
      "z": -3,
      "name": "Rock_Dark_Rusty_Metal"
    },
    {
      "x": -13,
      "y": 14,
      "z": -3,
      "name": "Rock_Dark_Rusty_Metal"
    },
    {
      "x": -13,
      "y": 15,
      "z": -3,
      "name": "Rock_Dark_Rusty_Metal"
    },
    {
      "x": -13,
      "y": 16,
      "z": -3,
      "name": "Rock_Dark_Rusty_Metal"
    },
    {
      "x": -13,
      "y": 17,
      "z": -3,
      "name": "Rock_Dark_Rusty_Metal"
    },
    {
      "x": -13,
      "y": -1,
      "z": -2,
      "name": "Rock_Rusty_Metal"
    },
    {
      "x": -13,
      "y": 11,
      "z": -2,
      "name": "Rock_Dark_Rusty_Metal"
    },
    {
      "x": -13,
      "y": 12,
      "z": -2,
      "name": "Rock_Dark_Rusty_Metal"
    },
    {
      "x": -13,
      "y": 13,
      "z": -2,
      "name": "Rock_Dark_Rusty_Metal"
    },
    {
      "x": -13,
      "y": 14,
      "z": -2,
      "name": "Rock_Dark_Rusty_Metal"
    },
    {
      "x": -13,
      "y": 15,
      "z": -2,
      "name": "Rock_Dark_Rusty_Metal"
    },
    {
      "x": -13,
      "y": 16,
      "z": -2,
      "name": "Rock_Dark_Rusty_Metal"
    },
    {
      "x": -13,
      "y": 17,
      "z": -2,
      "name": "Rock_Dark_Rusty_Metal"
    },
    {
      "x": -13,
      "y": -1,
      "z": -1,
      "name": "Rock_Rusty_Metal"
    },
    {
      "x": -13,
      "y": 11,
      "z": -1,
      "name": "Rock_Dark_Rusty_Metal"
    },
    {
      "x": -13,
      "y": 12,
      "z": -1,
      "name": "Rock_Bronze_Metal"
    },
    {
      "x": -13,
      "y": 13,
      "z": -1,
      "name": "Rock_Bronze_Metal"
    },
    {
      "x": -13,
      "y": 14,
      "z": -1,
      "name": "Rock_Bronze_Metal"
    },
    {
      "x": -13,
      "y": 15,
      "z": -1,
      "name": "Rock_Bronze_Metal"
    },
    {
      "x": -13,
      "y": 16,
      "z": -1,
      "name": "Rock_Bronze_Metal"
    },
    {
      "x": -13,
      "y": 17,
      "z": -1,
      "name": "Rock_Bronze_Metal"
    },
    {
      "x": -13,
      "y": 18,
      "z": -1,
      "name": "Rock_Bronze_Metal"
    },
    {
      "x": -13,
      "y": 19,
      "z": -1,
      "name": "Rock_Bronze_Metal"
    },
    {
      "x": -13,
      "y": 20,
      "z": -1,
      "name": "Rock_Bronze_Metal"
    },
    {
      "x": -13,
      "y": 21,
      "z": -1,
      "name": "Rock_Bronze_Metal"
    },
    {
      "x": -13,
      "y": 22,
      "z": -1,
      "name": "Rock_Bronze_Metal"
    },
    {
      "x": -13,
      "y": -1,
      "z": 0,
      "name": "Rock_Rusty_Metal"
    },
    {
      "x": -13,
      "y": 11,
      "z": 0,
      "name": "Rock_Dark_Rusty_Metal"
    },
    {
      "x": -13,
      "y": 12,
      "z": 0,
      "name": "Rock_Bronze_Metal"
    },
    {
      "x": -13,
      "y": 13,
      "z": 0,
      "name": "Rock_Bronze_Metal"
    },
    {
      "x": -13,
      "y": 14,
      "z": 0,
      "name": "Rock_Bronze_Metal"
    },
    {
      "x": -13,
      "y": 15,
      "z": 0,
      "name": "Rock_Bronze_Metal"
    },
    {
      "x": -13,
      "y": 16,
      "z": 0,
      "name": "Rock_Bronze_Metal"
    },
    {
      "x": -13,
      "y": 17,
      "z": 0,
      "name": "Rock_Bronze_Metal"
    },
    {
      "x": -13,
      "y": 18,
      "z": 0,
      "name": "Rock_Bronze_Metal"
    },
    {
      "x": -13,
      "y": 19,
      "z": 0,
      "name": "Rock_Bronze_Metal"
    },
    {
      "x": -13,
      "y": 20,
      "z": 0,
      "name": "Rock_Bronze_Metal"
    },
    {
      "x": -13,
      "y": 21,
      "z": 0,
      "name": "Rock_Bronze_Metal"
    },
    {
      "x": -13,
      "y": 22,
      "z": 0,
      "name": "Rock_Bronze_Metal"
    },
    {
      "x": -13,
      "y": 23,
      "z": 0,
      "name": "Rock_Bronze_Metal"
    },
    {
      "x": -13,
      "y": -1,
      "z": 1,
      "name": "Rock_Rusty_Metal"
    },
    {
      "x": -13,
      "y": 11,
      "z": 1,
      "name": "Rock_Dark_Rusty_Metal"
    },
    {
      "x": -13,
      "y": 12,
      "z": 1,
      "name": "Rock_Bronze_Metal"
    },
    {
      "x": -13,
      "y": 13,
      "z": 1,
      "name": "Rock_Bronze_Metal"
    },
    {
      "x": -13,
      "y": 14,
      "z": 1,
      "name": "Rock_Bronze_Metal"
    },
    {
      "x": -13,
      "y": 15,
      "z": 1,
      "name": "Rock_Bronze_Metal"
    },
    {
      "x": -13,
      "y": 16,
      "z": 1,
      "name": "Rock_Bronze_Metal"
    },
    {
      "x": -13,
      "y": 17,
      "z": 1,
      "name": "Rock_Bronze_Metal"
    },
    {
      "x": -13,
      "y": 18,
      "z": 1,
      "name": "Rock_Bronze_Metal"
    },
    {
      "x": -13,
      "y": 19,
      "z": 1,
      "name": "Rock_Bronze_Metal"
    },
    {
      "x": -13,
      "y": 20,
      "z": 1,
      "name": "Rock_Bronze_Metal"
    },
    {
      "x": -13,
      "y": 21,
      "z": 1,
      "name": "Rock_Bronze_Metal"
    },
    {
      "x": -13,
      "y": 22,
      "z": 1,
      "name": "Rock_Bronze_Metal"
    },
    {
      "x": -13,
      "y": -1,
      "z": 2,
      "name": "Rock_Rusty_Metal"
    },
    {
      "x": -13,
      "y": 11,
      "z": 2,
      "name": "Rock_Dark_Rusty_Metal"
    },
    {
      "x": -13,
      "y": 12,
      "z": 2,
      "name": "Rock_Dark_Rusty_Metal"
    },
    {
      "x": -13,
      "y": 13,
      "z": 2,
      "name": "Rock_Dark_Rusty_Metal"
    },
    {
      "x": -13,
      "y": 14,
      "z": 2,
      "name": "Rock_Dark_Rusty_Metal"
    },
    {
      "x": -13,
      "y": 15,
      "z": 2,
      "name": "Rock_Dark_Rusty_Metal"
    },
    {
      "x": -13,
      "y": 16,
      "z": 2,
      "name": "Rock_Dark_Rusty_Metal"
    },
    {
      "x": -13,
      "y": 17,
      "z": 2,
      "name": "Rock_Dark_Rusty_Metal"
    },
    {
      "x": -13,
      "y": -1,
      "z": 3,
      "name": "Rock_Rusty_Metal"
    },
    {
      "x": -13,
      "y": 8,
      "z": 3,
      "name": "Rock_Dark_Rusty_Metal"
    },
    {
      "x": -13,
      "y": 9,
      "z": 3,
      "name": "Rock_Dark_Rusty_Metal"
    },
    {
      "x": -13,
      "y": 10,
      "z": 3,
      "name": "Rock_Dark_Rusty_Metal"
    },
    {
      "x": -13,
      "y": 11,
      "z": 3,
      "name": "Rock_Dark_Rusty_Metal"
    },
    {
      "x": -13,
      "y": 12,
      "z": 3,
      "name": "Rock_Dark_Rusty_Metal"
    },
    {
      "x": -13,
      "y": 13,
      "z": 3,
      "name": "Rock_Dark_Rusty_Metal"
    },
    {
      "x": -13,
      "y": 14,
      "z": 3,
      "name": "Rock_Dark_Rusty_Metal"
    },
    {
      "x": -13,
      "y": 15,
      "z": 3,
      "name": "Rock_Dark_Rusty_Metal"
    },
    {
      "x": -13,
      "y": 16,
      "z": 3,
      "name": "Rock_Dark_Rusty_Metal"
    },
    {
      "x": -13,
      "y": 17,
      "z": 3,
      "name": "Rock_Dark_Rusty_Metal"
    },
    {
      "x": -13,
      "y": -1,
      "z": 4,
      "name": "Rock_Rusty_Metal"
    },
    {
      "x": -13,
      "y": 5,
      "z": 4,
      "name": "Rock_Dark_Rusty_Metal"
    },
    {
      "x": -13,
      "y": 6,
      "z": 4,
      "name": "Rock_Dark_Rusty_Metal"
    },
    {
      "x": -13,
      "y": 7,
      "z": 4,
      "name": "Rock_Dark_Rusty_Metal"
    },
    {
      "x": -13,
      "y": 8,
      "z": 4,
      "name": "Rock_Dark_Rusty_Metal"
    },
    {
      "x": -13,
      "y": 12,
      "z": 4,
      "name": "Rock_Dark_Rusty_Metal"
    },
    {
      "x": -13,
      "y": 13,
      "z": 4,
      "name": "Rock_Dark_Rusty_Metal"
    },
    {
      "x": -13,
      "y": 14,
      "z": 4,
      "name": "Rock_Dark_Rusty_Metal"
    },
    {
      "x": -13,
      "y": 15,
      "z": 4,
      "name": "Rock_Dark_Rusty_Metal"
    },
    {
      "x": -13,
      "y": 16,
      "z": 4,
      "name": "Rock_Dark_Rusty_Metal"
    },
    {
      "x": -13,
      "y": -1,
      "z": 5,
      "name": "Rock_Rusty_Metal"
    },
    {
      "x": -13,
      "y": 5,
      "z": 5,
      "name": "Rock_Dark_Rusty_Metal"
    },
    {
      "x": -13,
      "y": 6,
      "z": 5,
      "name": "Rock_Dark_Rusty_Metal"
    },
    {
      "x": -13,
      "y": 7,
      "z": 5,
      "name": "Rock_Dark_Rusty_Metal"
    },
    {
      "x": -13,
      "y": 8,
      "z": 5,
      "name": "Rock_Dark_Rusty_Metal"
    },
    {
      "x": -13,
      "y": 12,
      "z": 5,
      "name": "Rock_Dark_Rusty_Metal"
    },
    {
      "x": -13,
      "y": 13,
      "z": 5,
      "name": "Rock_Dark_Rusty_Metal"
    },
    {
      "x": -13,
      "y": 14,
      "z": 5,
      "name": "Rock_Dark_Rusty_Metal"
    },
    {
      "x": -13,
      "y": 15,
      "z": 5,
      "name": "Rock_Dark_Rusty_Metal"
    },
    {
      "x": -13,
      "y": -1,
      "z": 6,
      "name": "Rock_Rusty_Metal"
    },
    {
      "x": -13,
      "y": 5,
      "z": 6,
      "name": "Rock_Dark_Rusty_Metal"
    },
    {
      "x": -13,
      "y": 6,
      "z": 6,
      "name": "Rock_Dark_Rusty_Metal"
    },
    {
      "x": -13,
      "y": 7,
      "z": 6,
      "name": "Rock_Dark_Rusty_Metal"
    },
    {
      "x": -13,
      "y": 8,
      "z": 6,
      "name": "Rock_Dark_Rusty_Metal"
    },
    {
      "x": -13,
      "y": 12,
      "z": 6,
      "name": "Rock_Dark_Rusty_Metal"
    },
    {
      "x": -13,
      "y": 13,
      "z": 6,
      "name": "Rock_Dark_Rusty_Metal"
    },
    {
      "x": -13,
      "y": -1,
      "z": 7,
      "name": "Rock_Rusty_Metal"
    },
    {
      "x": -13,
      "y": 0,
      "z": 7,
      "name": "Rock_Rusty_Metal"
    },
    {
      "x": -13,
      "y": 1,
      "z": 7,
      "name": "Rock_Rusty_Metal"
    },
    {
      "x": -13,
      "y": 2,
      "z": 7,
      "name": "Rock_Rusty_Metal"
    },
    {
      "x": -13,
      "y": -1,
      "z": 8,
      "name": "Rock_Rusty_Metal"
    },
    {
      "x": -13,
      "y": 0,
      "z": 8,
      "name": "Rock_Rusty_Metal"
    },
    {
      "x": -13,
      "y": 1,
      "z": 8,
      "name": "Rock_Rusty_Metal"
    },
    {
      "x": -13,
      "y": 2,
      "z": 8,
      "name": "Rock_Rusty_Metal"
    },
    {
      "x": -12,
      "y": -1,
      "z": -9,
      "name": "Rock_Rusty_Metal"
    },
    {
      "x": -12,
      "y": 0,
      "z": -9,
      "name": "Rock_Rusty_Metal"
    },
    {
      "x": -12,
      "y": 1,
      "z": -9,
      "name": "Rock_Rusty_Metal"
    },
    {
      "x": -12,
      "y": 2,
      "z": -9,
      "name": "Rock_Rusty_Metal"
    },
    {
      "x": -12,
      "y": -1,
      "z": -8,
      "name": "Rock_Rusty_Metal"
    },
    {
      "x": -12,
      "y": 5,
      "z": -8,
      "name": "Rock_Dark_Rusty_Metal"
    },
    {
      "x": -12,
      "y": 6,
      "z": -8,
      "name": "Rock_Dark_Rusty_Metal"
    },
    {
      "x": -12,
      "y": 7,
      "z": -8,
      "name": "Rock_Dark_Rusty_Metal"
    },
    {
      "x": -12,
      "y": 8,
      "z": -8,
      "name": "Rock_Dark_Rusty_Metal"
    },
    {
      "x": -12,
      "y": 9,
      "z": -8,
      "name": "Rock_Dark_Rusty_Metal"
    },
    {
      "x": -12,
      "y": 10,
      "z": -8,
      "name": "Rock_Dark_Rusty_Metal"
    },
    {
      "x": -12,
      "y": 11,
      "z": -8,
      "name": "Rock_Dark_Rusty_Metal"
    },
    {
      "x": -12,
      "y": -1,
      "z": -7,
      "name": "Rock_Rusty_Metal"
    },
    {
      "x": -12,
      "y": 5,
      "z": -7,
      "name": "Rock_Dark_Rusty_Metal"
    },
    {
      "x": -12,
      "y": 6,
      "z": -7,
      "name": "Rock_Dark_Rusty_Metal"
    },
    {
      "x": -12,
      "y": 7,
      "z": -7,
      "name": "Rock_Dark_Rusty_Metal"
    },
    {
      "x": -12,
      "y": 8,
      "z": -7,
      "name": "Rock_Dark_Rusty_Metal"
    },
    {
      "x": -12,
      "y": 9,
      "z": -7,
      "name": "Rock_Dark_Rusty_Metal"
    },
    {
      "x": -12,
      "y": 10,
      "z": -7,
      "name": "Rock_Dark_Rusty_Metal"
    },
    {
      "x": -12,
      "y": 11,
      "z": -7,
      "name": "Rock_Dark_Rusty_Metal"
    },
    {
      "x": -12,
      "y": 12,
      "z": -7,
      "name": "Rock_Dark_Rusty_Metal"
    },
    {
      "x": -12,
      "y": 13,
      "z": -7,
      "name": "Rock_Dark_Rusty_Metal"
    },
    {
      "x": -12,
      "y": 14,
      "z": -7,
      "name": "Rock_Dark_Rusty_Metal"
    },
    {
      "x": -12,
      "y": 15,
      "z": -7,
      "name": "Rock_Dark_Rusty_Metal"
    },
    {
      "x": -12,
      "y": -1,
      "z": -6,
      "name": "Rock_Rusty_Metal"
    },
    {
      "x": -12,
      "y": 8,
      "z": -6,
      "name": "Rock_Dark_Rusty_Metal"
    },
    {
      "x": -12,
      "y": 9,
      "z": -6,
      "name": "Rock_Bronze_Metal"
    },
    {
      "x": -12,
      "y": 10,
      "z": -6,
      "name": "Rock_Bronze_Metal"
    },
    {
      "x": -12,
      "y": 11,
      "z": -6,
      "name": "Rock_Bronze_Metal"
    },
    {
      "x": -12,
      "y": 12,
      "z": -6,
      "name": "Rock_Dark_Rusty_Metal"
    },
    {
      "x": -12,
      "y": 13,
      "z": -6,
      "name": "Rock_Dark_Rusty_Metal"
    },
    {
      "x": -12,
      "y": 14,
      "z": -6,
      "name": "Rock_Dark_Rusty_Metal"
    },
    {
      "x": -12,
      "y": 15,
      "z": -6,
      "name": "Rock_Dark_Rusty_Metal"
    },
    {
      "x": -12,
      "y": 16,
      "z": -6,
      "name": "Rock_Dark_Rusty_Metal"
    },
    {
      "x": -12,
      "y": -1,
      "z": -5,
      "name": "Rock_Rusty_Metal"
    },
    {
      "x": -12,
      "y": 8,
      "z": -5,
      "name": "Rock_Dark_Rusty_Metal"
    },
    {
      "x": -12,
      "y": 9,
      "z": -5,
      "name": "Rock_Bronze_Metal"
    },
    {
      "x": -12,
      "y": 10,
      "z": -5,
      "name": "Rock_Crystal_Yellow_Block",
      "rotation": 4
    },
    {
      "x": -12,
      "y": 11,
      "z": -5,
      "name": "Rock_Bronze_Metal"
    },
    {
      "x": -12,
      "y": 12,
      "z": -5,
      "name": "Rock_Dark_Rusty_Metal"
    },
    {
      "x": -12,
      "y": 13,
      "z": -5,
      "name": "Rock_Dark_Rusty_Metal"
    },
    {
      "x": -12,
      "y": 14,
      "z": -5,
      "name": "Rock_Dark_Rusty_Metal"
    },
    {
      "x": -12,
      "y": 15,
      "z": -5,
      "name": "Rock_Dark_Rusty_Metal"
    },
    {
      "x": -12,
      "y": 16,
      "z": -5,
      "name": "Rock_Dark_Rusty_Metal"
    },
    {
      "x": -12,
      "y": 17,
      "z": -5,
      "name": "Rock_Dark_Rusty_Metal"
    },
    {
      "x": -12,
      "y": -1,
      "z": -4,
      "name": "Rock_Rusty_Metal"
    },
    {
      "x": -12,
      "y": 8,
      "z": -4,
      "name": "Rock_Dark_Rusty_Metal"
    },
    {
      "x": -12,
      "y": 9,
      "z": -4,
      "name": "Rock_Bronze_Metal"
    },
    {
      "x": -12,
      "y": 10,
      "z": -4,
      "name": "Rock_Bronze_Metal"
    },
    {
      "x": -12,
      "y": 11,
      "z": -4,
      "name": "Rock_Bronze_Metal"
    },
    {
      "x": -12,
      "y": 12,
      "z": -4,
      "name": "Rock_Dark_Rusty_Metal"
    },
    {
      "x": -12,
      "y": 13,
      "z": -4,
      "name": "Rock_Dark_Rusty_Metal"
    },
    {
      "x": -12,
      "y": 14,
      "z": -4,
      "name": "Rock_Dark_Rusty_Metal"
    },
    {
      "x": -12,
      "y": 15,
      "z": -4,
      "name": "Rock_Dark_Rusty_Metal"
    },
    {
      "x": -12,
      "y": 16,
      "z": -4,
      "name": "Rock_Dark_Rusty_Metal"
    },
    {
      "x": -12,
      "y": 17,
      "z": -4,
      "name": "Rock_Dark_Rusty_Metal"
    },
    {
      "x": -12,
      "y": 18,
      "z": -4,
      "name": "Rock_Dark_Rusty_Metal"
    },
    {
      "x": -12,
      "y": -1,
      "z": -3,
      "name": "Rock_Rusty_Metal"
    },
    {
      "x": -12,
      "y": 8,
      "z": -3,
      "name": "Rock_Dark_Rusty_Metal"
    },
    {
      "x": -12,
      "y": 9,
      "z": -3,
      "name": "Rock_Dark_Rusty_Metal"
    },
    {
      "x": -12,
      "y": 10,
      "z": -3,
      "name": "Rock_Dark_Rusty_Metal"
    },
    {
      "x": -12,
      "y": 11,
      "z": -3,
      "name": "Rock_Dark_Rusty_Metal"
    },
    {
      "x": -12,
      "y": 12,
      "z": -3,
      "name": "Rock_Dark_Rusty_Metal"
    },
    {
      "x": -12,
      "y": 13,
      "z": -3,
      "name": "Rock_Dark_Rusty_Metal"
    },
    {
      "x": -12,
      "y": 14,
      "z": -3,
      "name": "Rock_Dark_Rusty_Metal"
    },
    {
      "x": -12,
      "y": 15,
      "z": -3,
      "name": "Rock_Dark_Rusty_Metal"
    },
    {
      "x": -12,
      "y": 16,
      "z": -3,
      "name": "Rock_Dark_Rusty_Metal"
    },
    {
      "x": -12,
      "y": 17,
      "z": -3,
      "name": "Rock_Dark_Rusty_Metal"
    },
    {
      "x": -12,
      "y": 18,
      "z": -3,
      "name": "Rock_Dark_Rusty_Metal"
    },
    {
      "x": -12,
      "y": -1,
      "z": -2,
      "name": "Rock_Rusty_Metal"
    },
    {
      "x": -12,
      "y": 12,
      "z": -2,
      "name": "Rock_Dark_Rusty_Metal"
    },
    {
      "x": -12,
      "y": 13,
      "z": -2,
      "name": "Rock_Dark_Rusty_Metal"
    },
    {
      "x": -12,
      "y": 14,
      "z": -2,
      "name": "Rock_Dark_Rusty_Metal"
    },
    {
      "x": -12,
      "y": 15,
      "z": -2,
      "name": "Rock_Dark_Rusty_Metal"
    },
    {
      "x": -12,
      "y": 16,
      "z": -2,
      "name": "Rock_Dark_Rusty_Metal"
    },
    {
      "x": -12,
      "y": 17,
      "z": -2,
      "name": "Rock_Dark_Rusty_Metal"
    },
    {
      "x": -12,
      "y": 18,
      "z": -2,
      "name": "Rock_Dark_Rusty_Metal"
    },
    {
      "x": -12,
      "y": 19,
      "z": -2,
      "name": "Rock_Dark_Rusty_Metal"
    },
    {
      "x": -12,
      "y": -1,
      "z": -1,
      "name": "Rock_Rusty_Metal"
    },
    {
      "x": -12,
      "y": 12,
      "z": -1,
      "name": "Rock_Dark_Rusty_Metal"
    },
    {
      "x": -12,
      "y": 13,
      "z": -1,
      "name": "Rock_Dark_Rusty_Metal"
    },
    {
      "x": -12,
      "y": 14,
      "z": -1,
      "name": "Rock_Dark_Rusty_Metal"
    },
    {
      "x": -12,
      "y": 15,
      "z": -1,
      "name": "Rock_Bronze_Metal"
    },
    {
      "x": -12,
      "y": 16,
      "z": -1,
      "name": "Rock_Bronze_Metal"
    },
    {
      "x": -12,
      "y": 17,
      "z": -1,
      "name": "Rock_Bronze_Metal"
    },
    {
      "x": -12,
      "y": 18,
      "z": -1,
      "name": "Rock_Bronze_Metal"
    },
    {
      "x": -12,
      "y": 19,
      "z": -1,
      "name": "Rock_Bronze_Metal"
    },
    {
      "x": -12,
      "y": 20,
      "z": -1,
      "name": "Rock_Bronze_Metal"
    },
    {
      "x": -12,
      "y": 21,
      "z": -1,
      "name": "Rock_Bronze_Metal"
    },
    {
      "x": -12,
      "y": 22,
      "z": -1,
      "name": "Rock_Bronze_Metal"
    },
    {
      "x": -12,
      "y": -1,
      "z": 0,
      "name": "Rock_Rusty_Metal"
    },
    {
      "x": -12,
      "y": 12,
      "z": 0,
      "name": "Rock_Dark_Rusty_Metal"
    },
    {
      "x": -12,
      "y": 13,
      "z": 0,
      "name": "Rock_Dark_Rusty_Metal"
    },
    {
      "x": -12,
      "y": 14,
      "z": 0,
      "name": "Rock_Dark_Rusty_Metal"
    },
    {
      "x": -12,
      "y": 15,
      "z": 0,
      "name": "Rock_Bronze_Metal"
    },
    {
      "x": -12,
      "y": 16,
      "z": 0,
      "name": "Rock_Bronze_Metal"
    },
    {
      "x": -12,
      "y": 17,
      "z": 0,
      "name": "Rock_Bronze_Metal"
    },
    {
      "x": -12,
      "y": 18,
      "z": 0,
      "name": "Rock_Bronze_Metal"
    },
    {
      "x": -12,
      "y": 19,
      "z": 0,
      "name": "Rock_Bronze_Metal"
    },
    {
      "x": -12,
      "y": 20,
      "z": 0,
      "name": "Rock_Bronze_Metal"
    },
    {
      "x": -12,
      "y": 21,
      "z": 0,
      "name": "Rock_Bronze_Metal"
    },
    {
      "x": -12,
      "y": 22,
      "z": 0,
      "name": "Rock_Bronze_Metal"
    },
    {
      "x": -12,
      "y": 23,
      "z": 0,
      "name": "Rock_Bronze_Metal"
    },
    {
      "x": -12,
      "y": -1,
      "z": 1,
      "name": "Rock_Rusty_Metal"
    },
    {
      "x": -12,
      "y": 12,
      "z": 1,
      "name": "Rock_Dark_Rusty_Metal"
    },
    {
      "x": -12,
      "y": 13,
      "z": 1,
      "name": "Rock_Dark_Rusty_Metal"
    },
    {
      "x": -12,
      "y": 14,
      "z": 1,
      "name": "Rock_Dark_Rusty_Metal"
    },
    {
      "x": -12,
      "y": 15,
      "z": 1,
      "name": "Rock_Bronze_Metal"
    },
    {
      "x": -12,
      "y": 16,
      "z": 1,
      "name": "Rock_Bronze_Metal"
    },
    {
      "x": -12,
      "y": 17,
      "z": 1,
      "name": "Rock_Bronze_Metal"
    },
    {
      "x": -12,
      "y": 18,
      "z": 1,
      "name": "Rock_Bronze_Metal"
    },
    {
      "x": -12,
      "y": 19,
      "z": 1,
      "name": "Rock_Bronze_Metal"
    },
    {
      "x": -12,
      "y": 20,
      "z": 1,
      "name": "Rock_Bronze_Metal"
    },
    {
      "x": -12,
      "y": 21,
      "z": 1,
      "name": "Rock_Bronze_Metal"
    },
    {
      "x": -12,
      "y": 22,
      "z": 1,
      "name": "Rock_Bronze_Metal"
    },
    {
      "x": -12,
      "y": -1,
      "z": 2,
      "name": "Rock_Rusty_Metal"
    },
    {
      "x": -12,
      "y": 12,
      "z": 2,
      "name": "Rock_Dark_Rusty_Metal"
    },
    {
      "x": -12,
      "y": 13,
      "z": 2,
      "name": "Rock_Dark_Rusty_Metal"
    },
    {
      "x": -12,
      "y": 14,
      "z": 2,
      "name": "Rock_Dark_Rusty_Metal"
    },
    {
      "x": -12,
      "y": 15,
      "z": 2,
      "name": "Rock_Dark_Rusty_Metal"
    },
    {
      "x": -12,
      "y": 16,
      "z": 2,
      "name": "Rock_Dark_Rusty_Metal"
    },
    {
      "x": -12,
      "y": 17,
      "z": 2,
      "name": "Rock_Dark_Rusty_Metal"
    },
    {
      "x": -12,
      "y": 18,
      "z": 2,
      "name": "Rock_Dark_Rusty_Metal"
    },
    {
      "x": -12,
      "y": 19,
      "z": 2,
      "name": "Rock_Dark_Rusty_Metal"
    },
    {
      "x": -12,
      "y": -1,
      "z": 3,
      "name": "Rock_Rusty_Metal"
    },
    {
      "x": -12,
      "y": 8,
      "z": 3,
      "name": "Rock_Dark_Rusty_Metal"
    },
    {
      "x": -12,
      "y": 9,
      "z": 3,
      "name": "Rock_Dark_Rusty_Metal"
    },
    {
      "x": -12,
      "y": 10,
      "z": 3,
      "name": "Rock_Dark_Rusty_Metal"
    },
    {
      "x": -12,
      "y": 11,
      "z": 3,
      "name": "Rock_Dark_Rusty_Metal"
    },
    {
      "x": -12,
      "y": 12,
      "z": 3,
      "name": "Rock_Dark_Rusty_Metal"
    },
    {
      "x": -12,
      "y": 13,
      "z": 3,
      "name": "Rock_Dark_Rusty_Metal"
    },
    {
      "x": -12,
      "y": 14,
      "z": 3,
      "name": "Rock_Dark_Rusty_Metal"
    },
    {
      "x": -12,
      "y": 15,
      "z": 3,
      "name": "Rock_Dark_Rusty_Metal"
    },
    {
      "x": -12,
      "y": 16,
      "z": 3,
      "name": "Rock_Dark_Rusty_Metal"
    },
    {
      "x": -12,
      "y": 17,
      "z": 3,
      "name": "Rock_Dark_Rusty_Metal"
    },
    {
      "x": -12,
      "y": 18,
      "z": 3,
      "name": "Rock_Dark_Rusty_Metal"
    },
    {
      "x": -12,
      "y": -1,
      "z": 4,
      "name": "Rock_Rusty_Metal"
    },
    {
      "x": -12,
      "y": 8,
      "z": 4,
      "name": "Rock_Dark_Rusty_Metal"
    },
    {
      "x": -12,
      "y": 9,
      "z": 4,
      "name": "Rock_Bronze_Metal"
    },
    {
      "x": -12,
      "y": 10,
      "z": 4,
      "name": "Rock_Bronze_Metal"
    },
    {
      "x": -12,
      "y": 11,
      "z": 4,
      "name": "Rock_Bronze_Metal"
    },
    {
      "x": -12,
      "y": 12,
      "z": 4,
      "name": "Rock_Dark_Rusty_Metal"
    },
    {
      "x": -12,
      "y": 13,
      "z": 4,
      "name": "Rock_Dark_Rusty_Metal"
    },
    {
      "x": -12,
      "y": 14,
      "z": 4,
      "name": "Rock_Dark_Rusty_Metal"
    },
    {
      "x": -12,
      "y": 15,
      "z": 4,
      "name": "Rock_Dark_Rusty_Metal"
    },
    {
      "x": -12,
      "y": 16,
      "z": 4,
      "name": "Rock_Dark_Rusty_Metal"
    },
    {
      "x": -12,
      "y": 17,
      "z": 4,
      "name": "Rock_Dark_Rusty_Metal"
    },
    {
      "x": -12,
      "y": 18,
      "z": 4,
      "name": "Rock_Dark_Rusty_Metal"
    },
    {
      "x": -12,
      "y": -1,
      "z": 5,
      "name": "Rock_Rusty_Metal"
    },
    {
      "x": -12,
      "y": 8,
      "z": 5,
      "name": "Rock_Dark_Rusty_Metal"
    },
    {
      "x": -12,
      "y": 9,
      "z": 5,
      "name": "Rock_Bronze_Metal"
    },
    {
      "x": -12,
      "y": 10,
      "z": 5,
      "name": "Rock_Crystal_Yellow_Block",
      "rotation": 4
    },
    {
      "x": -12,
      "y": 11,
      "z": 5,
      "name": "Rock_Bronze_Metal"
    },
    {
      "x": -12,
      "y": 12,
      "z": 5,
      "name": "Rock_Dark_Rusty_Metal"
    },
    {
      "x": -12,
      "y": 13,
      "z": 5,
      "name": "Rock_Dark_Rusty_Metal"
    },
    {
      "x": -12,
      "y": 14,
      "z": 5,
      "name": "Rock_Dark_Rusty_Metal"
    },
    {
      "x": -12,
      "y": 15,
      "z": 5,
      "name": "Rock_Dark_Rusty_Metal"
    },
    {
      "x": -12,
      "y": 16,
      "z": 5,
      "name": "Rock_Dark_Rusty_Metal"
    },
    {
      "x": -12,
      "y": 17,
      "z": 5,
      "name": "Rock_Dark_Rusty_Metal"
    },
    {
      "x": -12,
      "y": -1,
      "z": 6,
      "name": "Rock_Rusty_Metal"
    },
    {
      "x": -12,
      "y": 8,
      "z": 6,
      "name": "Rock_Dark_Rusty_Metal"
    },
    {
      "x": -12,
      "y": 9,
      "z": 6,
      "name": "Rock_Bronze_Metal"
    },
    {
      "x": -12,
      "y": 10,
      "z": 6,
      "name": "Rock_Bronze_Metal"
    },
    {
      "x": -12,
      "y": 11,
      "z": 6,
      "name": "Rock_Bronze_Metal"
    },
    {
      "x": -12,
      "y": 12,
      "z": 6,
      "name": "Rock_Dark_Rusty_Metal"
    },
    {
      "x": -12,
      "y": 13,
      "z": 6,
      "name": "Rock_Dark_Rusty_Metal"
    },
    {
      "x": -12,
      "y": 14,
      "z": 6,
      "name": "Rock_Dark_Rusty_Metal"
    },
    {
      "x": -12,
      "y": 15,
      "z": 6,
      "name": "Rock_Dark_Rusty_Metal"
    },
    {
      "x": -12,
      "y": 16,
      "z": 6,
      "name": "Rock_Dark_Rusty_Metal"
    },
    {
      "x": -12,
      "y": -1,
      "z": 7,
      "name": "Rock_Rusty_Metal"
    },
    {
      "x": -12,
      "y": 5,
      "z": 7,
      "name": "Rock_Dark_Rusty_Metal"
    },
    {
      "x": -12,
      "y": 6,
      "z": 7,
      "name": "Rock_Dark_Rusty_Metal"
    },
    {
      "x": -12,
      "y": 7,
      "z": 7,
      "name": "Rock_Dark_Rusty_Metal"
    },
    {
      "x": -12,
      "y": 8,
      "z": 7,
      "name": "Rock_Dark_Rusty_Metal"
    },
    {
      "x": -12,
      "y": 9,
      "z": 7,
      "name": "Rock_Dark_Rusty_Metal"
    },
    {
      "x": -12,
      "y": 10,
      "z": 7,
      "name": "Rock_Dark_Rusty_Metal"
    },
    {
      "x": -12,
      "y": 11,
      "z": 7,
      "name": "Rock_Dark_Rusty_Metal"
    },
    {
      "x": -12,
      "y": 12,
      "z": 7,
      "name": "Rock_Dark_Rusty_Metal"
    },
    {
      "x": -12,
      "y": 13,
      "z": 7,
      "name": "Rock_Dark_Rusty_Metal"
    },
    {
      "x": -12,
      "y": 14,
      "z": 7,
      "name": "Rock_Dark_Rusty_Metal"
    },
    {
      "x": -12,
      "y": 15,
      "z": 7,
      "name": "Rock_Dark_Rusty_Metal"
    },
    {
      "x": -12,
      "y": -1,
      "z": 8,
      "name": "Rock_Rusty_Metal"
    },
    {
      "x": -12,
      "y": 5,
      "z": 8,
      "name": "Rock_Dark_Rusty_Metal"
    },
    {
      "x": -12,
      "y": 6,
      "z": 8,
      "name": "Rock_Dark_Rusty_Metal"
    },
    {
      "x": -12,
      "y": 7,
      "z": 8,
      "name": "Rock_Dark_Rusty_Metal"
    },
    {
      "x": -12,
      "y": 8,
      "z": 8,
      "name": "Rock_Dark_Rusty_Metal"
    },
    {
      "x": -12,
      "y": 9,
      "z": 8,
      "name": "Rock_Dark_Rusty_Metal"
    },
    {
      "x": -12,
      "y": 10,
      "z": 8,
      "name": "Rock_Dark_Rusty_Metal"
    },
    {
      "x": -12,
      "y": 11,
      "z": 8,
      "name": "Rock_Dark_Rusty_Metal"
    },
    {
      "x": -12,
      "y": -1,
      "z": 9,
      "name": "Rock_Rusty_Metal"
    },
    {
      "x": -12,
      "y": 0,
      "z": 9,
      "name": "Rock_Rusty_Metal"
    },
    {
      "x": -12,
      "y": 1,
      "z": 9,
      "name": "Rock_Rusty_Metal"
    },
    {
      "x": -12,
      "y": 2,
      "z": 9,
      "name": "Rock_Rusty_Metal"
    },
    {
      "x": -11,
      "y": -1,
      "z": -10,
      "name": "Rock_Rusty_Metal"
    },
    {
      "x": -11,
      "y": 0,
      "z": -10,
      "name": "Rock_Rusty_Metal"
    },
    {
      "x": -11,
      "y": 1,
      "z": -10,
      "name": "Rock_Rusty_Metal"
    },
    {
      "x": -11,
      "y": 2,
      "z": -10,
      "name": "Rock_Rusty_Metal"
    },
    {
      "x": -11,
      "y": -1,
      "z": -9,
      "name": "Rock_Rusty_Metal"
    },
    {
      "x": -11,
      "y": 5,
      "z": -9,
      "name": "Rock_Dark_Rusty_Metal"
    },
    {
      "x": -11,
      "y": 6,
      "z": -9,
      "name": "Rock_Dark_Rusty_Metal"
    },
    {
      "x": -11,
      "y": 7,
      "z": -9,
      "name": "Rock_Dark_Rusty_Metal"
    },
    {
      "x": -11,
      "y": 8,
      "z": -9,
      "name": "Rock_Dark_Rusty_Metal"
    },
    {
      "x": -11,
      "y": 9,
      "z": -9,
      "name": "Rock_Dark_Rusty_Metal"
    },
    {
      "x": -11,
      "y": 10,
      "z": -9,
      "name": "Rock_Dark_Rusty_Metal"
    },
    {
      "x": -11,
      "y": 11,
      "z": -9,
      "name": "Rock_Dark_Rusty_Metal"
    },
    {
      "x": -11,
      "y": 12,
      "z": -9,
      "name": "Rock_Dark_Rusty_Metal"
    },
    {
      "x": -11,
      "y": 13,
      "z": -9,
      "name": "Rock_Dark_Rusty_Metal"
    },
    {
      "x": -11,
      "y": 14,
      "z": -9,
      "name": "Rock_Dark_Rusty_Metal"
    },
    {
      "x": -11,
      "y": -1,
      "z": -8,
      "name": "Rock_Rusty_Metal"
    },
    {
      "x": -11,
      "y": 12,
      "z": -8,
      "name": "Rock_Dark_Rusty_Metal"
    },
    {
      "x": -11,
      "y": 13,
      "z": -8,
      "name": "Rock_Dark_Rusty_Metal"
    },
    {
      "x": -11,
      "y": 14,
      "z": -8,
      "name": "Rock_Dark_Rusty_Metal"
    },
    {
      "x": -11,
      "y": 15,
      "z": -8,
      "name": "Rock_Dark_Rusty_Metal"
    },
    {
      "x": -11,
      "y": 16,
      "z": -8,
      "name": "Rock_Dark_Rusty_Metal"
    },
    {
      "x": -11,
      "y": -1,
      "z": -7,
      "name": "Rock_Rusty_Metal"
    },
    {
      "x": -11,
      "y": 12,
      "z": -7,
      "name": "Rock_Dark_Rusty_Metal"
    },
    {
      "x": -11,
      "y": 13,
      "z": -7,
      "name": "Rock_Dark_Rusty_Metal"
    },
    {
      "x": -11,
      "y": 14,
      "z": -7,
      "name": "Rock_Dark_Rusty_Metal"
    },
    {
      "x": -11,
      "y": 15,
      "z": -7,
      "name": "Rock_Dark_Rusty_Metal"
    },
    {
      "x": -11,
      "y": 16,
      "z": -7,
      "name": "Rock_Dark_Rusty_Metal"
    },
    {
      "x": -11,
      "y": 17,
      "z": -7,
      "name": "Rock_Dark_Rusty_Metal"
    },
    {
      "x": -11,
      "y": -1,
      "z": -6,
      "name": "Rock_Rusty_Metal"
    },
    {
      "x": -11,
      "y": 0,
      "z": -6,
      "name": "Rock_Crystal_Red_Medium"
    },
    {
      "x": -11,
      "y": 12,
      "z": -6,
      "name": "Rock_Dark_Rusty_Metal"
    },
    {
      "x": -11,
      "y": 13,
      "z": -6,
      "name": "Rock_Dark_Rusty_Metal"
    },
    {
      "x": -11,
      "y": 14,
      "z": -6,
      "name": "Rock_Dark_Rusty_Metal"
    },
    {
      "x": -11,
      "y": 15,
      "z": -6,
      "name": "Rock_Dark_Rusty_Metal"
    },
    {
      "x": -11,
      "y": 16,
      "z": -6,
      "name": "Rock_Dark_Rusty_Metal"
    },
    {
      "x": -11,
      "y": 17,
      "z": -6,
      "name": "Rock_Dark_Rusty_Metal"
    },
    {
      "x": -11,
      "y": 18,
      "z": -6,
      "name": "Rock_Dark_Rusty_Metal"
    },
    {
      "x": -11,
      "y": -1,
      "z": -5,
      "name": "Rock_Rusty_Metal"
    },
    {
      "x": -11,
      "y": 12,
      "z": -5,
      "name": "Rock_Dark_Rusty_Metal"
    },
    {
      "x": -11,
      "y": 13,
      "z": -5,
      "name": "Rock_Dark_Rusty_Metal"
    },
    {
      "x": -11,
      "y": 14,
      "z": -5,
      "name": "Rock_Dark_Rusty_Metal"
    },
    {
      "x": -11,
      "y": 15,
      "z": -5,
      "name": "Rock_Dark_Rusty_Metal"
    },
    {
      "x": -11,
      "y": 16,
      "z": -5,
      "name": "Rock_Dark_Rusty_Metal"
    },
    {
      "x": -11,
      "y": 17,
      "z": -5,
      "name": "Rock_Dark_Rusty_Metal"
    },
    {
      "x": -11,
      "y": 18,
      "z": -5,
      "name": "Rock_Dark_Rusty_Metal"
    },
    {
      "x": -11,
      "y": 19,
      "z": -5,
      "name": "Rock_Dark_Rusty_Metal"
    },
    {
      "x": -11,
      "y": -1,
      "z": -4,
      "name": "Rock_Rusty_Metal"
    },
    {
      "x": -11,
      "y": 12,
      "z": -4,
      "name": "Rock_Dark_Rusty_Metal"
    },
    {
      "x": -11,
      "y": 13,
      "z": -4,
      "name": "Rock_Dark_Rusty_Metal"
    },
    {
      "x": -11,
      "y": 14,
      "z": -4,
      "name": "Rock_Dark_Rusty_Metal"
    },
    {
      "x": -11,
      "y": 15,
      "z": -4,
      "name": "Rock_Dark_Rusty_Metal"
    },
    {
      "x": -11,
      "y": 16,
      "z": -4,
      "name": "Rock_Dark_Rusty_Metal"
    },
    {
      "x": -11,
      "y": 17,
      "z": -4,
      "name": "Rock_Dark_Rusty_Metal"
    },
    {
      "x": -11,
      "y": 18,
      "z": -4,
      "name": "Rock_Dark_Rusty_Metal"
    },
    {
      "x": -11,
      "y": 19,
      "z": -4,
      "name": "Rock_Dark_Rusty_Metal"
    },
    {
      "x": -11,
      "y": -1,
      "z": -3,
      "name": "Rock_Rusty_Metal"
    },
    {
      "x": -11,
      "y": 12,
      "z": -3,
      "name": "Rock_Dark_Rusty_Metal"
    },
    {
      "x": -11,
      "y": 13,
      "z": -3,
      "name": "Rock_Dark_Rusty_Metal"
    },
    {
      "x": -11,
      "y": 14,
      "z": -3,
      "name": "Rock_Dark_Rusty_Metal"
    },
    {
      "x": -11,
      "y": 15,
      "z": -3,
      "name": "Rock_Dark_Rusty_Metal"
    },
    {
      "x": -11,
      "y": 16,
      "z": -3,
      "name": "Rock_Dark_Rusty_Metal"
    },
    {
      "x": -11,
      "y": 17,
      "z": -3,
      "name": "Rock_Dark_Rusty_Metal"
    },
    {
      "x": -11,
      "y": 18,
      "z": -3,
      "name": "Rock_Dark_Rusty_Metal"
    },
    {
      "x": -11,
      "y": 19,
      "z": -3,
      "name": "Rock_Dark_Rusty_Metal"
    },
    {
      "x": -11,
      "y": 20,
      "z": -3,
      "name": "Rock_Dark_Rusty_Metal"
    },
    {
      "x": -11,
      "y": -1,
      "z": -2,
      "name": "Rock_Rusty_Metal"
    },
    {
      "x": -11,
      "y": 12,
      "z": -2,
      "name": "Rock_Dark_Rusty_Metal"
    },
    {
      "x": -11,
      "y": 13,
      "z": -2,
      "name": "Rock_Dark_Rusty_Metal"
    },
    {
      "x": -11,
      "y": 14,
      "z": -2,
      "name": "Rock_Dark_Rusty_Metal"
    },
    {
      "x": -11,
      "y": 15,
      "z": -2,
      "name": "Rock_Dark_Rusty_Metal"
    },
    {
      "x": -11,
      "y": 16,
      "z": -2,
      "name": "Rock_Dark_Rusty_Metal"
    },
    {
      "x": -11,
      "y": 17,
      "z": -2,
      "name": "Rock_Dark_Rusty_Metal"
    },
    {
      "x": -11,
      "y": 18,
      "z": -2,
      "name": "Rock_Dark_Rusty_Metal"
    },
    {
      "x": -11,
      "y": 19,
      "z": -2,
      "name": "Rock_Dark_Rusty_Metal"
    },
    {
      "x": -11,
      "y": 20,
      "z": -2,
      "name": "Rock_Dark_Rusty_Metal"
    },
    {
      "x": -11,
      "y": -1,
      "z": -1,
      "name": "Rock_Rusty_Metal"
    },
    {
      "x": -11,
      "y": 12,
      "z": -1,
      "name": "Rock_Dark_Rusty_Metal"
    },
    {
      "x": -11,
      "y": 13,
      "z": -1,
      "name": "Rock_Dark_Rusty_Metal"
    },
    {
      "x": -11,
      "y": 14,
      "z": -1,
      "name": "Rock_Dark_Rusty_Metal"
    },
    {
      "x": -11,
      "y": 15,
      "z": -1,
      "name": "Rock_Bronze_Metal"
    },
    {
      "x": -11,
      "y": 16,
      "z": -1,
      "name": "Rock_Bronze_Metal"
    },
    {
      "x": -11,
      "y": 17,
      "z": -1,
      "name": "Rock_Bronze_Metal"
    },
    {
      "x": -11,
      "y": 18,
      "z": -1,
      "name": "Rock_Bronze_Metal"
    },
    {
      "x": -11,
      "y": 19,
      "z": -1,
      "name": "Rock_Bronze_Metal"
    },
    {
      "x": -11,
      "y": 20,
      "z": -1,
      "name": "Rock_Bronze_Metal"
    },
    {
      "x": -11,
      "y": 21,
      "z": -1,
      "name": "Rock_Bronze_Metal"
    },
    {
      "x": -11,
      "y": 22,
      "z": -1,
      "name": "Rock_Bronze_Metal"
    },
    {
      "x": -11,
      "y": 23,
      "z": -1,
      "name": "Rock_Bronze_Metal"
    },
    {
      "x": -11,
      "y": 24,
      "z": -1,
      "name": "Rock_Bronze_Metal"
    },
    {
      "x": -11,
      "y": -1,
      "z": 0,
      "name": "Rock_Rusty_Metal"
    },
    {
      "x": -11,
      "y": 12,
      "z": 0,
      "name": "Rock_Dark_Rusty_Metal"
    },
    {
      "x": -11,
      "y": 13,
      "z": 0,
      "name": "Rock_Dark_Rusty_Metal"
    },
    {
      "x": -11,
      "y": 14,
      "z": 0,
      "name": "Rock_Dark_Rusty_Metal"
    },
    {
      "x": -11,
      "y": 15,
      "z": 0,
      "name": "Rock_Bronze_Metal"
    },
    {
      "x": -11,
      "y": 16,
      "z": 0,
      "name": "Rock_Bronze_Metal"
    },
    {
      "x": -11,
      "y": 17,
      "z": 0,
      "name": "Rock_Bronze_Metal"
    },
    {
      "x": -11,
      "y": 18,
      "z": 0,
      "name": "Rock_Bronze_Metal"
    },
    {
      "x": -11,
      "y": 19,
      "z": 0,
      "name": "Rock_Bronze_Metal"
    },
    {
      "x": -11,
      "y": 20,
      "z": 0,
      "name": "Rock_Bronze_Metal"
    },
    {
      "x": -11,
      "y": 21,
      "z": 0,
      "name": "Rock_Bronze_Metal"
    },
    {
      "x": -11,
      "y": 22,
      "z": 0,
      "name": "Rock_Bronze_Metal"
    },
    {
      "x": -11,
      "y": 23,
      "z": 0,
      "name": "Rock_Bronze_Metal"
    },
    {
      "x": -11,
      "y": 24,
      "z": 0,
      "name": "Rock_Bronze_Metal"
    },
    {
      "x": -11,
      "y": 25,
      "z": 0,
      "name": "Rock_Bronze_Metal"
    },
    {
      "x": -11,
      "y": -1,
      "z": 1,
      "name": "Rock_Rusty_Metal"
    },
    {
      "x": -11,
      "y": 12,
      "z": 1,
      "name": "Rock_Dark_Rusty_Metal"
    },
    {
      "x": -11,
      "y": 13,
      "z": 1,
      "name": "Rock_Dark_Rusty_Metal"
    },
    {
      "x": -11,
      "y": 14,
      "z": 1,
      "name": "Rock_Dark_Rusty_Metal"
    },
    {
      "x": -11,
      "y": 15,
      "z": 1,
      "name": "Rock_Bronze_Metal"
    },
    {
      "x": -11,
      "y": 16,
      "z": 1,
      "name": "Rock_Bronze_Metal"
    },
    {
      "x": -11,
      "y": 17,
      "z": 1,
      "name": "Rock_Bronze_Metal"
    },
    {
      "x": -11,
      "y": 18,
      "z": 1,
      "name": "Rock_Bronze_Metal"
    },
    {
      "x": -11,
      "y": 19,
      "z": 1,
      "name": "Rock_Bronze_Metal"
    },
    {
      "x": -11,
      "y": 20,
      "z": 1,
      "name": "Rock_Bronze_Metal"
    },
    {
      "x": -11,
      "y": 21,
      "z": 1,
      "name": "Rock_Bronze_Metal"
    },
    {
      "x": -11,
      "y": 22,
      "z": 1,
      "name": "Rock_Bronze_Metal"
    },
    {
      "x": -11,
      "y": 23,
      "z": 1,
      "name": "Rock_Bronze_Metal"
    },
    {
      "x": -11,
      "y": 24,
      "z": 1,
      "name": "Rock_Bronze_Metal"
    },
    {
      "x": -11,
      "y": -1,
      "z": 2,
      "name": "Rock_Rusty_Metal"
    },
    {
      "x": -11,
      "y": 12,
      "z": 2,
      "name": "Rock_Dark_Rusty_Metal"
    },
    {
      "x": -11,
      "y": 13,
      "z": 2,
      "name": "Rock_Dark_Rusty_Metal"
    },
    {
      "x": -11,
      "y": 14,
      "z": 2,
      "name": "Rock_Dark_Rusty_Metal"
    },
    {
      "x": -11,
      "y": 15,
      "z": 2,
      "name": "Rock_Dark_Rusty_Metal"
    },
    {
      "x": -11,
      "y": 16,
      "z": 2,
      "name": "Rock_Dark_Rusty_Metal"
    },
    {
      "x": -11,
      "y": 17,
      "z": 2,
      "name": "Rock_Dark_Rusty_Metal"
    },
    {
      "x": -11,
      "y": 18,
      "z": 2,
      "name": "Rock_Dark_Rusty_Metal"
    },
    {
      "x": -11,
      "y": 19,
      "z": 2,
      "name": "Rock_Dark_Rusty_Metal"
    },
    {
      "x": -11,
      "y": 20,
      "z": 2,
      "name": "Rock_Dark_Rusty_Metal"
    },
    {
      "x": -11,
      "y": -1,
      "z": 3,
      "name": "Rock_Rusty_Metal"
    },
    {
      "x": -11,
      "y": 12,
      "z": 3,
      "name": "Rock_Dark_Rusty_Metal"
    },
    {
      "x": -11,
      "y": 13,
      "z": 3,
      "name": "Rock_Dark_Rusty_Metal"
    },
    {
      "x": -11,
      "y": 14,
      "z": 3,
      "name": "Rock_Dark_Rusty_Metal"
    },
    {
      "x": -11,
      "y": 15,
      "z": 3,
      "name": "Rock_Dark_Rusty_Metal"
    },
    {
      "x": -11,
      "y": 16,
      "z": 3,
      "name": "Rock_Dark_Rusty_Metal"
    },
    {
      "x": -11,
      "y": 17,
      "z": 3,
      "name": "Rock_Dark_Rusty_Metal"
    },
    {
      "x": -11,
      "y": 18,
      "z": 3,
      "name": "Rock_Dark_Rusty_Metal"
    },
    {
      "x": -11,
      "y": 19,
      "z": 3,
      "name": "Rock_Dark_Rusty_Metal"
    },
    {
      "x": -11,
      "y": 20,
      "z": 3,
      "name": "Rock_Dark_Rusty_Metal"
    },
    {
      "x": -11,
      "y": -1,
      "z": 4,
      "name": "Rock_Rusty_Metal"
    },
    {
      "x": -11,
      "y": 12,
      "z": 4,
      "name": "Rock_Dark_Rusty_Metal"
    },
    {
      "x": -11,
      "y": 13,
      "z": 4,
      "name": "Rock_Dark_Rusty_Metal"
    },
    {
      "x": -11,
      "y": 14,
      "z": 4,
      "name": "Rock_Dark_Rusty_Metal"
    },
    {
      "x": -11,
      "y": 15,
      "z": 4,
      "name": "Rock_Dark_Rusty_Metal"
    },
    {
      "x": -11,
      "y": 16,
      "z": 4,
      "name": "Rock_Dark_Rusty_Metal"
    },
    {
      "x": -11,
      "y": 17,
      "z": 4,
      "name": "Rock_Dark_Rusty_Metal"
    },
    {
      "x": -11,
      "y": 18,
      "z": 4,
      "name": "Rock_Dark_Rusty_Metal"
    },
    {
      "x": -11,
      "y": 19,
      "z": 4,
      "name": "Rock_Dark_Rusty_Metal"
    },
    {
      "x": -11,
      "y": -1,
      "z": 5,
      "name": "Rock_Rusty_Metal"
    },
    {
      "x": -11,
      "y": 12,
      "z": 5,
      "name": "Rock_Dark_Rusty_Metal"
    },
    {
      "x": -11,
      "y": 13,
      "z": 5,
      "name": "Rock_Dark_Rusty_Metal"
    },
    {
      "x": -11,
      "y": 14,
      "z": 5,
      "name": "Rock_Dark_Rusty_Metal"
    },
    {
      "x": -11,
      "y": 15,
      "z": 5,
      "name": "Rock_Dark_Rusty_Metal"
    },
    {
      "x": -11,
      "y": 16,
      "z": 5,
      "name": "Rock_Dark_Rusty_Metal"
    },
    {
      "x": -11,
      "y": 17,
      "z": 5,
      "name": "Rock_Dark_Rusty_Metal"
    },
    {
      "x": -11,
      "y": 18,
      "z": 5,
      "name": "Rock_Dark_Rusty_Metal"
    },
    {
      "x": -11,
      "y": 19,
      "z": 5,
      "name": "Rock_Dark_Rusty_Metal"
    },
    {
      "x": -11,
      "y": -1,
      "z": 6,
      "name": "Rock_Rusty_Metal"
    },
    {
      "x": -11,
      "y": 12,
      "z": 6,
      "name": "Rock_Dark_Rusty_Metal"
    },
    {
      "x": -11,
      "y": 13,
      "z": 6,
      "name": "Rock_Dark_Rusty_Metal"
    },
    {
      "x": -11,
      "y": 14,
      "z": 6,
      "name": "Rock_Dark_Rusty_Metal"
    },
    {
      "x": -11,
      "y": 15,
      "z": 6,
      "name": "Rock_Dark_Rusty_Metal"
    },
    {
      "x": -11,
      "y": 16,
      "z": 6,
      "name": "Rock_Dark_Rusty_Metal"
    },
    {
      "x": -11,
      "y": 17,
      "z": 6,
      "name": "Rock_Dark_Rusty_Metal"
    },
    {
      "x": -11,
      "y": 18,
      "z": 6,
      "name": "Rock_Dark_Rusty_Metal"
    },
    {
      "x": -11,
      "y": -1,
      "z": 7,
      "name": "Rock_Rusty_Metal"
    },
    {
      "x": -11,
      "y": 12,
      "z": 7,
      "name": "Rock_Dark_Rusty_Metal"
    },
    {
      "x": -11,
      "y": 13,
      "z": 7,
      "name": "Rock_Dark_Rusty_Metal"
    },
    {
      "x": -11,
      "y": 14,
      "z": 7,
      "name": "Rock_Dark_Rusty_Metal"
    },
    {
      "x": -11,
      "y": 15,
      "z": 7,
      "name": "Rock_Dark_Rusty_Metal"
    },
    {
      "x": -11,
      "y": 16,
      "z": 7,
      "name": "Rock_Dark_Rusty_Metal"
    },
    {
      "x": -11,
      "y": 17,
      "z": 7,
      "name": "Rock_Dark_Rusty_Metal"
    },
    {
      "x": -11,
      "y": -1,
      "z": 8,
      "name": "Rock_Rusty_Metal"
    },
    {
      "x": -11,
      "y": 12,
      "z": 8,
      "name": "Rock_Dark_Rusty_Metal"
    },
    {
      "x": -11,
      "y": 13,
      "z": 8,
      "name": "Rock_Dark_Rusty_Metal"
    },
    {
      "x": -11,
      "y": 14,
      "z": 8,
      "name": "Rock_Dark_Rusty_Metal"
    },
    {
      "x": -11,
      "y": 15,
      "z": 8,
      "name": "Rock_Dark_Rusty_Metal"
    },
    {
      "x": -11,
      "y": 16,
      "z": 8,
      "name": "Rock_Dark_Rusty_Metal"
    },
    {
      "x": -11,
      "y": -1,
      "z": 9,
      "name": "Rock_Rusty_Metal"
    },
    {
      "x": -11,
      "y": 5,
      "z": 9,
      "name": "Rock_Dark_Rusty_Metal"
    },
    {
      "x": -11,
      "y": 6,
      "z": 9,
      "name": "Rock_Dark_Rusty_Metal"
    },
    {
      "x": -11,
      "y": 7,
      "z": 9,
      "name": "Rock_Dark_Rusty_Metal"
    },
    {
      "x": -11,
      "y": 8,
      "z": 9,
      "name": "Rock_Dark_Rusty_Metal"
    },
    {
      "x": -11,
      "y": 9,
      "z": 9,
      "name": "Rock_Dark_Rusty_Metal"
    },
    {
      "x": -11,
      "y": 10,
      "z": 9,
      "name": "Rock_Dark_Rusty_Metal"
    },
    {
      "x": -11,
      "y": 11,
      "z": 9,
      "name": "Rock_Dark_Rusty_Metal"
    },
    {
      "x": -11,
      "y": 12,
      "z": 9,
      "name": "Rock_Dark_Rusty_Metal"
    },
    {
      "x": -11,
      "y": 13,
      "z": 9,
      "name": "Rock_Dark_Rusty_Metal"
    },
    {
      "x": -11,
      "y": 14,
      "z": 9,
      "name": "Rock_Dark_Rusty_Metal"
    },
    {
      "x": -11,
      "y": -1,
      "z": 10,
      "name": "Rock_Rusty_Metal"
    },
    {
      "x": -11,
      "y": 0,
      "z": 10,
      "name": "Rock_Rusty_Metal"
    },
    {
      "x": -11,
      "y": 1,
      "z": 10,
      "name": "Rock_Rusty_Metal"
    },
    {
      "x": -11,
      "y": 2,
      "z": 10,
      "name": "Rock_Rusty_Metal"
    },
    {
      "x": -10,
      "y": -1,
      "z": -11,
      "name": "Rock_Rusty_Metal"
    },
    {
      "x": -10,
      "y": 0,
      "z": -11,
      "name": "Rock_Rusty_Metal"
    },
    {
      "x": -10,
      "y": 1,
      "z": -11,
      "name": "Rock_Rusty_Metal"
    },
    {
      "x": -10,
      "y": 2,
      "z": -11,
      "name": "Rock_Rusty_Metal"
    },
    {
      "x": -10,
      "y": -1,
      "z": -10,
      "name": "Rock_Rusty_Metal"
    },
    {
      "x": -10,
      "y": 5,
      "z": -10,
      "name": "Rock_Dark_Rusty_Metal"
    },
    {
      "x": -10,
      "y": 6,
      "z": -10,
      "name": "Rock_Dark_Rusty_Metal"
    },
    {
      "x": -10,
      "y": 7,
      "z": -10,
      "name": "Rock_Dark_Rusty_Metal"
    },
    {
      "x": -10,
      "y": 8,
      "z": -10,
      "name": "Rock_Dark_Rusty_Metal"
    },
    {
      "x": -10,
      "y": 9,
      "z": -10,
      "name": "Rock_Dark_Rusty_Metal"
    },
    {
      "x": -10,
      "y": 10,
      "z": -10,
      "name": "Rock_Dark_Rusty_Metal"
    },
    {
      "x": -10,
      "y": 11,
      "z": -10,
      "name": "Rock_Dark_Rusty_Metal"
    },
    {
      "x": -10,
      "y": 12,
      "z": -10,
      "name": "Rock_Dark_Rusty_Metal"
    },
    {
      "x": -10,
      "y": 13,
      "z": -10,
      "name": "Rock_Dark_Rusty_Metal"
    },
    {
      "x": -10,
      "y": 14,
      "z": -10,
      "name": "Rock_Dark_Rusty_Metal"
    },
    {
      "x": -10,
      "y": -1,
      "z": -9,
      "name": "Rock_Rusty_Metal"
    },
    {
      "x": -10,
      "y": 12,
      "z": -9,
      "name": "Rock_Dark_Rusty_Metal"
    },
    {
      "x": -10,
      "y": 13,
      "z": -9,
      "name": "Rock_Dark_Rusty_Metal"
    },
    {
      "x": -10,
      "y": 14,
      "z": -9,
      "name": "Rock_Dark_Rusty_Metal"
    },
    {
      "x": -10,
      "y": 15,
      "z": -9,
      "name": "Rock_Dark_Rusty_Metal"
    },
    {
      "x": -10,
      "y": 16,
      "z": -9,
      "name": "Rock_Dark_Rusty_Metal"
    },
    {
      "x": -10,
      "y": -1,
      "z": -8,
      "name": "Rock_Rusty_Metal"
    },
    {
      "x": -10,
      "y": 12,
      "z": -8,
      "name": "Rock_Dark_Rusty_Metal"
    },
    {
      "x": -10,
      "y": 13,
      "z": -8,
      "name": "Rock_Dark_Rusty_Metal"
    },
    {
      "x": -10,
      "y": 14,
      "z": -8,
      "name": "Rock_Dark_Rusty_Metal"
    },
    {
      "x": -10,
      "y": 15,
      "z": -8,
      "name": "Rock_Dark_Rusty_Metal"
    },
    {
      "x": -10,
      "y": 16,
      "z": -8,
      "name": "Rock_Dark_Rusty_Metal"
    },
    {
      "x": -10,
      "y": 17,
      "z": -8,
      "name": "Rock_Dark_Rusty_Metal"
    },
    {
      "x": -10,
      "y": 18,
      "z": -8,
      "name": "Rock_Dark_Rusty_Metal"
    },
    {
      "x": -10,
      "y": -1,
      "z": -7,
      "name": "Rock_Rusty_Metal"
    },
    {
      "x": -10,
      "y": 12,
      "z": -7,
      "name": "Rock_Dark_Rusty_Metal"
    },
    {
      "x": -10,
      "y": 13,
      "z": -7,
      "name": "Rock_Dark_Rusty_Metal"
    },
    {
      "x": -10,
      "y": 14,
      "z": -7,
      "name": "Rock_Dark_Rusty_Metal"
    },
    {
      "x": -10,
      "y": 15,
      "z": -7,
      "name": "Rock_Dark_Rusty_Metal"
    },
    {
      "x": -10,
      "y": 16,
      "z": -7,
      "name": "Rock_Dark_Rusty_Metal"
    },
    {
      "x": -10,
      "y": 17,
      "z": -7,
      "name": "Rock_Dark_Rusty_Metal"
    },
    {
      "x": -10,
      "y": 18,
      "z": -7,
      "name": "Rock_Dark_Rusty_Metal"
    },
    {
      "x": -10,
      "y": 19,
      "z": -7,
      "name": "Rock_Dark_Rusty_Metal"
    },
    {
      "x": -10,
      "y": -1,
      "z": -6,
      "name": "Rock_Rusty_Metal"
    },
    {
      "x": -10,
      "y": 12,
      "z": -6,
      "name": "Rock_Dark_Rusty_Metal"
    },
    {
      "x": -10,
      "y": 13,
      "z": -6,
      "name": "Rock_Dark_Rusty_Metal"
    },
    {
      "x": -10,
      "y": 14,
      "z": -6,
      "name": "Rock_Dark_Rusty_Metal"
    },
    {
      "x": -10,
      "y": 15,
      "z": -6,
      "name": "Rock_Dark_Rusty_Metal"
    },
    {
      "x": -10,
      "y": 16,
      "z": -6,
      "name": "Rock_Dark_Rusty_Metal"
    },
    {
      "x": -10,
      "y": 17,
      "z": -6,
      "name": "Rock_Dark_Rusty_Metal"
    },
    {
      "x": -10,
      "y": 18,
      "z": -6,
      "name": "Rock_Dark_Rusty_Metal"
    },
    {
      "x": -10,
      "y": 19,
      "z": -6,
      "name": "Rock_Dark_Rusty_Metal"
    },
    {
      "x": -10,
      "y": -1,
      "z": -5,
      "name": "Rock_Rusty_Metal"
    },
    {
      "x": -10,
      "y": 12,
      "z": -5,
      "name": "Rock_Dark_Rusty_Metal"
    },
    {
      "x": -10,
      "y": 13,
      "z": -5,
      "name": "Rock_Dark_Rusty_Metal"
    },
    {
      "x": -10,
      "y": 14,
      "z": -5,
      "name": "Rock_Dark_Rusty_Metal"
    },
    {
      "x": -10,
      "y": 15,
      "z": -5,
      "name": "Rock_Dark_Rusty_Metal"
    },
    {
      "x": -10,
      "y": 16,
      "z": -5,
      "name": "Rock_Dark_Rusty_Metal"
    },
    {
      "x": -10,
      "y": 17,
      "z": -5,
      "name": "Rock_Dark_Rusty_Metal"
    },
    {
      "x": -10,
      "y": 18,
      "z": -5,
      "name": "Rock_Dark_Rusty_Metal"
    },
    {
      "x": -10,
      "y": 19,
      "z": -5,
      "name": "Rock_Dark_Rusty_Metal"
    },
    {
      "x": -10,
      "y": 20,
      "z": -5,
      "name": "Rock_Dark_Rusty_Metal"
    },
    {
      "x": -10,
      "y": -1,
      "z": -4,
      "name": "Rock_Rusty_Metal"
    },
    {
      "x": -10,
      "y": 12,
      "z": -4,
      "name": "Rock_Dark_Rusty_Metal"
    },
    {
      "x": -10,
      "y": 13,
      "z": -4,
      "name": "Rock_Dark_Rusty_Metal"
    },
    {
      "x": -10,
      "y": 14,
      "z": -4,
      "name": "Rock_Dark_Rusty_Metal"
    },
    {
      "x": -10,
      "y": 15,
      "z": -4,
      "name": "Rock_Dark_Rusty_Metal"
    },
    {
      "x": -10,
      "y": 16,
      "z": -4,
      "name": "Rock_Dark_Rusty_Metal"
    },
    {
      "x": -10,
      "y": 17,
      "z": -4,
      "name": "Rock_Dark_Rusty_Metal"
    },
    {
      "x": -10,
      "y": 18,
      "z": -4,
      "name": "Rock_Dark_Rusty_Metal"
    },
    {
      "x": -10,
      "y": 19,
      "z": -4,
      "name": "Rock_Dark_Rusty_Metal"
    },
    {
      "x": -10,
      "y": 20,
      "z": -4,
      "name": "Rock_Dark_Rusty_Metal"
    },
    {
      "x": -10,
      "y": -1,
      "z": -3,
      "name": "Rock_Rusty_Metal"
    },
    {
      "x": -10,
      "y": 12,
      "z": -3,
      "name": "Rock_Dark_Rusty_Metal"
    },
    {
      "x": -10,
      "y": 13,
      "z": -3,
      "name": "Rock_Dark_Rusty_Metal"
    },
    {
      "x": -10,
      "y": 14,
      "z": -3,
      "name": "Rock_Dark_Rusty_Metal"
    },
    {
      "x": -10,
      "y": 15,
      "z": -3,
      "name": "Rock_Dark_Rusty_Metal"
    },
    {
      "x": -10,
      "y": 16,
      "z": -3,
      "name": "Rock_Dark_Rusty_Metal"
    },
    {
      "x": -10,
      "y": 17,
      "z": -3,
      "name": "Rock_Dark_Rusty_Metal"
    },
    {
      "x": -10,
      "y": 18,
      "z": -3,
      "name": "Rock_Dark_Rusty_Metal"
    },
    {
      "x": -10,
      "y": 19,
      "z": -3,
      "name": "Rock_Dark_Rusty_Metal"
    },
    {
      "x": -10,
      "y": 20,
      "z": -3,
      "name": "Rock_Dark_Rusty_Metal"
    },
    {
      "x": -10,
      "y": 21,
      "z": -3,
      "name": "Rock_Dark_Rusty_Metal"
    },
    {
      "x": -10,
      "y": -1,
      "z": -2,
      "name": "Rock_Rusty_Metal"
    },
    {
      "x": -10,
      "y": 12,
      "z": -2,
      "name": "Rock_Dark_Rusty_Metal"
    },
    {
      "x": -10,
      "y": 13,
      "z": -2,
      "name": "Rock_Dark_Rusty_Metal"
    },
    {
      "x": -10,
      "y": 14,
      "z": -2,
      "name": "Rock_Dark_Rusty_Metal"
    },
    {
      "x": -10,
      "y": 15,
      "z": -2,
      "name": "Rock_Dark_Rusty_Metal"
    },
    {
      "x": -10,
      "y": 16,
      "z": -2,
      "name": "Rock_Dark_Rusty_Metal"
    },
    {
      "x": -10,
      "y": 17,
      "z": -2,
      "name": "Rock_Dark_Rusty_Metal"
    },
    {
      "x": -10,
      "y": 18,
      "z": -2,
      "name": "Rock_Dark_Rusty_Metal"
    },
    {
      "x": -10,
      "y": 19,
      "z": -2,
      "name": "Rock_Dark_Rusty_Metal"
    },
    {
      "x": -10,
      "y": 20,
      "z": -2,
      "name": "Rock_Dark_Rusty_Metal"
    },
    {
      "x": -10,
      "y": 21,
      "z": -2,
      "name": "Rock_Dark_Rusty_Metal"
    },
    {
      "x": -10,
      "y": -1,
      "z": -1,
      "name": "Rock_Rusty_Metal"
    },
    {
      "x": -10,
      "y": 12,
      "z": -1,
      "name": "Rock_Dark_Rusty_Metal"
    },
    {
      "x": -10,
      "y": 13,
      "z": -1,
      "name": "Rock_Dark_Rusty_Metal"
    },
    {
      "x": -10,
      "y": 14,
      "z": -1,
      "name": "Rock_Dark_Rusty_Metal"
    },
    {
      "x": -10,
      "y": 15,
      "z": -1,
      "name": "Rock_Dark_Rusty_Metal"
    },
    {
      "x": -10,
      "y": 16,
      "z": -1,
      "name": "Rock_Dark_Rusty_Metal"
    },
    {
      "x": -10,
      "y": 17,
      "z": -1,
      "name": "Rock_Dark_Rusty_Metal"
    },
    {
      "x": -10,
      "y": 18,
      "z": -1,
      "name": "Rock_Bronze_Metal"
    },
    {
      "x": -10,
      "y": 19,
      "z": -1,
      "name": "Rock_Bronze_Metal"
    },
    {
      "x": -10,
      "y": 20,
      "z": -1,
      "name": "Rock_Bronze_Metal"
    },
    {
      "x": -10,
      "y": 21,
      "z": -1,
      "name": "Rock_Bronze_Metal"
    },
    {
      "x": -10,
      "y": 22,
      "z": -1,
      "name": "Rock_Bronze_Metal"
    },
    {
      "x": -10,
      "y": 23,
      "z": -1,
      "name": "Rock_Bronze_Metal"
    },
    {
      "x": -10,
      "y": 24,
      "z": -1,
      "name": "Rock_Bronze_Metal"
    },
    {
      "x": -10,
      "y": 25,
      "z": -1,
      "name": "Rock_Bronze_Metal"
    },
    {
      "x": -10,
      "y": -1,
      "z": 0,
      "name": "Rock_Rusty_Metal"
    },
    {
      "x": -10,
      "y": 12,
      "z": 0,
      "name": "Rock_Dark_Rusty_Metal"
    },
    {
      "x": -10,
      "y": 13,
      "z": 0,
      "name": "Rock_Dark_Rusty_Metal"
    },
    {
      "x": -10,
      "y": 14,
      "z": 0,
      "name": "Rock_Dark_Rusty_Metal"
    },
    {
      "x": -10,
      "y": 15,
      "z": 0,
      "name": "Rock_Dark_Rusty_Metal"
    },
    {
      "x": -10,
      "y": 16,
      "z": 0,
      "name": "Rock_Dark_Rusty_Metal"
    },
    {
      "x": -10,
      "y": 17,
      "z": 0,
      "name": "Rock_Dark_Rusty_Metal"
    },
    {
      "x": -10,
      "y": 18,
      "z": 0,
      "name": "Rock_Bronze_Metal"
    },
    {
      "x": -10,
      "y": 19,
      "z": 0,
      "name": "Rock_Bronze_Metal"
    },
    {
      "x": -10,
      "y": 20,
      "z": 0,
      "name": "Rock_Bronze_Metal"
    },
    {
      "x": -10,
      "y": 21,
      "z": 0,
      "name": "Rock_Bronze_Metal"
    },
    {
      "x": -10,
      "y": 22,
      "z": 0,
      "name": "Rock_Bronze_Metal"
    },
    {
      "x": -10,
      "y": 23,
      "z": 0,
      "name": "Rock_Bronze_Metal"
    },
    {
      "x": -10,
      "y": 24,
      "z": 0,
      "name": "Rock_Bronze_Metal"
    },
    {
      "x": -10,
      "y": 25,
      "z": 0,
      "name": "Rock_Bronze_Metal"
    },
    {
      "x": -10,
      "y": 26,
      "z": 0,
      "name": "Rock_Bronze_Metal"
    },
    {
      "x": -10,
      "y": -1,
      "z": 1,
      "name": "Rock_Rusty_Metal"
    },
    {
      "x": -10,
      "y": 12,
      "z": 1,
      "name": "Rock_Dark_Rusty_Metal"
    },
    {
      "x": -10,
      "y": 13,
      "z": 1,
      "name": "Rock_Dark_Rusty_Metal"
    },
    {
      "x": -10,
      "y": 14,
      "z": 1,
      "name": "Rock_Dark_Rusty_Metal"
    },
    {
      "x": -10,
      "y": 15,
      "z": 1,
      "name": "Rock_Dark_Rusty_Metal"
    },
    {
      "x": -10,
      "y": 16,
      "z": 1,
      "name": "Rock_Dark_Rusty_Metal"
    },
    {
      "x": -10,
      "y": 17,
      "z": 1,
      "name": "Rock_Dark_Rusty_Metal"
    },
    {
      "x": -10,
      "y": 18,
      "z": 1,
      "name": "Rock_Bronze_Metal"
    },
    {
      "x": -10,
      "y": 19,
      "z": 1,
      "name": "Rock_Bronze_Metal"
    },
    {
      "x": -10,
      "y": 20,
      "z": 1,
      "name": "Rock_Bronze_Metal"
    },
    {
      "x": -10,
      "y": 21,
      "z": 1,
      "name": "Rock_Bronze_Metal"
    },
    {
      "x": -10,
      "y": 22,
      "z": 1,
      "name": "Rock_Bronze_Metal"
    },
    {
      "x": -10,
      "y": 23,
      "z": 1,
      "name": "Rock_Bronze_Metal"
    },
    {
      "x": -10,
      "y": 24,
      "z": 1,
      "name": "Rock_Bronze_Metal"
    },
    {
      "x": -10,
      "y": 25,
      "z": 1,
      "name": "Rock_Bronze_Metal"
    },
    {
      "x": -10,
      "y": -1,
      "z": 2,
      "name": "Rock_Rusty_Metal"
    },
    {
      "x": -10,
      "y": 12,
      "z": 2,
      "name": "Rock_Dark_Rusty_Metal"
    },
    {
      "x": -10,
      "y": 13,
      "z": 2,
      "name": "Rock_Dark_Rusty_Metal"
    },
    {
      "x": -10,
      "y": 14,
      "z": 2,
      "name": "Rock_Dark_Rusty_Metal"
    },
    {
      "x": -10,
      "y": 15,
      "z": 2,
      "name": "Rock_Dark_Rusty_Metal"
    },
    {
      "x": -10,
      "y": 16,
      "z": 2,
      "name": "Rock_Dark_Rusty_Metal"
    },
    {
      "x": -10,
      "y": 17,
      "z": 2,
      "name": "Rock_Dark_Rusty_Metal"
    },
    {
      "x": -10,
      "y": 18,
      "z": 2,
      "name": "Rock_Dark_Rusty_Metal"
    },
    {
      "x": -10,
      "y": 19,
      "z": 2,
      "name": "Rock_Dark_Rusty_Metal"
    },
    {
      "x": -10,
      "y": 20,
      "z": 2,
      "name": "Rock_Dark_Rusty_Metal"
    },
    {
      "x": -10,
      "y": 21,
      "z": 2,
      "name": "Rock_Dark_Rusty_Metal"
    },
    {
      "x": -10,
      "y": -1,
      "z": 3,
      "name": "Rock_Rusty_Metal"
    },
    {
      "x": -10,
      "y": 12,
      "z": 3,
      "name": "Rock_Dark_Rusty_Metal"
    },
    {
      "x": -10,
      "y": 13,
      "z": 3,
      "name": "Rock_Dark_Rusty_Metal"
    },
    {
      "x": -10,
      "y": 14,
      "z": 3,
      "name": "Rock_Dark_Rusty_Metal"
    },
    {
      "x": -10,
      "y": 15,
      "z": 3,
      "name": "Rock_Dark_Rusty_Metal"
    },
    {
      "x": -10,
      "y": 16,
      "z": 3,
      "name": "Rock_Dark_Rusty_Metal"
    },
    {
      "x": -10,
      "y": 17,
      "z": 3,
      "name": "Rock_Dark_Rusty_Metal"
    },
    {
      "x": -10,
      "y": 18,
      "z": 3,
      "name": "Rock_Dark_Rusty_Metal"
    },
    {
      "x": -10,
      "y": 19,
      "z": 3,
      "name": "Rock_Dark_Rusty_Metal"
    },
    {
      "x": -10,
      "y": 20,
      "z": 3,
      "name": "Rock_Dark_Rusty_Metal"
    },
    {
      "x": -10,
      "y": 21,
      "z": 3,
      "name": "Rock_Dark_Rusty_Metal"
    },
    {
      "x": -10,
      "y": -1,
      "z": 4,
      "name": "Rock_Rusty_Metal"
    },
    {
      "x": -10,
      "y": 12,
      "z": 4,
      "name": "Rock_Dark_Rusty_Metal"
    },
    {
      "x": -10,
      "y": 13,
      "z": 4,
      "name": "Rock_Dark_Rusty_Metal"
    },
    {
      "x": -10,
      "y": 14,
      "z": 4,
      "name": "Rock_Dark_Rusty_Metal"
    },
    {
      "x": -10,
      "y": 15,
      "z": 4,
      "name": "Rock_Dark_Rusty_Metal"
    },
    {
      "x": -10,
      "y": 16,
      "z": 4,
      "name": "Rock_Dark_Rusty_Metal"
    },
    {
      "x": -10,
      "y": 17,
      "z": 4,
      "name": "Rock_Dark_Rusty_Metal"
    },
    {
      "x": -10,
      "y": 18,
      "z": 4,
      "name": "Rock_Dark_Rusty_Metal"
    },
    {
      "x": -10,
      "y": 19,
      "z": 4,
      "name": "Rock_Dark_Rusty_Metal"
    },
    {
      "x": -10,
      "y": 20,
      "z": 4,
      "name": "Rock_Dark_Rusty_Metal"
    },
    {
      "x": -10,
      "y": -1,
      "z": 5,
      "name": "Rock_Rusty_Metal"
    },
    {
      "x": -10,
      "y": 12,
      "z": 5,
      "name": "Rock_Dark_Rusty_Metal"
    },
    {
      "x": -10,
      "y": 13,
      "z": 5,
      "name": "Rock_Dark_Rusty_Metal"
    },
    {
      "x": -10,
      "y": 14,
      "z": 5,
      "name": "Rock_Dark_Rusty_Metal"
    },
    {
      "x": -10,
      "y": 15,
      "z": 5,
      "name": "Rock_Dark_Rusty_Metal"
    },
    {
      "x": -10,
      "y": 16,
      "z": 5,
      "name": "Rock_Dark_Rusty_Metal"
    },
    {
      "x": -10,
      "y": 17,
      "z": 5,
      "name": "Rock_Dark_Rusty_Metal"
    },
    {
      "x": -10,
      "y": 18,
      "z": 5,
      "name": "Rock_Dark_Rusty_Metal"
    },
    {
      "x": -10,
      "y": 19,
      "z": 5,
      "name": "Rock_Dark_Rusty_Metal"
    },
    {
      "x": -10,
      "y": 20,
      "z": 5,
      "name": "Rock_Dark_Rusty_Metal"
    },
    {
      "x": -10,
      "y": -1,
      "z": 6,
      "name": "Rock_Rusty_Metal"
    },
    {
      "x": -10,
      "y": 0,
      "z": 6,
      "name": "Rock_Crystal_Red_Small"
    },
    {
      "x": -10,
      "y": 12,
      "z": 6,
      "name": "Rock_Dark_Rusty_Metal"
    },
    {
      "x": -10,
      "y": 13,
      "z": 6,
      "name": "Rock_Dark_Rusty_Metal"
    },
    {
      "x": -10,
      "y": 14,
      "z": 6,
      "name": "Rock_Dark_Rusty_Metal"
    },
    {
      "x": -10,
      "y": 15,
      "z": 6,
      "name": "Rock_Dark_Rusty_Metal"
    },
    {
      "x": -10,
      "y": 16,
      "z": 6,
      "name": "Rock_Dark_Rusty_Metal"
    },
    {
      "x": -10,
      "y": 17,
      "z": 6,
      "name": "Rock_Dark_Rusty_Metal"
    },
    {
      "x": -10,
      "y": 18,
      "z": 6,
      "name": "Rock_Dark_Rusty_Metal"
    },
    {
      "x": -10,
      "y": 19,
      "z": 6,
      "name": "Rock_Dark_Rusty_Metal"
    },
    {
      "x": -10,
      "y": -1,
      "z": 7,
      "name": "Rock_Rusty_Metal"
    },
    {
      "x": -10,
      "y": 12,
      "z": 7,
      "name": "Rock_Dark_Rusty_Metal"
    },
    {
      "x": -10,
      "y": 13,
      "z": 7,
      "name": "Rock_Dark_Rusty_Metal"
    },
    {
      "x": -10,
      "y": 14,
      "z": 7,
      "name": "Rock_Dark_Rusty_Metal"
    },
    {
      "x": -10,
      "y": 15,
      "z": 7,
      "name": "Rock_Dark_Rusty_Metal"
    },
    {
      "x": -10,
      "y": 16,
      "z": 7,
      "name": "Rock_Dark_Rusty_Metal"
    },
    {
      "x": -10,
      "y": 17,
      "z": 7,
      "name": "Rock_Dark_Rusty_Metal"
    },
    {
      "x": -10,
      "y": 18,
      "z": 7,
      "name": "Rock_Dark_Rusty_Metal"
    },
    {
      "x": -10,
      "y": 19,
      "z": 7,
      "name": "Rock_Dark_Rusty_Metal"
    },
    {
      "x": -10,
      "y": -1,
      "z": 8,
      "name": "Rock_Rusty_Metal"
    },
    {
      "x": -10,
      "y": 12,
      "z": 8,
      "name": "Rock_Dark_Rusty_Metal"
    },
    {
      "x": -10,
      "y": 13,
      "z": 8,
      "name": "Rock_Dark_Rusty_Metal"
    },
    {
      "x": -10,
      "y": 14,
      "z": 8,
      "name": "Rock_Dark_Rusty_Metal"
    },
    {
      "x": -10,
      "y": 15,
      "z": 8,
      "name": "Rock_Dark_Rusty_Metal"
    },
    {
      "x": -10,
      "y": 16,
      "z": 8,
      "name": "Rock_Dark_Rusty_Metal"
    },
    {
      "x": -10,
      "y": 17,
      "z": 8,
      "name": "Rock_Dark_Rusty_Metal"
    },
    {
      "x": -10,
      "y": 18,
      "z": 8,
      "name": "Rock_Dark_Rusty_Metal"
    },
    {
      "x": -10,
      "y": -1,
      "z": 9,
      "name": "Rock_Rusty_Metal"
    },
    {
      "x": -10,
      "y": 12,
      "z": 9,
      "name": "Rock_Dark_Rusty_Metal"
    },
    {
      "x": -10,
      "y": 13,
      "z": 9,
      "name": "Rock_Dark_Rusty_Metal"
    },
    {
      "x": -10,
      "y": 14,
      "z": 9,
      "name": "Rock_Dark_Rusty_Metal"
    },
    {
      "x": -10,
      "y": 15,
      "z": 9,
      "name": "Rock_Dark_Rusty_Metal"
    },
    {
      "x": -10,
      "y": 16,
      "z": 9,
      "name": "Rock_Dark_Rusty_Metal"
    },
    {
      "x": -10,
      "y": -1,
      "z": 10,
      "name": "Rock_Rusty_Metal"
    },
    {
      "x": -10,
      "y": 5,
      "z": 10,
      "name": "Rock_Dark_Rusty_Metal"
    },
    {
      "x": -10,
      "y": 6,
      "z": 10,
      "name": "Rock_Dark_Rusty_Metal"
    },
    {
      "x": -10,
      "y": 7,
      "z": 10,
      "name": "Rock_Dark_Rusty_Metal"
    },
    {
      "x": -10,
      "y": 8,
      "z": 10,
      "name": "Rock_Dark_Rusty_Metal"
    },
    {
      "x": -10,
      "y": 9,
      "z": 10,
      "name": "Rock_Dark_Rusty_Metal"
    },
    {
      "x": -10,
      "y": 10,
      "z": 10,
      "name": "Rock_Dark_Rusty_Metal"
    },
    {
      "x": -10,
      "y": 11,
      "z": 10,
      "name": "Rock_Dark_Rusty_Metal"
    },
    {
      "x": -10,
      "y": 12,
      "z": 10,
      "name": "Rock_Dark_Rusty_Metal"
    },
    {
      "x": -10,
      "y": 13,
      "z": 10,
      "name": "Rock_Dark_Rusty_Metal"
    },
    {
      "x": -10,
      "y": 14,
      "z": 10,
      "name": "Rock_Dark_Rusty_Metal"
    },
    {
      "x": -10,
      "y": -1,
      "z": 11,
      "name": "Rock_Rusty_Metal"
    },
    {
      "x": -10,
      "y": 0,
      "z": 11,
      "name": "Rock_Rusty_Metal"
    },
    {
      "x": -10,
      "y": 1,
      "z": 11,
      "name": "Rock_Rusty_Metal"
    },
    {
      "x": -10,
      "y": 2,
      "z": 11,
      "name": "Rock_Rusty_Metal"
    },
    {
      "x": -9,
      "y": -1,
      "z": -12,
      "name": "Rock_Rusty_Metal"
    },
    {
      "x": -9,
      "y": 0,
      "z": -12,
      "name": "Rock_Rusty_Metal"
    },
    {
      "x": -9,
      "y": 1,
      "z": -12,
      "name": "Rock_Rusty_Metal"
    },
    {
      "x": -9,
      "y": 2,
      "z": -12,
      "name": "Rock_Rusty_Metal"
    },
    {
      "x": -9,
      "y": -1,
      "z": -11,
      "name": "Rock_Rusty_Metal"
    },
    {
      "x": -9,
      "y": 5,
      "z": -11,
      "name": "Rock_Dark_Rusty_Metal"
    },
    {
      "x": -9,
      "y": 6,
      "z": -11,
      "name": "Rock_Dark_Rusty_Metal"
    },
    {
      "x": -9,
      "y": 7,
      "z": -11,
      "name": "Rock_Dark_Rusty_Metal"
    },
    {
      "x": -9,
      "y": 8,
      "z": -11,
      "name": "Rock_Dark_Rusty_Metal"
    },
    {
      "x": -9,
      "y": 9,
      "z": -11,
      "name": "Rock_Dark_Rusty_Metal"
    },
    {
      "x": -9,
      "y": 10,
      "z": -11,
      "name": "Rock_Dark_Rusty_Metal"
    },
    {
      "x": -9,
      "y": 11,
      "z": -11,
      "name": "Rock_Dark_Rusty_Metal"
    },
    {
      "x": -9,
      "y": 12,
      "z": -11,
      "name": "Rock_Dark_Rusty_Metal"
    },
    {
      "x": -9,
      "y": 13,
      "z": -11,
      "name": "Rock_Dark_Rusty_Metal"
    },
    {
      "x": -9,
      "y": 14,
      "z": -11,
      "name": "Rock_Dark_Rusty_Metal"
    },
    {
      "x": -9,
      "y": -1,
      "z": -10,
      "name": "Rock_Rusty_Metal"
    },
    {
      "x": -9,
      "y": 12,
      "z": -10,
      "name": "Rock_Dark_Rusty_Metal"
    },
    {
      "x": -9,
      "y": 13,
      "z": -10,
      "name": "Rock_Dark_Rusty_Metal"
    },
    {
      "x": -9,
      "y": 14,
      "z": -10,
      "name": "Rock_Dark_Rusty_Metal"
    },
    {
      "x": -9,
      "y": 15,
      "z": -10,
      "name": "Rock_Dark_Rusty_Metal"
    },
    {
      "x": -9,
      "y": 16,
      "z": -10,
      "name": "Rock_Dark_Rusty_Metal"
    },
    {
      "x": -9,
      "y": -1,
      "z": -9,
      "name": "Rock_Rusty_Metal"
    },
    {
      "x": -9,
      "y": 12,
      "z": -9,
      "name": "Rock_Dark_Rusty_Metal"
    },
    {
      "x": -9,
      "y": 13,
      "z": -9,
      "name": "Rock_Dark_Rusty_Metal"
    },
    {
      "x": -9,
      "y": 14,
      "z": -9,
      "name": "Rock_Dark_Rusty_Metal"
    },
    {
      "x": -9,
      "y": 15,
      "z": -9,
      "name": "Rock_Dark_Rusty_Metal"
    },
    {
      "x": -9,
      "y": 16,
      "z": -9,
      "name": "Rock_Dark_Rusty_Metal"
    },
    {
      "x": -9,
      "y": 17,
      "z": -9,
      "name": "Rock_Dark_Rusty_Metal"
    },
    {
      "x": -9,
      "y": 18,
      "z": -9,
      "name": "Rock_Dark_Rusty_Metal"
    },
    {
      "x": -9,
      "y": -1,
      "z": -8,
      "name": "Rock_Rusty_Metal"
    },
    {
      "x": -9,
      "y": 12,
      "z": -8,
      "name": "Rock_Dark_Rusty_Metal"
    },
    {
      "x": -9,
      "y": 13,
      "z": -8,
      "name": "Rock_Dark_Rusty_Metal"
    },
    {
      "x": -9,
      "y": 14,
      "z": -8,
      "name": "Rock_Dark_Rusty_Metal"
    },
    {
      "x": -9,
      "y": 15,
      "z": -8,
      "name": "Rock_Dark_Rusty_Metal"
    },
    {
      "x": -9,
      "y": 16,
      "z": -8,
      "name": "Rock_Dark_Rusty_Metal"
    },
    {
      "x": -9,
      "y": 17,
      "z": -8,
      "name": "Rock_Dark_Rusty_Metal"
    },
    {
      "x": -9,
      "y": 18,
      "z": -8,
      "name": "Rock_Dark_Rusty_Metal"
    },
    {
      "x": -9,
      "y": 19,
      "z": -8,
      "name": "Rock_Dark_Rusty_Metal"
    },
    {
      "x": -9,
      "y": -1,
      "z": -7,
      "name": "Rock_Rusty_Metal"
    },
    {
      "x": -9,
      "y": 0,
      "z": -7,
      "name": "Rock_Crystal_Red_Large"
    },
    {
      "x": -9,
      "y": 12,
      "z": -7,
      "name": "Rock_Dark_Rusty_Metal"
    },
    {
      "x": -9,
      "y": 13,
      "z": -7,
      "name": "Rock_Dark_Rusty_Metal"
    },
    {
      "x": -9,
      "y": 14,
      "z": -7,
      "name": "Rock_Dark_Rusty_Metal"
    },
    {
      "x": -9,
      "y": 15,
      "z": -7,
      "name": "Rock_Dark_Rusty_Metal"
    },
    {
      "x": -9,
      "y": 16,
      "z": -7,
      "name": "Rock_Dark_Rusty_Metal"
    },
    {
      "x": -9,
      "y": 17,
      "z": -7,
      "name": "Rock_Dark_Rusty_Metal"
    },
    {
      "x": -9,
      "y": 18,
      "z": -7,
      "name": "Rock_Dark_Rusty_Metal"
    },
    {
      "x": -9,
      "y": 19,
      "z": -7,
      "name": "Rock_Dark_Rusty_Metal"
    },
    {
      "x": -9,
      "y": 20,
      "z": -7,
      "name": "Rock_Dark_Rusty_Metal"
    },
    {
      "x": -9,
      "y": -1,
      "z": -6,
      "name": "Rock_Rusty_Metal"
    },
    {
      "x": -9,
      "y": 12,
      "z": -6,
      "name": "Rock_Dark_Rusty_Metal"
    },
    {
      "x": -9,
      "y": 13,
      "z": -6,
      "name": "Rock_Dark_Rusty_Metal"
    },
    {
      "x": -9,
      "y": 14,
      "z": -6,
      "name": "Rock_Dark_Rusty_Metal"
    },
    {
      "x": -9,
      "y": 15,
      "z": -6,
      "name": "Rock_Dark_Rusty_Metal"
    },
    {
      "x": -9,
      "y": 16,
      "z": -6,
      "name": "Rock_Dark_Rusty_Metal"
    },
    {
      "x": -9,
      "y": 17,
      "z": -6,
      "name": "Rock_Dark_Rusty_Metal"
    },
    {
      "x": -9,
      "y": 18,
      "z": -6,
      "name": "Rock_Dark_Rusty_Metal"
    },
    {
      "x": -9,
      "y": 19,
      "z": -6,
      "name": "Rock_Dark_Rusty_Metal"
    },
    {
      "x": -9,
      "y": 20,
      "z": -6,
      "name": "Rock_Dark_Rusty_Metal"
    },
    {
      "x": -9,
      "y": -1,
      "z": -5,
      "name": "Rock_Rusty_Metal"
    },
    {
      "x": -9,
      "y": 12,
      "z": -5,
      "name": "Rock_Dark_Rusty_Metal"
    },
    {
      "x": -9,
      "y": 13,
      "z": -5,
      "name": "Rock_Dark_Rusty_Metal"
    },
    {
      "x": -9,
      "y": 14,
      "z": -5,
      "name": "Rock_Dark_Rusty_Metal"
    },
    {
      "x": -9,
      "y": 15,
      "z": -5,
      "name": "Rock_Dark_Rusty_Metal"
    },
    {
      "x": -9,
      "y": 16,
      "z": -5,
      "name": "Rock_Dark_Rusty_Metal"
    },
    {
      "x": -9,
      "y": 17,
      "z": -5,
      "name": "Rock_Dark_Rusty_Metal"
    },
    {
      "x": -9,
      "y": 18,
      "z": -5,
      "name": "Rock_Dark_Rusty_Metal"
    },
    {
      "x": -9,
      "y": 19,
      "z": -5,
      "name": "Rock_Dark_Rusty_Metal"
    },
    {
      "x": -9,
      "y": 20,
      "z": -5,
      "name": "Rock_Dark_Rusty_Metal"
    },
    {
      "x": -9,
      "y": 21,
      "z": -5,
      "name": "Rock_Dark_Rusty_Metal"
    },
    {
      "x": -9,
      "y": -1,
      "z": -4,
      "name": "Rock_Rusty_Metal"
    },
    {
      "x": -9,
      "y": 12,
      "z": -4,
      "name": "Rock_Dark_Rusty_Metal"
    },
    {
      "x": -9,
      "y": 13,
      "z": -4,
      "name": "Rock_Dark_Rusty_Metal"
    },
    {
      "x": -9,
      "y": 14,
      "z": -4,
      "name": "Rock_Dark_Rusty_Metal"
    },
    {
      "x": -9,
      "y": 15,
      "z": -4,
      "name": "Rock_Dark_Rusty_Metal"
    },
    {
      "x": -9,
      "y": 16,
      "z": -4,
      "name": "Rock_Dark_Rusty_Metal"
    },
    {
      "x": -9,
      "y": 17,
      "z": -4,
      "name": "Rock_Dark_Rusty_Metal"
    },
    {
      "x": -9,
      "y": 18,
      "z": -4,
      "name": "Rock_Dark_Rusty_Metal"
    },
    {
      "x": -9,
      "y": 19,
      "z": -4,
      "name": "Rock_Dark_Rusty_Metal"
    },
    {
      "x": -9,
      "y": 20,
      "z": -4,
      "name": "Rock_Dark_Rusty_Metal"
    },
    {
      "x": -9,
      "y": 21,
      "z": -4,
      "name": "Rock_Dark_Rusty_Metal"
    },
    {
      "x": -9,
      "y": -1,
      "z": -3,
      "name": "Rock_Rusty_Metal"
    },
    {
      "x": -9,
      "y": 12,
      "z": -3,
      "name": "Rock_Dark_Rusty_Metal"
    },
    {
      "x": -9,
      "y": 13,
      "z": -3,
      "name": "Rock_Dark_Rusty_Metal"
    },
    {
      "x": -9,
      "y": 14,
      "z": -3,
      "name": "Rock_Dark_Rusty_Metal"
    },
    {
      "x": -9,
      "y": 15,
      "z": -3,
      "name": "Rock_Dark_Rusty_Metal"
    },
    {
      "x": -9,
      "y": 16,
      "z": -3,
      "name": "Rock_Dark_Rusty_Metal"
    },
    {
      "x": -9,
      "y": 17,
      "z": -3,
      "name": "Rock_Dark_Rusty_Metal"
    },
    {
      "x": -9,
      "y": 18,
      "z": -3,
      "name": "Rock_Dark_Rusty_Metal"
    },
    {
      "x": -9,
      "y": 19,
      "z": -3,
      "name": "Rock_Dark_Rusty_Metal"
    },
    {
      "x": -9,
      "y": 20,
      "z": -3,
      "name": "Rock_Dark_Rusty_Metal"
    },
    {
      "x": -9,
      "y": 21,
      "z": -3,
      "name": "Rock_Dark_Rusty_Metal"
    },
    {
      "x": -9,
      "y": 22,
      "z": -3,
      "name": "Rock_Dark_Rusty_Metal"
    },
    {
      "x": -9,
      "y": -1,
      "z": -2,
      "name": "Rock_Rusty_Metal"
    },
    {
      "x": -9,
      "y": 12,
      "z": -2,
      "name": "Rock_Dark_Rusty_Metal"
    },
    {
      "x": -9,
      "y": 13,
      "z": -2,
      "name": "Rock_Dark_Rusty_Metal"
    },
    {
      "x": -9,
      "y": 14,
      "z": -2,
      "name": "Rock_Dark_Rusty_Metal"
    },
    {
      "x": -9,
      "y": 15,
      "z": -2,
      "name": "Rock_Dark_Rusty_Metal"
    },
    {
      "x": -9,
      "y": 16,
      "z": -2,
      "name": "Rock_Dark_Rusty_Metal"
    },
    {
      "x": -9,
      "y": 17,
      "z": -2,
      "name": "Rock_Dark_Rusty_Metal"
    },
    {
      "x": -9,
      "y": 18,
      "z": -2,
      "name": "Rock_Dark_Rusty_Metal"
    },
    {
      "x": -9,
      "y": 19,
      "z": -2,
      "name": "Rock_Dark_Rusty_Metal"
    },
    {
      "x": -9,
      "y": 20,
      "z": -2,
      "name": "Rock_Dark_Rusty_Metal"
    },
    {
      "x": -9,
      "y": 21,
      "z": -2,
      "name": "Rock_Dark_Rusty_Metal"
    },
    {
      "x": -9,
      "y": 22,
      "z": -2,
      "name": "Rock_Dark_Rusty_Metal"
    },
    {
      "x": -9,
      "y": -1,
      "z": -1,
      "name": "Rock_Rusty_Metal"
    },
    {
      "x": -9,
      "y": 12,
      "z": -1,
      "name": "Rock_Dark_Rusty_Metal"
    },
    {
      "x": -9,
      "y": 13,
      "z": -1,
      "name": "Rock_Dark_Rusty_Metal"
    },
    {
      "x": -9,
      "y": 14,
      "z": -1,
      "name": "Rock_Dark_Rusty_Metal"
    },
    {
      "x": -9,
      "y": 15,
      "z": -1,
      "name": "Rock_Dark_Rusty_Metal"
    },
    {
      "x": -9,
      "y": 16,
      "z": -1,
      "name": "Rock_Dark_Rusty_Metal"
    },
    {
      "x": -9,
      "y": 17,
      "z": -1,
      "name": "Rock_Dark_Rusty_Metal"
    },
    {
      "x": -9,
      "y": 18,
      "z": -1,
      "name": "Rock_Bronze_Metal"
    },
    {
      "x": -9,
      "y": 19,
      "z": -1,
      "name": "Rock_Bronze_Metal"
    },
    {
      "x": -9,
      "y": 20,
      "z": -1,
      "name": "Rock_Bronze_Metal"
    },
    {
      "x": -9,
      "y": 21,
      "z": -1,
      "name": "Rock_Bronze_Metal"
    },
    {
      "x": -9,
      "y": 22,
      "z": -1,
      "name": "Rock_Bronze_Metal"
    },
    {
      "x": -9,
      "y": 23,
      "z": -1,
      "name": "Rock_Bronze_Metal"
    },
    {
      "x": -9,
      "y": 24,
      "z": -1,
      "name": "Rock_Bronze_Metal"
    },
    {
      "x": -9,
      "y": 25,
      "z": -1,
      "name": "Rock_Bronze_Metal"
    },
    {
      "x": -9,
      "y": 26,
      "z": -1,
      "name": "Rock_Bronze_Metal"
    },
    {
      "x": -9,
      "y": -1,
      "z": 0,
      "name": "Rock_Rusty_Metal"
    },
    {
      "x": -9,
      "y": 12,
      "z": 0,
      "name": "Rock_Dark_Rusty_Metal"
    },
    {
      "x": -9,
      "y": 13,
      "z": 0,
      "name": "Rock_Dark_Rusty_Metal"
    },
    {
      "x": -9,
      "y": 14,
      "z": 0,
      "name": "Rock_Dark_Rusty_Metal"
    },
    {
      "x": -9,
      "y": 15,
      "z": 0,
      "name": "Rock_Dark_Rusty_Metal"
    },
    {
      "x": -9,
      "y": 16,
      "z": 0,
      "name": "Rock_Dark_Rusty_Metal"
    },
    {
      "x": -9,
      "y": 17,
      "z": 0,
      "name": "Rock_Dark_Rusty_Metal"
    },
    {
      "x": -9,
      "y": 18,
      "z": 0,
      "name": "Rock_Bronze_Metal"
    },
    {
      "x": -9,
      "y": 19,
      "z": 0,
      "name": "Rock_Bronze_Metal"
    },
    {
      "x": -9,
      "y": 20,
      "z": 0,
      "name": "Rock_Bronze_Metal"
    },
    {
      "x": -9,
      "y": 21,
      "z": 0,
